2025-09-17 15:26:27,725 - root - INFO - logger.py:49 - Social Media Automation System logging initialized
2025-09-17 15:26:27,795 - models.database - INFO - database.py:102 - Database initialized successfully
2025-09-17 15:26:29,650 - app - INFO - app.py:54 - Social Media Automation System initialized successfully
2025-09-17 15:26:29,653 - __main__ - ERROR - run.py:68 - Application startup failed: 'PostScheduler' object has no attribute 'start'
2025-09-17 15:27:03,762 - root - INFO - logger.py:49 - Social Media Automation System logging initialized
2025-09-17 15:27:03,768 - models.database - INFO - database.py:102 - Database initialized successfully
2025-09-17 15:27:04,783 - app - INFO - app.py:54 - Social Media Automation System initialized successfully
2025-09-17 15:27:04,784 - __main__ - ERROR - run.py:68 - Application startup failed: 'PostScheduler' object has no attribute 'start'
2025-09-17 15:36:12,128 - root - INFO - logger.py:49 - Social Media Automation System logging initialized
2025-09-17 15:36:12,150 - models.database - INFO - database.py:102 - Database initialized successfully
2025-09-17 15:36:13,308 - app - INFO - app.py:54 - Social Media Automation System initialized successfully
2025-09-17 15:36:13,309 - services.scheduler - INFO - scheduler.py:13 - PostScheduler iniciado
2025-09-17 15:36:13,310 - __main__ - INFO - run.py:53 - Starting Social Media Automation System
2025-09-17 15:36:13,310 - __main__ - INFO - run.py:54 - Debug mode: True
2025-09-17 15:36:13,310 - __main__ - INFO - run.py:55 - Upload folder: uploads
2025-09-17 15:36:13,313 - models.database - INFO - database.py:102 - Database initialized successfully
2025-09-17 15:36:13,313 - services.scheduler - INFO - scheduler.py:13 - PostScheduler iniciado
2025-09-17 15:36:13,313 - app - INFO - app.py:728 - Application context initialized successfully
2025-09-17 15:36:13,314 - app - INFO - app.py:740 - Starting Social Media Automation System on 0.0.0.0:5000
2025-09-17 15:36:13,314 - app - INFO - app.py:741 - Debug mode: True
2025-09-17 15:36:13,315 - app - INFO - app.py:742 - Upload folder: uploads
2025-09-17 15:36:14,325 - werkzeug - INFO - _internal.py:96 - [31m[1mWARNING: This is a development server. Do not use it in a production deployment. Use a production WSGI server instead.[0m
 * Running on all addresses (0.0.0.0)
 * Running on http://127.0.0.1:5000
 * Running on http://192.168.0.7:5000
2025-09-17 15:36:14,325 - werkzeug - INFO - _internal.py:96 - [33mPress CTRL+C to quit[0m
2025-09-17 15:36:14,330 - werkzeug - INFO - _internal.py:96 -  * Restarting with stat
2025-09-17 15:36:18,147 - root - INFO - logger.py:49 - Social Media Automation System logging initialized
2025-09-17 15:36:18,151 - models.database - INFO - database.py:102 - Database initialized successfully
2025-09-17 15:36:19,430 - app - INFO - app.py:54 - Social Media Automation System initialized successfully
2025-09-17 15:36:19,431 - services.scheduler - INFO - scheduler.py:13 - PostScheduler iniciado
2025-09-17 15:36:19,432 - __main__ - INFO - run.py:53 - Starting Social Media Automation System
2025-09-17 15:36:19,432 - __main__ - INFO - run.py:54 - Debug mode: True
2025-09-17 15:36:19,433 - __main__ - INFO - run.py:55 - Upload folder: uploads
2025-09-17 15:36:19,435 - models.database - INFO - database.py:102 - Database initialized successfully
2025-09-17 15:36:19,436 - services.scheduler - INFO - scheduler.py:13 - PostScheduler iniciado
2025-09-17 15:36:19,436 - app - INFO - app.py:728 - Application context initialized successfully
2025-09-17 15:36:19,437 - app - INFO - app.py:740 - Starting Social Media Automation System on 0.0.0.0:5000
2025-09-17 15:36:19,437 - app - INFO - app.py:741 - Debug mode: True
2025-09-17 15:36:19,438 - app - INFO - app.py:742 - Upload folder: uploads
2025-09-17 15:36:19,454 - werkzeug - WARNING - _internal.py:96 -  * Debugger is active!
2025-09-17 15:36:19,463 - werkzeug - INFO - _internal.py:96 -  * Debugger PIN: 372-696-833
2025-09-17 15:36:23,694 - werkzeug - INFO - _internal.py:96 - 127.0.0.1 - - [17/Sep/2025 15:36:23] "GET / HTTP/1.1" 200 -
2025-09-17 15:36:24,046 - werkzeug - INFO - _internal.py:96 - 127.0.0.1 - - [17/Sep/2025 15:36:24] "GET /static/css/style.css HTTP/1.1" 200 -
2025-09-17 15:36:24,196 - werkzeug - INFO - _internal.py:96 - 127.0.0.1 - - [17/Sep/2025 15:36:24] "GET /static/js/app.js HTTP/1.1" 200 -
2025-09-17 15:36:26,254 - werkzeug - INFO - _internal.py:96 - 127.0.0.1 - - [17/Sep/2025 15:36:26] "GET /api/accounts/status HTTP/1.1" 200 -
2025-09-17 15:36:29,056 - werkzeug - INFO - _internal.py:96 - 127.0.0.1 - - [17/Sep/2025 15:36:29] "[33mGET /favicon.ico HTTP/1.1[0m" 404 -
2025-09-17 15:51:09,567 - werkzeug - INFO - _internal.py:96 - 127.0.0.1 - - [17/Sep/2025 15:51:09] "[36mGET /static/css/style.css HTTP/1.1[0m" 304 -
2025-09-17 15:51:09,571 - werkzeug - INFO - _internal.py:96 - 127.0.0.1 - - [17/Sep/2025 15:51:09] "[33mGET /.well-known/appspecific/com.chrome.devtools.json HTTP/1.1[0m" 404 -
2025-09-17 15:58:55,043 - werkzeug - INFO - _internal.py:96 - 127.0.0.1 - - [17/Sep/2025 15:58:55] "GET / HTTP/1.1" 200 -
2025-09-17 15:58:55,125 - werkzeug - INFO - _internal.py:96 - 127.0.0.1 - - [17/Sep/2025 15:58:55] "GET /static/css/style.css HTTP/1.1" 200 -
2025-09-17 15:58:55,210 - werkzeug - INFO - _internal.py:96 - 127.0.0.1 - - [17/Sep/2025 15:58:55] "[36mGET /static/js/app.js HTTP/1.1[0m" 304 -
2025-09-17 15:58:56,251 - werkzeug - INFO - _internal.py:96 - 127.0.0.1 - - [17/Sep/2025 15:58:56] "GET /api/accounts/status HTTP/1.1" 200 -
2025-09-17 16:15:21,639 - werkzeug - INFO - _internal.py:96 - 127.0.0.1 - - [17/Sep/2025 16:15:21] "[31m[1mPOST /api/accounts/connect HTTP/1.1[0m" 400 -
2025-09-17 16:15:28,763 - werkzeug - INFO - _internal.py:96 - 127.0.0.1 - - [17/Sep/2025 16:15:28] "[31m[1mPOST /api/accounts/connect HTTP/1.1[0m" 400 -
2025-09-17 16:30:47,627 - werkzeug - INFO - _internal.py:96 - 127.0.0.1 - - [17/Sep/2025 16:30:47] "POST /api/accounts/connect HTTP/1.1" 200 -
2025-09-17 16:51:56,702 - models.database - ERROR - database.py:117 - Database operation failed: 'sqlite3.Connection' object has no attribute 'rowcount'
2025-09-17 16:51:56,778 - models.database - ERROR - database.py:244 - Failed to update post 40ab1178-c646-44d8-a158-eb13bac6d7a7: 'sqlite3.Connection' object has no attribute 'rowcount'
2025-09-17 16:51:56,935 - werkzeug - INFO - _internal.py:96 - 127.0.0.1 - - [17/Sep/2025 16:51:56] "POST /api/upload HTTP/1.1" 200 -
2025-09-17 17:14:25,628 - werkzeug - INFO - _internal.py:96 - 127.0.0.1 - - [17/Sep/2025 17:14:25] "[31m[1mPOST /api/upload HTTP/1.1[0m" 400 -
2025-09-17 17:14:34,667 - werkzeug - INFO - _internal.py:96 - 127.0.0.1 - - [17/Sep/2025 17:14:34] "[31m[1mPOST /api/upload HTTP/1.1[0m" 400 -
2025-09-17 17:14:49,535 - models.database - ERROR - database.py:117 - Database operation failed: 'sqlite3.Connection' object has no attribute 'rowcount'
2025-09-17 17:14:49,536 - models.database - ERROR - database.py:244 - Failed to update post 739eb675-50c6-42a5-b1d2-a5be3c757ffe: 'sqlite3.Connection' object has no attribute 'rowcount'
2025-09-17 17:14:49,550 - werkzeug - INFO - _internal.py:96 - 127.0.0.1 - - [17/Sep/2025 17:14:49] "POST /api/upload HTTP/1.1" 200 -
2025-09-17 18:05:05,417 - werkzeug - INFO - _internal.py:96 -  * Detected change in 'C:\\Users\\wilker.gandra\\Documents\\GitHub\\videos_automacoes\\models\\database.py', reloading
2025-09-17 18:05:05,463 - services.scheduler - INFO - scheduler.py:18 - PostScheduler parado
2025-09-17 18:05:05,470 - app - INFO - app.py:755 - Application shutdown complete
2025-09-17 18:05:05,474 - services.scheduler - INFO - scheduler.py:18 - PostScheduler parado
2025-09-17 18:05:10,125 - werkzeug - INFO - _internal.py:96 -  * Restarting with stat
2025-09-17 18:05:27,320 - services.scheduler - INFO - scheduler.py:18 - PostScheduler parado
2025-09-17 18:05:27,330 - app - INFO - app.py:755 - Application shutdown complete
2025-09-17 18:05:27,336 - services.scheduler - INFO - scheduler.py:18 - PostScheduler parado
2025-09-17 21:16:20,242 - root - INFO - logger.py:49 - Social Media Automation System logging initialized
2025-09-17 21:16:20,269 - models.database - INFO - database.py:102 - Database initialized successfully
2025-09-17 21:16:22,012 - __main__ - ERROR - run.py:68 - Application startup failed: name 'app' is not defined
2025-09-17 21:17:36,156 - root - INFO - logger.py:49 - Social Media Automation System logging initialized
2025-09-17 21:17:36,160 - models.database - INFO - database.py:102 - Database initialized successfully
2025-09-17 21:17:37,192 - __main__ - ERROR - run.py:68 - Application startup failed: name 'app' is not defined
2025-09-17 21:21:19,296 - root - INFO - logger.py:49 - Social Media Automation System logging initialized
2025-09-17 21:21:19,333 - models.database - INFO - database.py:102 - Database initialized successfully
2025-09-18 14:09:25,534 - root - INFO - logger.py:49 - Social Media Automation System logging initialized
2025-09-18 14:09:25,555 - models.database - INFO - database.py:102 - Database initialized successfully
2025-09-18 14:16:24,179 - root - INFO - logger.py:49 - Social Media Automation System logging initialized
2025-09-18 14:16:24,201 - models.database - INFO - database.py:102 - Database initialized successfully
2025-09-18 14:20:01,684 - root - INFO - logger.py:49 - Social Media Automation System logging initialized
2025-09-18 14:20:01,709 - models.database - INFO - database.py:102 - Database initialized successfully
2025-09-18 14:20:02,912 - app - INFO - app.py:54 - Social Media Automation System initialized successfully
2025-09-18 14:20:02,934 - models.database - INFO - database.py:102 - Database initialized successfully
2025-09-18 14:20:03,707 - app - INFO - app.py:54 - Social Media Automation System initialized successfully
2025-09-18 14:20:03,708 - services.scheduler - INFO - scheduler.py:13 - PostScheduler iniciado
2025-09-18 14:20:03,709 - __main__ - INFO - run.py:55 - Starting Social Media Automation System
2025-09-18 14:20:03,709 - __main__ - INFO - run.py:56 - Debug mode: False
2025-09-18 14:20:03,709 - __main__ - INFO - run.py:57 - Upload folder: uploads
2025-09-18 14:20:03,712 - models.database - INFO - database.py:102 - Database initialized successfully
2025-09-18 14:20:03,712 - services.scheduler - INFO - scheduler.py:13 - PostScheduler iniciado
2025-09-18 14:20:03,712 - app - INFO - app.py:763 - Application context initialized successfully
2025-09-18 14:20:03,713 - app - INFO - app.py:775 - Starting Social Media Automation System on 0.0.0.0:5000
2025-09-18 14:20:03,713 - app - INFO - app.py:776 - Debug mode: False
2025-09-18 14:20:03,713 - app - INFO - app.py:777 - Upload folder: uploads
2025-09-18 14:20:04,785 - werkzeug - INFO - _internal.py:96 - [31m[1mWARNING: This is a development server. Do not use it in a production deployment. Use a production WSGI server instead.[0m
 * Running on all addresses (0.0.0.0)
 * Running on http://127.0.0.1:5000
 * Running on http://192.168.0.7:5000
2025-09-18 14:20:04,786 - werkzeug - INFO - _internal.py:96 - [33mPress CTRL+C to quit[0m
2025-09-18 14:21:18,053 - services.scheduler - INFO - scheduler.py:18 - PostScheduler parado
2025-09-18 14:21:18,054 - app - INFO - app.py:790 - Application shutdown complete
2025-09-18 14:21:18,055 - services.scheduler - INFO - scheduler.py:18 - PostScheduler parado
2025-09-18 14:21:18,058 - models.database - INFO - database.py:102 - Database initialized successfully
2025-09-18 14:21:18,059 - services.scheduler - INFO - scheduler.py:13 - PostScheduler iniciado
2025-09-18 14:21:18,059 - app - INFO - app.py:763 - Application context initialized successfully
2025-09-18 14:21:18,059 - app - INFO - app.py:775 - Starting Social Media Automation System on 0.0.0.0:5000
2025-09-18 14:21:18,060 - app - INFO - app.py:776 - Debug mode: False
2025-09-18 14:21:18,060 - app - INFO - app.py:777 - Upload folder: uploads
2025-09-18 14:21:18,917 - werkzeug - INFO - _internal.py:96 - [31m[1mWARNING: This is a development server. Do not use it in a production deployment. Use a production WSGI server instead.[0m
 * Running on all addresses (0.0.0.0)
 * Running on http://127.0.0.1:5000
 * Running on http://192.168.0.7:5000
2025-09-18 14:21:18,919 - werkzeug - INFO - _internal.py:96 - [33mPress CTRL+C to quit[0m
2025-09-18 14:21:23,514 - services.scheduler - INFO - scheduler.py:18 - PostScheduler parado
2025-09-18 14:21:23,514 - app - INFO - app.py:790 - Application shutdown complete
2025-09-18 14:21:37,906 - root - INFO - logger.py:49 - Social Media Automation System logging initialized
2025-09-18 14:21:37,911 - models.database - INFO - database.py:102 - Database initialized successfully
2025-09-18 14:21:39,454 - app - INFO - app.py:54 - Social Media Automation System initialized successfully
2025-09-18 14:21:39,461 - models.database - INFO - database.py:102 - Database initialized successfully
2025-09-18 14:21:40,143 - app - INFO - app.py:54 - Social Media Automation System initialized successfully
2025-09-18 14:21:40,144 - services.scheduler - INFO - scheduler.py:13 - PostScheduler iniciado
2025-09-18 14:21:40,144 - __main__ - INFO - run.py:55 - Starting Social Media Automation System
2025-09-18 14:21:40,145 - __main__ - INFO - run.py:56 - Debug mode: False
2025-09-18 14:21:40,145 - __main__ - INFO - run.py:57 - Upload folder: uploads
2025-09-18 14:21:40,148 - models.database - INFO - database.py:102 - Database initialized successfully
2025-09-18 14:21:40,148 - services.scheduler - INFO - scheduler.py:13 - PostScheduler iniciado
2025-09-18 14:21:40,149 - app - INFO - app.py:763 - Application context initialized successfully
2025-09-18 14:21:40,149 - app - INFO - app.py:775 - Starting Social Media Automation System on 0.0.0.0:5000
2025-09-18 14:21:40,149 - app - INFO - app.py:776 - Debug mode: False
2025-09-18 14:21:40,150 - app - INFO - app.py:777 - Upload folder: uploads
2025-09-18 14:21:41,054 - werkzeug - INFO - _internal.py:96 - [31m[1mWARNING: This is a development server. Do not use it in a production deployment. Use a production WSGI server instead.[0m
 * Running on all addresses (0.0.0.0)
 * Running on http://127.0.0.1:5000
 * Running on http://192.168.0.7:5000
2025-09-18 14:21:41,055 - werkzeug - INFO - _internal.py:96 - [33mPress CTRL+C to quit[0m
2025-09-18 14:21:45,029 - werkzeug - INFO - _internal.py:96 - 127.0.0.1 - - [18/Sep/2025 14:21:45] "GET / HTTP/1.1" 200 -
2025-09-18 14:21:45,419 - werkzeug - INFO - _internal.py:96 - 127.0.0.1 - - [18/Sep/2025 14:21:45] "GET /static/css/style.css HTTP/1.1" 200 -
2025-09-18 14:21:45,517 - werkzeug - INFO - _internal.py:96 - 127.0.0.1 - - [18/Sep/2025 14:21:45] "GET /static/js/app.js HTTP/1.1" 200 -
2025-09-18 14:21:47,629 - werkzeug - INFO - _internal.py:96 - 127.0.0.1 - - [18/Sep/2025 14:21:47] "GET /api/accounts/status HTTP/1.1" 200 -
2025-09-18 14:34:54,847 - werkzeug - INFO - _internal.py:96 - 127.0.0.1 - - [18/Sep/2025 14:34:54] "POST /api/accounts/connect HTTP/1.1" 200 -
2025-09-18 14:35:44,328 - openai._base_client - INFO - _base_client.py:1058 - Retrying request to /chat/completions in 0.482783 seconds
2025-09-18 14:35:44,873 - openai._base_client - INFO - _base_client.py:1058 - Retrying request to /chat/completions in 0.957604 seconds
2025-09-18 14:35:45,895 - services.ai_service - ERROR - ai_service.py:85 - AI content generation failed: Connection error.
2025-09-18 14:35:45,952 - werkzeug - INFO - _internal.py:96 - 127.0.0.1 - - [18/Sep/2025 14:35:45] "POST /api/upload HTTP/1.1" 200 -
2025-09-18 14:36:45,248 - werkzeug - INFO - _internal.py:96 - 127.0.0.1 - - [18/Sep/2025 14:36:45] "POST /api/upload HTTP/1.1" 200 -
2025-09-18 15:29:10,132 - services.scheduler - INFO - scheduler.py:18 - PostScheduler parado
2025-09-18 15:29:10,157 - app - INFO - app.py:790 - Application shutdown complete
2025-09-18 15:29:10,162 - services.scheduler - INFO - scheduler.py:18 - PostScheduler parado
2025-09-18 15:29:10,229 - models.database - INFO - database.py:102 - Database initialized successfully
2025-09-18 15:29:10,231 - services.scheduler - INFO - scheduler.py:13 - PostScheduler iniciado
2025-09-18 15:29:10,231 - app - INFO - app.py:763 - Application context initialized successfully
2025-09-18 15:29:10,232 - app - INFO - app.py:775 - Starting Social Media Automation System on 0.0.0.0:5000
2025-09-18 15:29:10,233 - app - INFO - app.py:776 - Debug mode: False
2025-09-18 15:29:10,233 - app - INFO - app.py:777 - Upload folder: uploads
2025-09-18 15:29:11,473 - werkzeug - INFO - _internal.py:96 - [31m[1mWARNING: This is a development server. Do not use it in a production deployment. Use a production WSGI server instead.[0m
 * Running on all addresses (0.0.0.0)
 * Running on http://127.0.0.1:5000
 * Running on http://192.168.0.7:5000
2025-09-18 15:29:11,474 - werkzeug - INFO - _internal.py:96 - [33mPress CTRL+C to quit[0m
2025-09-18 15:29:14,538 - services.scheduler - INFO - scheduler.py:18 - PostScheduler parado
2025-09-18 15:29:14,539 - app - INFO - app.py:790 - Application shutdown complete
2025-09-18 15:29:41,854 - root - INFO - logger.py:49 - Social Media Automation System logging initialized
2025-09-18 15:29:41,863 - models.database - INFO - database.py:102 - Database initialized successfully
2025-09-18 15:29:43,209 - app - INFO - app.py:54 - Social Media Automation System initialized successfully
2025-09-18 15:29:43,216 - models.database - INFO - database.py:102 - Database initialized successfully
2025-09-18 15:29:43,871 - app - INFO - app.py:54 - Social Media Automation System initialized successfully
2025-09-18 15:29:43,872 - services.scheduler - INFO - scheduler.py:13 - PostScheduler iniciado
2025-09-18 15:29:43,873 - __main__ - INFO - run.py:55 - Starting Social Media Automation System
2025-09-18 15:29:43,873 - __main__ - INFO - run.py:56 - Debug mode: False
2025-09-18 15:29:43,874 - __main__ - INFO - run.py:57 - Upload folder: uploads
2025-09-18 15:29:43,876 - models.database - INFO - database.py:102 - Database initialized successfully
2025-09-18 15:29:43,877 - services.scheduler - INFO - scheduler.py:13 - PostScheduler iniciado
2025-09-18 15:29:43,877 - app - INFO - app.py:763 - Application context initialized successfully
2025-09-18 15:29:43,878 - app - INFO - app.py:775 - Starting Social Media Automation System on 0.0.0.0:5000
2025-09-18 15:29:43,879 - app - INFO - app.py:776 - Debug mode: False
2025-09-18 15:29:43,879 - app - INFO - app.py:777 - Upload folder: uploads
2025-09-18 15:29:44,773 - werkzeug - INFO - _internal.py:96 - [31m[1mWARNING: This is a development server. Do not use it in a production deployment. Use a production WSGI server instead.[0m
 * Running on all addresses (0.0.0.0)
 * Running on http://127.0.0.1:5000
 * Running on http://192.168.0.7:5000
2025-09-18 15:29:44,773 - werkzeug - INFO - _internal.py:96 - [33mPress CTRL+C to quit[0m
2025-09-18 15:30:14,227 - werkzeug - INFO - _internal.py:96 - 127.0.0.1 - - [18/Sep/2025 15:30:14] "GET / HTTP/1.1" 200 -
2025-09-18 15:30:14,776 - werkzeug - INFO - _internal.py:96 - 127.0.0.1 - - [18/Sep/2025 15:30:14] "[36mGET /static/css/style.css HTTP/1.1[0m" 304 -
2025-09-18 15:30:14,928 - werkzeug - INFO - _internal.py:96 - 127.0.0.1 - - [18/Sep/2025 15:30:14] "[36mGET /static/js/app.js HTTP/1.1[0m" 304 -
2025-09-18 15:30:17,415 - werkzeug - INFO - _internal.py:96 - 127.0.0.1 - - [18/Sep/2025 15:30:17] "GET /api/accounts/status HTTP/1.1" 200 -
2025-09-18 15:36:53,039 - werkzeug - INFO - _internal.py:96 - 127.0.0.1 - - [18/Sep/2025 15:36:53] "POST /api/accounts/connect HTTP/1.1" 200 -
2025-09-18 15:37:28,855 - werkzeug - INFO - _internal.py:96 - 127.0.0.1 - - [18/Sep/2025 15:37:28] "POST /api/upload HTTP/1.1" 200 -
2025-09-19 09:19:04,564 - werkzeug - INFO - _internal.py:96 - 127.0.0.1 - - [19/Sep/2025 09:19:04] "GET / HTTP/1.1" 200 -
2025-09-19 09:19:05,275 - werkzeug - INFO - _internal.py:96 - 127.0.0.1 - - [19/Sep/2025 09:19:05] "GET /static/css/style.css HTTP/1.1" 200 -
2025-09-19 09:19:05,471 - werkzeug - INFO - _internal.py:96 - 127.0.0.1 - - [19/Sep/2025 09:19:05] "GET /static/js/app.js HTTP/1.1" 200 -
2025-09-19 09:19:09,346 - werkzeug - INFO - _internal.py:96 - 127.0.0.1 - - [19/Sep/2025 09:19:09] "GET /api/accounts/status HTTP/1.1" 200 -
2025-09-19 09:19:20,087 - werkzeug - INFO - _internal.py:96 - 127.0.0.1 - - [19/Sep/2025 09:19:20] "[33mGET /favicon.ico HTTP/1.1[0m" 404 -
2025-09-19 09:23:24,215 - werkzeug - INFO - _internal.py:96 - 127.0.0.1 - - [19/Sep/2025 09:23:24] "GET / HTTP/1.1" 200 -
2025-09-19 09:23:24,759 - werkzeug - INFO - _internal.py:96 - 127.0.0.1 - - [19/Sep/2025 09:23:24] "[36mGET /static/css/style.css HTTP/1.1[0m" 304 -
2025-09-19 09:23:24,795 - werkzeug - INFO - _internal.py:96 - 127.0.0.1 - - [19/Sep/2025 09:23:24] "[36mGET /static/js/app.js HTTP/1.1[0m" 304 -
2025-09-19 09:23:26,201 - werkzeug - INFO - _internal.py:96 - 127.0.0.1 - - [19/Sep/2025 09:23:26] "GET /api/accounts/status HTTP/1.1" 200 -
2025-09-19 09:23:42,503 - services.scheduler - INFO - scheduler.py:18 - PostScheduler parado
2025-09-19 09:23:42,506 - app - INFO - app.py:790 - Application shutdown complete
2025-09-19 09:23:42,514 - services.scheduler - INFO - scheduler.py:18 - PostScheduler parado
2025-09-19 09:23:42,615 - models.database - INFO - database.py:102 - Database initialized successfully
2025-09-19 09:23:42,620 - services.scheduler - INFO - scheduler.py:13 - PostScheduler iniciado
2025-09-19 09:23:42,620 - app - INFO - app.py:763 - Application context initialized successfully
2025-09-19 09:23:42,621 - app - INFO - app.py:775 - Starting Social Media Automation System on 0.0.0.0:5000
2025-09-19 09:23:42,622 - app - INFO - app.py:776 - Debug mode: False
2025-09-19 09:23:42,623 - app - INFO - app.py:777 - Upload folder: uploads
2025-09-19 09:23:43,863 - werkzeug - INFO - _internal.py:96 - [31m[1mWARNING: This is a development server. Do not use it in a production deployment. Use a production WSGI server instead.[0m
 * Running on all addresses (0.0.0.0)
 * Running on http://127.0.0.1:5000
 * Running on http://192.168.0.7:5000
2025-09-19 09:23:43,864 - werkzeug - INFO - _internal.py:96 - [33mPress CTRL+C to quit[0m
2025-09-19 09:26:08,456 - werkzeug - INFO - _internal.py:96 - 127.0.0.1 - - [19/Sep/2025 09:26:08] "GET / HTTP/1.1" 200 -
2025-09-19 09:26:08,545 - werkzeug - INFO - _internal.py:96 - 127.0.0.1 - - [19/Sep/2025 09:26:08] "[36mGET /static/js/app.js HTTP/1.1[0m" 304 -
2025-09-19 09:26:08,568 - werkzeug - INFO - _internal.py:96 - 127.0.0.1 - - [19/Sep/2025 09:26:08] "[36mGET /static/css/style.css HTTP/1.1[0m" 304 -
2025-09-19 09:26:10,297 - werkzeug - INFO - _internal.py:96 - 127.0.0.1 - - [19/Sep/2025 09:26:10] "GET /api/accounts/status HTTP/1.1" 200 -
2025-09-19 09:28:19,577 - werkzeug - INFO - _internal.py:96 - 127.0.0.1 - - [19/Sep/2025 09:28:19] "GET / HTTP/1.1" 200 -
2025-09-19 09:28:19,886 - werkzeug - INFO - _internal.py:96 - 127.0.0.1 - - [19/Sep/2025 09:28:19] "[36mGET /static/js/app.js HTTP/1.1[0m" 304 -
2025-09-19 09:28:19,917 - werkzeug - INFO - _internal.py:96 - 127.0.0.1 - - [19/Sep/2025 09:28:19] "[36mGET /static/css/style.css HTTP/1.1[0m" 304 -
2025-09-19 09:28:21,679 - werkzeug - INFO - _internal.py:96 - 127.0.0.1 - - [19/Sep/2025 09:28:21] "GET /api/accounts/status HTTP/1.1" 200 -
2025-09-19 11:30:19,167 - services.scheduler - INFO - scheduler.py:18 - PostScheduler parado
2025-09-19 11:30:19,196 - app - INFO - app.py:790 - Application shutdown complete
2025-09-19 11:31:24,892 - root - INFO - logger.py:49 - Social Media Automation System logging initialized
2025-09-19 11:31:24,915 - models.database - INFO - database.py:102 - Database initialized successfully
2025-09-19 11:31:26,358 - app - INFO - app.py:54 - Social Media Automation System initialized successfully
2025-09-19 11:31:26,388 - models.database - INFO - database.py:102 - Database initialized successfully
2025-09-19 11:31:27,008 - app - INFO - app.py:54 - Social Media Automation System initialized successfully
2025-09-19 11:31:27,009 - services.scheduler - INFO - scheduler.py:13 - PostScheduler iniciado
2025-09-19 11:31:27,010 - __main__ - INFO - run.py:55 - Starting Social Media Automation System
2025-09-19 11:31:27,010 - __main__ - INFO - run.py:56 - Debug mode: False
2025-09-19 11:31:27,010 - __main__ - INFO - run.py:57 - Upload folder: uploads
2025-09-19 11:31:27,012 - models.database - INFO - database.py:102 - Database initialized successfully
2025-09-19 11:31:27,013 - services.scheduler - INFO - scheduler.py:13 - PostScheduler iniciado
2025-09-19 11:31:27,014 - app - INFO - app.py:763 - Application context initialized successfully
2025-09-19 11:31:27,015 - app - INFO - app.py:775 - Starting Social Media Automation System on 0.0.0.0:5000
2025-09-19 11:31:27,016 - app - INFO - app.py:776 - Debug mode: False
2025-09-19 11:31:27,016 - app - INFO - app.py:777 - Upload folder: uploads
2025-09-19 11:31:28,030 - werkzeug - INFO - _internal.py:96 - [31m[1mWARNING: This is a development server. Do not use it in a production deployment. Use a production WSGI server instead.[0m
 * Running on all addresses (0.0.0.0)
 * Running on http://127.0.0.1:5000
 * Running on http://192.168.0.7:5000
2025-09-19 11:31:28,033 - werkzeug - INFO - _internal.py:96 - [33mPress CTRL+C to quit[0m
2025-09-19 11:32:52,389 - services.scheduler - INFO - scheduler.py:18 - PostScheduler parado
2025-09-19 11:32:52,397 - app - INFO - app.py:790 - Application shutdown complete
2025-09-19 11:32:52,398 - services.scheduler - INFO - scheduler.py:18 - PostScheduler parado
2025-09-19 11:32:52,422 - models.database - INFO - database.py:102 - Database initialized successfully
2025-09-19 11:32:52,423 - services.scheduler - INFO - scheduler.py:13 - PostScheduler iniciado
2025-09-19 11:32:52,423 - app - INFO - app.py:763 - Application context initialized successfully
2025-09-19 11:32:52,423 - app - INFO - app.py:775 - Starting Social Media Automation System on 0.0.0.0:5000
2025-09-19 11:32:52,423 - app - INFO - app.py:776 - Debug mode: False
2025-09-19 11:32:52,424 - app - INFO - app.py:777 - Upload folder: uploads
2025-09-19 11:32:53,320 - werkzeug - INFO - _internal.py:96 - [31m[1mWARNING: This is a development server. Do not use it in a production deployment. Use a production WSGI server instead.[0m
 * Running on all addresses (0.0.0.0)
 * Running on http://127.0.0.1:5000
 * Running on http://192.168.0.7:5000
2025-09-19 11:32:53,321 - werkzeug - INFO - _internal.py:96 - [33mPress CTRL+C to quit[0m
2025-09-19 11:32:55,367 - services.scheduler - INFO - scheduler.py:18 - PostScheduler parado
2025-09-19 11:32:55,368 - app - INFO - app.py:790 - Application shutdown complete
2025-09-19 11:33:26,495 - root - INFO - logger.py:49 - Social Media Automation System logging initialized
2025-09-19 11:33:26,499 - models.database - INFO - database.py:102 - Database initialized successfully
2025-09-19 11:33:28,136 - app - INFO - app.py:54 - Social Media Automation System initialized successfully
2025-09-19 11:33:28,143 - models.database - INFO - database.py:102 - Database initialized successfully
2025-09-19 11:33:28,779 - app - INFO - app.py:54 - Social Media Automation System initialized successfully
2025-09-19 11:33:28,780 - services.scheduler - INFO - scheduler.py:13 - PostScheduler iniciado
2025-09-19 11:33:28,780 - __main__ - INFO - run.py:55 - Starting Social Media Automation System
2025-09-19 11:33:28,781 - __main__ - INFO - run.py:56 - Debug mode: False
2025-09-19 11:33:28,781 - __main__ - INFO - run.py:57 - Upload folder: uploads
2025-09-19 11:33:28,783 - models.database - INFO - database.py:102 - Database initialized successfully
2025-09-19 11:33:28,783 - services.scheduler - INFO - scheduler.py:13 - PostScheduler iniciado
2025-09-19 11:33:28,784 - app - INFO - app.py:763 - Application context initialized successfully
2025-09-19 11:33:28,784 - app - INFO - app.py:775 - Starting Social Media Automation System on 0.0.0.0:5000
2025-09-19 11:33:28,785 - app - INFO - app.py:776 - Debug mode: False
2025-09-19 11:33:28,785 - app - INFO - app.py:777 - Upload folder: uploads
2025-09-19 11:33:29,669 - werkzeug - INFO - _internal.py:96 - [31m[1mWARNING: This is a development server. Do not use it in a production deployment. Use a production WSGI server instead.[0m
 * Running on all addresses (0.0.0.0)
 * Running on http://127.0.0.1:5000
 * Running on http://192.168.0.7:5000
2025-09-19 11:33:29,669 - werkzeug - INFO - _internal.py:96 - [33mPress CTRL+C to quit[0m
2025-09-19 11:33:35,511 - werkzeug - INFO - _internal.py:96 - 127.0.0.1 - - [19/Sep/2025 11:33:35] "GET / HTTP/1.1" 200 -
2025-09-19 11:33:35,969 - werkzeug - INFO - _internal.py:96 - 127.0.0.1 - - [19/Sep/2025 11:33:35] "GET /static/css/style.css HTTP/1.1" 200 -
2025-09-19 11:33:36,240 - werkzeug - INFO - _internal.py:96 - 127.0.0.1 - - [19/Sep/2025 11:33:36] "GET /static/js/app.js HTTP/1.1" 200 -
2025-09-19 11:33:38,413 - werkzeug - INFO - _internal.py:96 - 127.0.0.1 - - [19/Sep/2025 11:33:38] "GET /api/accounts/status HTTP/1.1" 200 -
2025-09-19 11:34:28,765 - werkzeug - INFO - _internal.py:96 - 127.0.0.1 - - [19/Sep/2025 11:34:28] "POST /api/accounts/connect HTTP/1.1" 200 -
2025-09-19 11:37:31,331 - werkzeug - INFO - _internal.py:96 - 127.0.0.1 - - [19/Sep/2025 11:37:31] "POST /api/upload HTTP/1.1" 200 -
2025-09-20 10:33:22,724 - werkzeug - INFO - _internal.py:96 - 127.0.0.1 - - [20/Sep/2025 10:33:22] "GET / HTTP/1.1" 200 -
2025-09-20 10:33:23,948 - werkzeug - INFO - _internal.py:96 - 127.0.0.1 - - [20/Sep/2025 10:33:23] "GET /static/css/style.css HTTP/1.1" 200 -
2025-09-20 10:33:24,130 - werkzeug - INFO - _internal.py:96 - 127.0.0.1 - - [20/Sep/2025 10:33:24] "GET /static/js/app.js HTTP/1.1" 200 -
2025-09-20 10:33:25,675 - werkzeug - INFO - _internal.py:96 - 127.0.0.1 - - [20/Sep/2025 10:33:25] "GET /api/accounts/status HTTP/1.1" 200 -
2025-09-20 10:33:25,791 - werkzeug - INFO - _internal.py:96 - 127.0.0.1 - - [20/Sep/2025 10:33:25] "[33mGET /favicon.ico HTTP/1.1[0m" 404 -
2025-09-20 10:33:45,026 - services.scheduler - INFO - scheduler.py:18 - PostScheduler parado
2025-09-20 10:33:45,037 - app - INFO - app.py:790 - Application shutdown complete
2025-09-20 10:33:45,050 - services.scheduler - INFO - scheduler.py:18 - PostScheduler parado
2025-09-20 10:33:45,328 - models.database - INFO - database.py:102 - Database initialized successfully
2025-09-20 10:33:45,335 - services.scheduler - INFO - scheduler.py:13 - PostScheduler iniciado
2025-09-20 10:33:45,348 - app - INFO - app.py:763 - Application context initialized successfully
2025-09-20 10:33:45,368 - app - INFO - app.py:775 - Starting Social Media Automation System on 0.0.0.0:5000
2025-09-20 10:33:45,373 - app - INFO - app.py:776 - Debug mode: False
2025-09-20 10:33:45,379 - app - INFO - app.py:777 - Upload folder: uploads
2025-09-20 10:33:47,251 - werkzeug - INFO - _internal.py:96 - [31m[1mWARNING: This is a development server. Do not use it in a production deployment. Use a production WSGI server instead.[0m
 * Running on all addresses (0.0.0.0)
 * Running on http://127.0.0.1:5000
 * Running on http://192.168.0.7:5000
2025-09-20 10:33:47,252 - werkzeug - INFO - _internal.py:96 - [33mPress CTRL+C to quit[0m
2025-09-20 10:33:52,291 - services.scheduler - INFO - scheduler.py:18 - PostScheduler parado
2025-09-20 10:33:52,292 - app - INFO - app.py:790 - Application shutdown complete
2025-09-21 08:56:19,325 - root - INFO - logger.py:49 - Social Media Automation System logging initialized
2025-09-21 08:56:19,405 - models.database - INFO - database.py:102 - Database initialized successfully
2025-09-21 08:56:33,037 - app - INFO - app.py:54 - Social Media Automation System initialized successfully
2025-09-21 08:56:33,119 - models.database - INFO - database.py:102 - Database initialized successfully
2025-09-21 08:56:39,641 - app - INFO - app.py:54 - Social Media Automation System initialized successfully
2025-09-21 08:56:39,733 - services.scheduler - INFO - scheduler.py:13 - PostScheduler iniciado
2025-09-21 08:56:39,807 - __main__ - INFO - run.py:55 - Starting Social Media Automation System
2025-09-21 08:56:39,923 - __main__ - INFO - run.py:56 - Debug mode: False
2025-09-21 08:56:39,923 - __main__ - INFO - run.py:57 - Upload folder: uploads
2025-09-21 08:56:39,927 - models.database - INFO - database.py:102 - Database initialized successfully
2025-09-21 08:56:39,928 - services.scheduler - INFO - scheduler.py:13 - PostScheduler iniciado
2025-09-21 08:56:39,929 - app - INFO - app.py:763 - Application context initialized successfully
2025-09-21 08:56:39,929 - app - INFO - app.py:775 - Starting Social Media Automation System on 0.0.0.0:5000
2025-09-21 08:56:39,930 - app - INFO - app.py:776 - Debug mode: False
2025-09-21 08:56:39,930 - app - INFO - app.py:777 - Upload folder: uploads
2025-09-21 08:56:42,228 - werkzeug - INFO - _internal.py:96 - [31m[1mWARNING: This is a development server. Do not use it in a production deployment. Use a production WSGI server instead.[0m
 * Running on all addresses (0.0.0.0)
 * Running on http://127.0.0.1:5000
 * Running on http://192.168.0.7:5000
2025-09-21 08:56:42,479 - werkzeug - INFO - _internal.py:96 - [33mPress CTRL+C to quit[0m
2025-09-21 08:57:06,112 - werkzeug - INFO - _internal.py:96 - 127.0.0.1 - - [21/Sep/2025 08:57:06] "GET / HTTP/1.1" 200 -
2025-09-21 08:57:07,594 - werkzeug - INFO - _internal.py:96 - 127.0.0.1 - - [21/Sep/2025 08:57:07] "GET /static/css/style.css HTTP/1.1" 200 -
2025-09-21 08:57:07,628 - werkzeug - INFO - _internal.py:96 - 127.0.0.1 - - [21/Sep/2025 08:57:07] "GET /static/js/app.js HTTP/1.1" 200 -
2025-09-21 08:57:09,707 - werkzeug - INFO - _internal.py:96 - 127.0.0.1 - - [21/Sep/2025 08:57:09] "GET /api/accounts/status HTTP/1.1" 200 -
2025-09-21 08:57:13,642 - werkzeug - INFO - _internal.py:96 - 127.0.0.1 - - [21/Sep/2025 08:57:13] "[33mGET /favicon.ico HTTP/1.1[0m" 404 -
2025-09-22 23:39:39,188 - root - INFO - logger.py:49 - Social Media Automation System logging initialized
2025-09-22 23:39:39,206 - models.database - INFO - database.py:102 - Database initialized successfully
2025-09-23 13:49:55,795 - root - INFO - logger.py:49 - Social Media Automation System logging initialized
2025-09-23 13:49:55,814 - models.database - INFO - database.py:102 - Database initialized successfully
2025-09-23 13:49:55,815 - services.ai_service - WARNING - ai_service.py:16 - OpenAI API key not configured
2025-09-23 13:49:55,827 - app - INFO - app.py:59 - Social Media Automation System initialized successfully
2025-09-23 13:49:55,834 - models.database - INFO - database.py:102 - Database initialized successfully
2025-09-23 13:49:55,834 - services.ai_service - WARNING - ai_service.py:16 - OpenAI API key not configured
2025-09-23 13:49:55,856 - app - INFO - app.py:59 - Social Media Automation System initialized successfully
2025-09-23 13:49:55,856 - services.scheduler - INFO - scheduler.py:13 - PostScheduler iniciado
2025-09-23 13:49:55,857 - __main__ - INFO - run.py:55 - Starting Social Media Automation System
2025-09-23 13:49:55,857 - __main__ - INFO - run.py:56 - Debug mode: False
2025-09-23 13:49:55,858 - __main__ - INFO - run.py:57 - Upload folder: uploads
2025-09-23 13:49:55,863 - models.database - INFO - database.py:102 - Database initialized successfully
2025-09-23 13:49:55,870 - services.scheduler - INFO - scheduler.py:13 - PostScheduler iniciado
2025-09-23 13:49:55,872 - app - INFO - app.py:763 - Application context initialized successfully
2025-09-23 13:49:55,875 - app - INFO - app.py:775 - Starting Social Media Automation System on 0.0.0.0:5000
2025-09-23 13:49:55,877 - app - INFO - app.py:776 - Debug mode: False
2025-09-23 13:49:55,890 - app - INFO - app.py:777 - Upload folder: uploads
2025-09-23 13:49:55,944 - werkzeug - INFO - _internal.py:187 - [31m[1mWARNING: This is a development server. Do not use it in a production deployment. Use a production WSGI server instead.[0m
 * Running on all addresses (0.0.0.0)
 * Running on http://127.0.0.1:5000
 * Running on http://192.168.0.7:5000
2025-09-23 13:49:55,950 - werkzeug - INFO - _internal.py:187 - [33mPress CTRL+C to quit[0m
2025-09-23 13:50:38,699 - services.scheduler - INFO - scheduler.py:18 - PostScheduler parado
2025-09-23 13:50:38,700 - app - INFO - app.py:790 - Application shutdown complete
2025-09-23 13:50:38,701 - services.scheduler - INFO - scheduler.py:18 - PostScheduler parado
2025-09-23 13:50:38,708 - models.database - INFO - database.py:102 - Database initialized successfully
2025-09-23 13:50:38,709 - services.scheduler - INFO - scheduler.py:13 - PostScheduler iniciado
2025-09-23 13:50:38,711 - app - INFO - app.py:763 - Application context initialized successfully
2025-09-23 13:50:38,713 - app - INFO - app.py:775 - Starting Social Media Automation System on 0.0.0.0:5000
2025-09-23 13:50:38,715 - app - INFO - app.py:776 - Debug mode: False
2025-09-23 13:50:38,716 - app - INFO - app.py:777 - Upload folder: uploads
2025-09-23 13:50:38,752 - werkzeug - INFO - _internal.py:187 - [31m[1mWARNING: This is a development server. Do not use it in a production deployment. Use a production WSGI server instead.[0m
 * Running on all addresses (0.0.0.0)
 * Running on http://127.0.0.1:5000
 * Running on http://192.168.0.7:5000
2025-09-23 13:50:38,753 - werkzeug - INFO - _internal.py:187 - [33mPress CTRL+C to quit[0m
2025-09-23 13:50:41,812 - services.scheduler - INFO - scheduler.py:18 - PostScheduler parado
2025-09-23 13:50:41,813 - app - INFO - app.py:790 - Application shutdown complete
2025-09-23 13:50:53,189 - root - INFO - logger.py:49 - Social Media Automation System logging initialized
2025-09-23 13:50:53,193 - models.database - INFO - database.py:102 - Database initialized successfully
2025-09-23 13:50:53,193 - services.ai_service - WARNING - ai_service.py:16 - OpenAI API key not configured
2025-09-23 13:50:53,207 - app - INFO - app.py:59 - Social Media Automation System initialized successfully
2025-09-23 13:50:53,213 - models.database - INFO - database.py:102 - Database initialized successfully
2025-09-23 13:50:53,213 - services.ai_service - WARNING - ai_service.py:16 - OpenAI API key not configured
2025-09-23 13:50:53,232 - app - INFO - app.py:59 - Social Media Automation System initialized successfully
2025-09-23 13:50:53,233 - services.scheduler - INFO - scheduler.py:13 - PostScheduler iniciado
2025-09-23 13:50:53,233 - __main__ - INFO - run.py:55 - Starting Social Media Automation System
2025-09-23 13:50:53,234 - __main__ - INFO - run.py:56 - Debug mode: False
2025-09-23 13:50:53,234 - __main__ - INFO - run.py:57 - Upload folder: uploads
2025-09-23 13:50:53,236 - models.database - INFO - database.py:102 - Database initialized successfully
2025-09-23 13:50:53,237 - services.scheduler - INFO - scheduler.py:13 - PostScheduler iniciado
2025-09-23 13:50:53,237 - app - INFO - app.py:763 - Application context initialized successfully
2025-09-23 13:50:53,237 - app - INFO - app.py:775 - Starting Social Media Automation System on 0.0.0.0:5000
2025-09-23 13:50:53,238 - app - INFO - app.py:776 - Debug mode: False
2025-09-23 13:50:53,238 - app - INFO - app.py:777 - Upload folder: uploads
2025-09-23 13:50:53,256 - werkzeug - INFO - _internal.py:187 - [31m[1mWARNING: This is a development server. Do not use it in a production deployment. Use a production WSGI server instead.[0m
 * Running on all addresses (0.0.0.0)
 * Running on http://127.0.0.1:5000
 * Running on http://192.168.0.7:5000
2025-09-23 13:50:53,256 - werkzeug - INFO - _internal.py:187 - [33mPress CTRL+C to quit[0m
2025-09-23 13:50:55,944 - werkzeug - INFO - _internal.py:187 - 127.0.0.1 - - [23/Sep/2025 13:50:55] "GET / HTTP/1.1" 200 -
2025-09-23 13:50:56,259 - werkzeug - INFO - _internal.py:187 - 127.0.0.1 - - [23/Sep/2025 13:50:56] "GET /static/css/style.css HTTP/1.1" 200 -
2025-09-23 13:50:56,304 - werkzeug - INFO - _internal.py:187 - 127.0.0.1 - - [23/Sep/2025 13:50:56] "GET /static/js/app.js HTTP/1.1" 200 -
2025-09-23 13:50:58,099 - werkzeug - INFO - _internal.py:187 - 127.0.0.1 - - [23/Sep/2025 13:50:58] "GET /api/accounts/status HTTP/1.1" 200 -
2025-09-28 15:53:42,463 - root - INFO - logger.py:49 - Social Media Automation System logging initialized
2025-09-28 15:53:42,490 - models.database - INFO - database.py:102 - Database initialized successfully
2025-09-28 15:53:42,491 - services.ai_service - WARNING - ai_service.py:16 - OpenAI API key not configured
2025-09-28 15:53:42,532 - app - INFO - app.py:59 - Social Media Automation System initialized successfully
2025-09-28 15:53:42,568 - models.database - INFO - database.py:102 - Database initialized successfully
2025-09-28 15:53:42,569 - services.ai_service - WARNING - ai_service.py:16 - OpenAI API key not configured
2025-09-28 15:53:42,604 - app - INFO - app.py:59 - Social Media Automation System initialized successfully
2025-09-28 15:53:42,605 - services.scheduler - INFO - scheduler.py:13 - PostScheduler iniciado
2025-09-28 15:53:42,607 - __main__ - INFO - run.py:55 - Starting Social Media Automation System
2025-09-28 15:53:42,607 - __main__ - INFO - run.py:56 - Debug mode: False
2025-09-28 15:53:42,608 - __main__ - INFO - run.py:57 - Upload folder: uploads
2025-09-28 15:53:42,614 - models.database - INFO - database.py:102 - Database initialized successfully
2025-09-28 15:53:42,615 - services.scheduler - INFO - scheduler.py:13 - PostScheduler iniciado
2025-09-28 15:53:42,617 - app - INFO - app.py:763 - Application context initialized successfully
2025-09-28 15:53:42,617 - app - INFO - app.py:775 - Starting Social Media Automation System on 0.0.0.0:5000
2025-09-28 15:53:42,618 - app - INFO - app.py:776 - Debug mode: False
2025-09-28 15:53:42,625 - app - INFO - app.py:777 - Upload folder: uploads
2025-09-28 15:53:42,681 - werkzeug - INFO - _internal.py:187 - [31m[1mWARNING: This is a development server. Do not use it in a production deployment. Use a production WSGI server instead.[0m
 * Running on all addresses (0.0.0.0)
 * Running on http://127.0.0.1:5000
 * Running on http://192.168.0.7:5000
2025-09-28 15:53:42,685 - werkzeug - INFO - _internal.py:187 - [33mPress CTRL+C to quit[0m
2025-09-28 15:54:52,567 - services.scheduler - INFO - scheduler.py:18 - PostScheduler parado
2025-09-28 15:54:52,568 - app - INFO - app.py:790 - Application shutdown complete
2025-09-28 15:54:52,569 - services.scheduler - INFO - scheduler.py:18 - PostScheduler parado
2025-09-28 15:54:52,572 - models.database - INFO - database.py:102 - Database initialized successfully
2025-09-28 15:54:52,573 - services.scheduler - INFO - scheduler.py:13 - PostScheduler iniciado
2025-09-28 15:54:52,576 - app - INFO - app.py:763 - Application context initialized successfully
2025-09-28 15:54:52,576 - app - INFO - app.py:775 - Starting Social Media Automation System on 0.0.0.0:5000
2025-09-28 15:54:52,577 - app - INFO - app.py:776 - Debug mode: False
2025-09-28 15:54:52,577 - app - INFO - app.py:777 - Upload folder: uploads
2025-09-28 15:54:52,591 - werkzeug - INFO - _internal.py:187 - [31m[1mWARNING: This is a development server. Do not use it in a production deployment. Use a production WSGI server instead.[0m
 * Running on all addresses (0.0.0.0)
 * Running on http://127.0.0.1:5000
 * Running on http://192.168.0.7:5000
2025-09-28 15:54:52,592 - werkzeug - INFO - _internal.py:187 - [33mPress CTRL+C to quit[0m
2025-09-28 15:54:55,651 - services.scheduler - INFO - scheduler.py:18 - PostScheduler parado
2025-09-28 15:54:55,652 - app - INFO - app.py:790 - Application shutdown complete
2025-09-28 15:55:06,596 - root - INFO - logger.py:49 - Social Media Automation System logging initialized
2025-09-28 15:55:06,603 - models.database - INFO - database.py:102 - Database initialized successfully
2025-09-28 15:55:06,604 - services.ai_service - WARNING - ai_service.py:16 - OpenAI API key not configured
2025-09-28 15:55:06,636 - app - INFO - app.py:59 - Social Media Automation System initialized successfully
2025-09-28 15:55:06,653 - models.database - INFO - database.py:102 - Database initialized successfully
2025-09-28 15:55:06,653 - services.ai_service - WARNING - ai_service.py:16 - OpenAI API key not configured
2025-09-28 15:55:06,694 - app - INFO - app.py:59 - Social Media Automation System initialized successfully
2025-09-28 15:55:06,696 - services.scheduler - INFO - scheduler.py:13 - PostScheduler iniciado
2025-09-28 15:55:06,697 - __main__ - INFO - run.py:55 - Starting Social Media Automation System
2025-09-28 15:55:06,698 - __main__ - INFO - run.py:56 - Debug mode: False
2025-09-28 15:55:06,698 - __main__ - INFO - run.py:57 - Upload folder: uploads
2025-09-28 15:55:06,702 - models.database - INFO - database.py:102 - Database initialized successfully
2025-09-28 15:55:06,703 - services.scheduler - INFO - scheduler.py:13 - PostScheduler iniciado
2025-09-28 15:55:06,704 - app - INFO - app.py:763 - Application context initialized successfully
2025-09-28 15:55:06,705 - app - INFO - app.py:775 - Starting Social Media Automation System on 0.0.0.0:5000
2025-09-28 15:55:06,705 - app - INFO - app.py:776 - Debug mode: False
2025-09-28 15:55:06,706 - app - INFO - app.py:777 - Upload folder: uploads
2025-09-28 15:55:06,755 - werkzeug - INFO - _internal.py:187 - [31m[1mWARNING: This is a development server. Do not use it in a production deployment. Use a production WSGI server instead.[0m
 * Running on all addresses (0.0.0.0)
 * Running on http://127.0.0.1:5000
 * Running on http://192.168.0.7:5000
2025-09-28 15:55:06,774 - werkzeug - INFO - _internal.py:187 - [33mPress CTRL+C to quit[0m
2025-09-28 15:55:14,130 - werkzeug - INFO - _internal.py:187 - 127.0.0.1 - - [28/Sep/2025 15:55:14] "GET / HTTP/1.1" 200 -
2025-09-28 15:55:14,408 - werkzeug - INFO - _internal.py:187 - 127.0.0.1 - - [28/Sep/2025 15:55:14] "GET /static/css/style.css HTTP/1.1" 200 -
2025-09-28 15:55:14,423 - werkzeug - INFO - _internal.py:187 - 127.0.0.1 - - [28/Sep/2025 15:55:14] "GET /static/js/app.js HTTP/1.1" 200 -
2025-09-28 15:55:14,758 - werkzeug - INFO - _internal.py:187 - 127.0.0.1 - - [28/Sep/2025 15:55:14] "GET /api/accounts/status HTTP/1.1" 200 -
2025-09-28 17:02:21,933 - services.scheduler - INFO - scheduler.py:18 - PostScheduler parado
2025-09-28 17:02:21,939 - app - INFO - app.py:790 - Application shutdown complete
2025-09-28 17:02:21,940 - services.scheduler - INFO - scheduler.py:18 - PostScheduler parado
2025-09-28 17:02:21,959 - models.database - INFO - database.py:102 - Database initialized successfully
2025-09-28 17:02:21,962 - services.scheduler - INFO - scheduler.py:13 - PostScheduler iniciado
2025-09-28 17:02:21,964 - app - INFO - app.py:763 - Application context initialized successfully
2025-09-28 17:02:21,965 - app - INFO - app.py:775 - Starting Social Media Automation System on 0.0.0.0:5000
2025-09-28 17:02:21,966 - app - INFO - app.py:776 - Debug mode: False
2025-09-28 17:02:21,966 - app - INFO - app.py:777 - Upload folder: uploads
2025-09-28 17:02:22,043 - werkzeug - INFO - _internal.py:187 - [31m[1mWARNING: This is a development server. Do not use it in a production deployment. Use a production WSGI server instead.[0m
 * Running on all addresses (0.0.0.0)
 * Running on http://127.0.0.1:5000
 * Running on http://192.168.0.7:5000
2025-09-28 17:02:22,045 - werkzeug - INFO - _internal.py:187 - [33mPress CTRL+C to quit[0m
2025-09-28 17:02:24,097 - services.scheduler - INFO - scheduler.py:18 - PostScheduler parado
2025-09-28 17:02:24,098 - app - INFO - app.py:790 - Application shutdown complete
2025-09-28 17:02:43,304 - root - INFO - logger.py:49 - Social Media Automation System logging initialized
2025-09-28 17:08:57,778 - root - INFO - logger.py:49 - Social Media Automation System logging initialized
2025-09-28 17:08:57,780 - __main__ - WARNING - run.py:47 - Configuration warnings:
2025-09-28 17:08:57,780 - __main__ - WARNING - run.py:49 -   - Missing API keys for: YouTube
2025-09-28 17:08:57,781 - __main__ - WARNING - run.py:49 -   - Please change the default JWT_SECRET_KEY in production
2025-09-28 17:08:57,785 - models.database - INFO - database.py:102 - Database initialized successfully
2025-09-28 17:08:57,786 - services.ai_service - ERROR - ai_service.py:26 - Failed to initialize OpenAI client: AsyncClient.__init__() got an unexpected keyword argument 'proxies'
2025-09-28 17:08:57,821 - __main__ - ERROR - run.py:80 - Application startup failed: View function mapping is overwriting an existing endpoint function: start_youtube_oauth
2025-09-28 17:09:19,775 - root - INFO - logger.py:49 - Social Media Automation System logging initialized
2025-09-28 17:09:19,804 - models.database - INFO - database.py:102 - Database initialized successfully
2025-09-28 17:09:19,806 - services.ai_service - ERROR - ai_service.py:26 - Failed to initialize OpenAI client: AsyncClient.__init__() got an unexpected keyword argument 'proxies'
2025-09-28 17:09:19,870 - models.database - INFO - database.py:102 - Database initialized successfully
2025-09-28 17:09:19,872 - services.ai_service - ERROR - ai_service.py:26 - Failed to initialize OpenAI client: AsyncClient.__init__() got an unexpected keyword argument 'proxies'
2025-09-28 17:09:19,928 - models.database - INFO - database.py:102 - Database initialized successfully
2025-09-28 17:09:19,931 - services.ai_service - ERROR - ai_service.py:26 - Failed to initialize OpenAI client: AsyncClient.__init__() got an unexpected keyword argument 'proxies'
2025-09-28 17:09:19,978 - models.database - INFO - database.py:102 - Database initialized successfully
2025-09-28 17:09:19,980 - services.ai_service - ERROR - ai_service.py:26 - Failed to initialize OpenAI client: AsyncClient.__init__() got an unexpected keyword argument 'proxies'
2025-09-28 17:09:20,060 - models.database - INFO - database.py:102 - Database initialized successfully
2025-09-28 17:09:20,061 - services.ai_service - ERROR - ai_service.py:26 - Failed to initialize OpenAI client: AsyncClient.__init__() got an unexpected keyword argument 'proxies'
2025-09-28 17:09:20,226 - models.database - INFO - database.py:102 - Database initialized successfully
2025-09-28 17:09:20,246 - services.ai_service - ERROR - ai_service.py:26 - Failed to initialize OpenAI client: AsyncClient.__init__() got an unexpected keyword argument 'proxies'
2025-09-28 17:09:20,328 - models.database - INFO - database.py:102 - Database initialized successfully
2025-09-28 17:09:20,332 - services.ai_service - ERROR - ai_service.py:26 - Failed to initialize OpenAI client: AsyncClient.__init__() got an unexpected keyword argument 'proxies'
2025-09-28 17:09:20,386 - models.database - INFO - database.py:102 - Database initialized successfully
2025-09-28 17:09:20,387 - services.ai_service - ERROR - ai_service.py:26 - Failed to initialize OpenAI client: AsyncClient.__init__() got an unexpected keyword argument 'proxies'
2025-09-28 17:09:20,437 - models.database - INFO - database.py:102 - Database initialized successfully
2025-09-28 17:09:20,438 - services.ai_service - ERROR - ai_service.py:26 - Failed to initialize OpenAI client: AsyncClient.__init__() got an unexpected keyword argument 'proxies'
2025-09-28 17:09:20,498 - models.database - INFO - database.py:102 - Database initialized successfully
2025-09-28 17:09:20,499 - services.ai_service - ERROR - ai_service.py:26 - Failed to initialize OpenAI client: AsyncClient.__init__() got an unexpected keyword argument 'proxies'
2025-09-28 17:09:20,569 - models.database - INFO - database.py:102 - Database initialized successfully
2025-09-28 17:09:20,571 - services.ai_service - ERROR - ai_service.py:26 - Failed to initialize OpenAI client: AsyncClient.__init__() got an unexpected keyword argument 'proxies'
2025-09-28 17:09:20,629 - models.database - INFO - database.py:102 - Database initialized successfully
2025-09-28 17:09:20,636 - services.ai_service - ERROR - ai_service.py:26 - Failed to initialize OpenAI client: AsyncClient.__init__() got an unexpected keyword argument 'proxies'
2025-09-28 17:09:20,694 - models.database - INFO - database.py:102 - Database initialized successfully
2025-09-28 17:09:20,695 - services.ai_service - ERROR - ai_service.py:26 - Failed to initialize OpenAI client: AsyncClient.__init__() got an unexpected keyword argument 'proxies'
2025-09-28 17:09:20,748 - models.database - INFO - database.py:102 - Database initialized successfully
2025-09-28 17:09:20,749 - services.ai_service - ERROR - ai_service.py:26 - Failed to initialize OpenAI client: AsyncClient.__init__() got an unexpected keyword argument 'proxies'
2025-09-28 17:09:20,801 - models.database - INFO - database.py:102 - Database initialized successfully
2025-09-28 17:09:20,805 - services.ai_service - ERROR - ai_service.py:26 - Failed to initialize OpenAI client: AsyncClient.__init__() got an unexpected keyword argument 'proxies'
2025-09-28 17:09:20,865 - models.database - INFO - database.py:102 - Database initialized successfully
2025-09-28 17:09:20,868 - services.ai_service - ERROR - ai_service.py:26 - Failed to initialize OpenAI client: AsyncClient.__init__() got an unexpected keyword argument 'proxies'
2025-09-28 17:09:20,939 - models.database - INFO - database.py:102 - Database initialized successfully
2025-09-28 17:09:20,940 - services.ai_service - ERROR - ai_service.py:26 - Failed to initialize OpenAI client: AsyncClient.__init__() got an unexpected keyword argument 'proxies'
2025-09-28 17:09:21,022 - models.database - INFO - database.py:102 - Database initialized successfully
2025-09-28 17:09:21,027 - services.ai_service - ERROR - ai_service.py:26 - Failed to initialize OpenAI client: AsyncClient.__init__() got an unexpected keyword argument 'proxies'
2025-09-28 17:09:21,117 - models.database - INFO - database.py:102 - Database initialized successfully
2025-09-28 17:09:21,118 - services.ai_service - ERROR - ai_service.py:26 - Failed to initialize OpenAI client: AsyncClient.__init__() got an unexpected keyword argument 'proxies'
2025-09-28 17:09:21,166 - models.database - INFO - database.py:102 - Database initialized successfully
2025-09-28 17:09:21,167 - services.ai_service - ERROR - ai_service.py:26 - Failed to initialize OpenAI client: AsyncClient.__init__() got an unexpected keyword argument 'proxies'
2025-09-28 17:09:21,244 - models.database - INFO - database.py:102 - Database initialized successfully
2025-09-28 17:09:21,246 - services.ai_service - ERROR - ai_service.py:26 - Failed to initialize OpenAI client: AsyncClient.__init__() got an unexpected keyword argument 'proxies'
2025-09-28 17:09:21,294 - models.database - INFO - database.py:102 - Database initialized successfully
2025-09-28 17:09:21,296 - services.ai_service - ERROR - ai_service.py:26 - Failed to initialize OpenAI client: AsyncClient.__init__() got an unexpected keyword argument 'proxies'
2025-09-28 17:09:21,350 - models.database - INFO - database.py:102 - Database initialized successfully
2025-09-28 17:09:21,353 - services.ai_service - ERROR - ai_service.py:26 - Failed to initialize OpenAI client: AsyncClient.__init__() got an unexpected keyword argument 'proxies'
2025-09-28 17:09:21,401 - models.database - INFO - database.py:102 - Database initialized successfully
2025-09-28 17:09:21,402 - services.ai_service - ERROR - ai_service.py:26 - Failed to initialize OpenAI client: AsyncClient.__init__() got an unexpected keyword argument 'proxies'
2025-09-28 17:09:21,453 - models.database - INFO - database.py:102 - Database initialized successfully
2025-09-28 17:09:21,454 - services.ai_service - ERROR - ai_service.py:26 - Failed to initialize OpenAI client: AsyncClient.__init__() got an unexpected keyword argument 'proxies'
2025-09-28 17:09:21,526 - models.database - INFO - database.py:102 - Database initialized successfully
2025-09-28 17:09:21,527 - services.ai_service - ERROR - ai_service.py:26 - Failed to initialize OpenAI client: AsyncClient.__init__() got an unexpected keyword argument 'proxies'
2025-09-28 17:09:21,590 - models.database - INFO - database.py:102 - Database initialized successfully
2025-09-28 17:09:21,592 - services.ai_service - ERROR - ai_service.py:26 - Failed to initialize OpenAI client: AsyncClient.__init__() got an unexpected keyword argument 'proxies'
2025-09-28 17:09:21,741 - models.database - INFO - database.py:102 - Database initialized successfully
2025-09-28 17:09:21,742 - services.ai_service - ERROR - ai_service.py:26 - Failed to initialize OpenAI client: AsyncClient.__init__() got an unexpected keyword argument 'proxies'
2025-09-28 17:09:21,823 - models.database - INFO - database.py:102 - Database initialized successfully
2025-09-28 17:09:21,824 - services.ai_service - ERROR - ai_service.py:26 - Failed to initialize OpenAI client: AsyncClient.__init__() got an unexpected keyword argument 'proxies'
2025-09-28 17:09:21,897 - models.database - INFO - database.py:102 - Database initialized successfully
2025-09-28 17:09:21,899 - services.ai_service - ERROR - ai_service.py:26 - Failed to initialize OpenAI client: AsyncClient.__init__() got an unexpected keyword argument 'proxies'
2025-09-28 17:09:21,948 - models.database - INFO - database.py:102 - Database initialized successfully
2025-09-28 17:09:21,950 - services.ai_service - ERROR - ai_service.py:26 - Failed to initialize OpenAI client: AsyncClient.__init__() got an unexpected keyword argument 'proxies'
2025-09-28 17:09:22,005 - models.database - INFO - database.py:102 - Database initialized successfully
2025-09-28 17:09:22,006 - services.ai_service - ERROR - ai_service.py:26 - Failed to initialize OpenAI client: AsyncClient.__init__() got an unexpected keyword argument 'proxies'
2025-09-28 17:09:22,058 - models.database - INFO - database.py:102 - Database initialized successfully
2025-09-28 17:09:22,060 - services.ai_service - ERROR - ai_service.py:26 - Failed to initialize OpenAI client: AsyncClient.__init__() got an unexpected keyword argument 'proxies'
2025-09-28 17:09:22,115 - models.database - INFO - database.py:102 - Database initialized successfully
2025-09-28 17:09:22,119 - services.ai_service - ERROR - ai_service.py:26 - Failed to initialize OpenAI client: AsyncClient.__init__() got an unexpected keyword argument 'proxies'
2025-09-28 17:09:22,183 - models.database - INFO - database.py:102 - Database initialized successfully
2025-09-28 17:09:22,187 - services.ai_service - ERROR - ai_service.py:26 - Failed to initialize OpenAI client: AsyncClient.__init__() got an unexpected keyword argument 'proxies'
2025-09-28 17:09:22,246 - models.database - INFO - database.py:102 - Database initialized successfully
2025-09-28 17:09:22,247 - services.ai_service - ERROR - ai_service.py:26 - Failed to initialize OpenAI client: AsyncClient.__init__() got an unexpected keyword argument 'proxies'
2025-09-28 17:09:22,310 - models.database - INFO - database.py:102 - Database initialized successfully
2025-09-28 17:09:22,312 - services.ai_service - ERROR - ai_service.py:26 - Failed to initialize OpenAI client: AsyncClient.__init__() got an unexpected keyword argument 'proxies'
2025-09-28 17:09:22,380 - models.database - INFO - database.py:102 - Database initialized successfully
2025-09-28 17:09:22,383 - services.ai_service - ERROR - ai_service.py:26 - Failed to initialize OpenAI client: AsyncClient.__init__() got an unexpected keyword argument 'proxies'
2025-09-28 17:09:22,441 - models.database - INFO - database.py:102 - Database initialized successfully
2025-09-28 17:09:22,442 - services.ai_service - ERROR - ai_service.py:26 - Failed to initialize OpenAI client: AsyncClient.__init__() got an unexpected keyword argument 'proxies'
2025-09-28 17:09:22,513 - models.database - INFO - database.py:102 - Database initialized successfully
2025-09-28 17:09:22,514 - services.ai_service - ERROR - ai_service.py:26 - Failed to initialize OpenAI client: AsyncClient.__init__() got an unexpected keyword argument 'proxies'
2025-09-28 17:09:22,562 - models.database - INFO - database.py:102 - Database initialized successfully
2025-09-28 17:09:22,564 - services.ai_service - ERROR - ai_service.py:26 - Failed to initialize OpenAI client: AsyncClient.__init__() got an unexpected keyword argument 'proxies'
2025-09-28 17:09:22,622 - models.database - INFO - database.py:102 - Database initialized successfully
2025-09-28 17:09:22,623 - services.ai_service - ERROR - ai_service.py:26 - Failed to initialize OpenAI client: AsyncClient.__init__() got an unexpected keyword argument 'proxies'
2025-09-28 17:09:22,684 - models.database - INFO - database.py:102 - Database initialized successfully
2025-09-28 17:09:22,686 - services.ai_service - ERROR - ai_service.py:26 - Failed to initialize OpenAI client: AsyncClient.__init__() got an unexpected keyword argument 'proxies'
2025-09-28 17:09:22,747 - models.database - INFO - database.py:102 - Database initialized successfully
2025-09-28 17:09:22,748 - services.ai_service - ERROR - ai_service.py:26 - Failed to initialize OpenAI client: AsyncClient.__init__() got an unexpected keyword argument 'proxies'
2025-09-28 17:09:22,809 - models.database - INFO - database.py:102 - Database initialized successfully
2025-09-28 17:09:22,811 - services.ai_service - ERROR - ai_service.py:26 - Failed to initialize OpenAI client: AsyncClient.__init__() got an unexpected keyword argument 'proxies'
2025-09-28 17:09:22,857 - models.database - INFO - database.py:102 - Database initialized successfully
2025-09-28 17:09:22,859 - services.ai_service - ERROR - ai_service.py:26 - Failed to initialize OpenAI client: AsyncClient.__init__() got an unexpected keyword argument 'proxies'
2025-09-28 17:09:22,915 - models.database - INFO - database.py:102 - Database initialized successfully
2025-09-28 17:09:22,918 - services.ai_service - ERROR - ai_service.py:26 - Failed to initialize OpenAI client: AsyncClient.__init__() got an unexpected keyword argument 'proxies'
2025-09-28 17:09:22,975 - models.database - INFO - database.py:102 - Database initialized successfully
2025-09-28 17:09:22,976 - services.ai_service - ERROR - ai_service.py:26 - Failed to initialize OpenAI client: AsyncClient.__init__() got an unexpected keyword argument 'proxies'
2025-09-28 17:09:23,027 - models.database - INFO - database.py:102 - Database initialized successfully
2025-09-28 17:09:23,028 - services.ai_service - ERROR - ai_service.py:26 - Failed to initialize OpenAI client: AsyncClient.__init__() got an unexpected keyword argument 'proxies'
2025-09-28 17:09:23,079 - models.database - INFO - database.py:102 - Database initialized successfully
2025-09-28 17:09:23,081 - services.ai_service - ERROR - ai_service.py:26 - Failed to initialize OpenAI client: AsyncClient.__init__() got an unexpected keyword argument 'proxies'
2025-09-28 17:09:23,144 - models.database - INFO - database.py:102 - Database initialized successfully
2025-09-28 17:09:23,147 - services.ai_service - ERROR - ai_service.py:26 - Failed to initialize OpenAI client: AsyncClient.__init__() got an unexpected keyword argument 'proxies'
2025-09-28 17:09:23,205 - models.database - INFO - database.py:102 - Database initialized successfully
2025-09-28 17:09:23,206 - services.ai_service - ERROR - ai_service.py:26 - Failed to initialize OpenAI client: AsyncClient.__init__() got an unexpected keyword argument 'proxies'
2025-09-28 17:09:23,255 - models.database - INFO - database.py:102 - Database initialized successfully
2025-09-28 17:09:23,256 - services.ai_service - ERROR - ai_service.py:26 - Failed to initialize OpenAI client: AsyncClient.__init__() got an unexpected keyword argument 'proxies'
2025-09-28 17:09:23,303 - models.database - INFO - database.py:102 - Database initialized successfully
2025-09-28 17:09:23,304 - services.ai_service - ERROR - ai_service.py:26 - Failed to initialize OpenAI client: AsyncClient.__init__() got an unexpected keyword argument 'proxies'
2025-09-28 17:09:23,361 - models.database - INFO - database.py:102 - Database initialized successfully
2025-09-28 17:09:23,362 - services.ai_service - ERROR - ai_service.py:26 - Failed to initialize OpenAI client: AsyncClient.__init__() got an unexpected keyword argument 'proxies'
2025-09-28 17:09:23,412 - models.database - INFO - database.py:102 - Database initialized successfully
2025-09-28 17:09:23,413 - services.ai_service - ERROR - ai_service.py:26 - Failed to initialize OpenAI client: AsyncClient.__init__() got an unexpected keyword argument 'proxies'
2025-09-28 17:09:23,494 - models.database - INFO - database.py:102 - Database initialized successfully
2025-09-28 17:09:23,495 - services.ai_service - ERROR - ai_service.py:26 - Failed to initialize OpenAI client: AsyncClient.__init__() got an unexpected keyword argument 'proxies'
2025-09-28 17:09:23,578 - models.database - INFO - database.py:102 - Database initialized successfully
2025-09-28 17:09:23,580 - services.ai_service - ERROR - ai_service.py:26 - Failed to initialize OpenAI client: AsyncClient.__init__() got an unexpected keyword argument 'proxies'
2025-09-28 17:09:23,633 - models.database - INFO - database.py:102 - Database initialized successfully
2025-09-28 17:09:23,634 - services.ai_service - ERROR - ai_service.py:26 - Failed to initialize OpenAI client: AsyncClient.__init__() got an unexpected keyword argument 'proxies'
2025-09-28 17:09:23,692 - models.database - INFO - database.py:102 - Database initialized successfully
2025-09-28 17:09:23,693 - services.ai_service - ERROR - ai_service.py:26 - Failed to initialize OpenAI client: AsyncClient.__init__() got an unexpected keyword argument 'proxies'
2025-09-28 17:09:23,745 - models.database - INFO - database.py:102 - Database initialized successfully
2025-09-28 17:09:23,746 - services.ai_service - ERROR - ai_service.py:26 - Failed to initialize OpenAI client: AsyncClient.__init__() got an unexpected keyword argument 'proxies'
2025-09-28 17:09:23,799 - models.database - INFO - database.py:102 - Database initialized successfully
2025-09-28 17:09:23,800 - services.ai_service - ERROR - ai_service.py:26 - Failed to initialize OpenAI client: AsyncClient.__init__() got an unexpected keyword argument 'proxies'
2025-09-28 17:09:23,866 - models.database - INFO - database.py:102 - Database initialized successfully
2025-09-28 17:09:23,868 - services.ai_service - ERROR - ai_service.py:26 - Failed to initialize OpenAI client: AsyncClient.__init__() got an unexpected keyword argument 'proxies'
2025-09-28 17:09:23,925 - models.database - INFO - database.py:102 - Database initialized successfully
2025-09-28 17:09:23,926 - services.ai_service - ERROR - ai_service.py:26 - Failed to initialize OpenAI client: AsyncClient.__init__() got an unexpected keyword argument 'proxies'
2025-09-28 17:09:23,993 - models.database - INFO - database.py:102 - Database initialized successfully
2025-09-28 17:09:23,994 - services.ai_service - ERROR - ai_service.py:26 - Failed to initialize OpenAI client: AsyncClient.__init__() got an unexpected keyword argument 'proxies'
2025-09-28 17:09:24,045 - models.database - INFO - database.py:102 - Database initialized successfully
2025-09-28 17:09:24,046 - services.ai_service - ERROR - ai_service.py:26 - Failed to initialize OpenAI client: AsyncClient.__init__() got an unexpected keyword argument 'proxies'
2025-09-28 17:09:24,118 - models.database - INFO - database.py:102 - Database initialized successfully
2025-09-28 17:09:24,120 - services.ai_service - ERROR - ai_service.py:26 - Failed to initialize OpenAI client: AsyncClient.__init__() got an unexpected keyword argument 'proxies'
2025-09-28 17:09:24,174 - models.database - INFO - database.py:102 - Database initialized successfully
2025-09-28 17:09:24,175 - services.ai_service - ERROR - ai_service.py:26 - Failed to initialize OpenAI client: AsyncClient.__init__() got an unexpected keyword argument 'proxies'
2025-09-28 17:09:24,230 - models.database - INFO - database.py:102 - Database initialized successfully
2025-09-28 17:09:24,231 - services.ai_service - ERROR - ai_service.py:26 - Failed to initialize OpenAI client: AsyncClient.__init__() got an unexpected keyword argument 'proxies'
2025-09-28 17:09:24,276 - models.database - INFO - database.py:102 - Database initialized successfully
2025-09-28 17:09:24,277 - services.ai_service - ERROR - ai_service.py:26 - Failed to initialize OpenAI client: AsyncClient.__init__() got an unexpected keyword argument 'proxies'
2025-09-28 17:09:24,324 - models.database - INFO - database.py:102 - Database initialized successfully
2025-09-28 17:09:24,325 - services.ai_service - ERROR - ai_service.py:26 - Failed to initialize OpenAI client: AsyncClient.__init__() got an unexpected keyword argument 'proxies'
2025-09-28 17:09:24,372 - models.database - INFO - database.py:102 - Database initialized successfully
2025-09-28 17:09:24,373 - services.ai_service - ERROR - ai_service.py:26 - Failed to initialize OpenAI client: AsyncClient.__init__() got an unexpected keyword argument 'proxies'
2025-09-28 17:09:24,430 - models.database - INFO - database.py:102 - Database initialized successfully
2025-09-28 17:09:24,432 - services.ai_service - ERROR - ai_service.py:26 - Failed to initialize OpenAI client: AsyncClient.__init__() got an unexpected keyword argument 'proxies'
2025-09-28 17:09:24,488 - models.database - INFO - database.py:102 - Database initialized successfully
2025-09-28 17:09:24,489 - services.ai_service - ERROR - ai_service.py:26 - Failed to initialize OpenAI client: AsyncClient.__init__() got an unexpected keyword argument 'proxies'
2025-09-28 17:09:24,546 - models.database - INFO - database.py:102 - Database initialized successfully
2025-09-28 17:09:24,547 - services.ai_service - ERROR - ai_service.py:26 - Failed to initialize OpenAI client: AsyncClient.__init__() got an unexpected keyword argument 'proxies'
2025-09-28 17:09:24,624 - models.database - INFO - database.py:102 - Database initialized successfully
2025-09-28 17:09:24,626 - services.ai_service - ERROR - ai_service.py:26 - Failed to initialize OpenAI client: AsyncClient.__init__() got an unexpected keyword argument 'proxies'
2025-09-28 17:09:24,798 - models.database - INFO - database.py:102 - Database initialized successfully
2025-09-28 17:09:24,800 - services.ai_service - ERROR - ai_service.py:26 - Failed to initialize OpenAI client: AsyncClient.__init__() got an unexpected keyword argument 'proxies'
2025-09-28 17:09:24,917 - models.database - INFO - database.py:102 - Database initialized successfully
2025-09-28 17:09:24,919 - services.ai_service - ERROR - ai_service.py:26 - Failed to initialize OpenAI client: AsyncClient.__init__() got an unexpected keyword argument 'proxies'
2025-09-28 17:09:24,980 - models.database - INFO - database.py:102 - Database initialized successfully
2025-09-28 17:09:24,981 - services.ai_service - ERROR - ai_service.py:26 - Failed to initialize OpenAI client: AsyncClient.__init__() got an unexpected keyword argument 'proxies'
2025-09-28 17:09:25,037 - models.database - INFO - database.py:102 - Database initialized successfully
2025-09-28 17:09:25,038 - services.ai_service - ERROR - ai_service.py:26 - Failed to initialize OpenAI client: AsyncClient.__init__() got an unexpected keyword argument 'proxies'
2025-09-28 17:09:25,094 - models.database - INFO - database.py:102 - Database initialized successfully
2025-09-28 17:09:25,096 - services.ai_service - ERROR - ai_service.py:26 - Failed to initialize OpenAI client: AsyncClient.__init__() got an unexpected keyword argument 'proxies'
2025-09-28 17:09:25,187 - models.database - INFO - database.py:102 - Database initialized successfully
2025-09-28 17:09:25,188 - services.ai_service - ERROR - ai_service.py:26 - Failed to initialize OpenAI client: AsyncClient.__init__() got an unexpected keyword argument 'proxies'
2025-09-28 17:09:25,307 - models.database - INFO - database.py:102 - Database initialized successfully
2025-09-28 17:09:25,309 - services.ai_service - ERROR - ai_service.py:26 - Failed to initialize OpenAI client: AsyncClient.__init__() got an unexpected keyword argument 'proxies'
2025-09-28 17:09:25,363 - models.database - INFO - database.py:102 - Database initialized successfully
2025-09-28 17:09:25,364 - services.ai_service - ERROR - ai_service.py:26 - Failed to initialize OpenAI client: AsyncClient.__init__() got an unexpected keyword argument 'proxies'
2025-09-28 17:09:25,446 - models.database - INFO - database.py:102 - Database initialized successfully
2025-09-28 17:09:25,447 - services.ai_service - ERROR - ai_service.py:26 - Failed to initialize OpenAI client: AsyncClient.__init__() got an unexpected keyword argument 'proxies'
2025-09-28 17:09:25,512 - models.database - INFO - database.py:102 - Database initialized successfully
2025-09-28 17:09:25,514 - services.ai_service - ERROR - ai_service.py:26 - Failed to initialize OpenAI client: AsyncClient.__init__() got an unexpected keyword argument 'proxies'
2025-09-28 17:09:25,583 - models.database - INFO - database.py:102 - Database initialized successfully
2025-09-28 17:09:25,585 - services.ai_service - ERROR - ai_service.py:26 - Failed to initialize OpenAI client: AsyncClient.__init__() got an unexpected keyword argument 'proxies'
2025-09-28 17:09:25,643 - models.database - INFO - database.py:102 - Database initialized successfully
2025-09-28 17:09:25,644 - services.ai_service - ERROR - ai_service.py:26 - Failed to initialize OpenAI client: AsyncClient.__init__() got an unexpected keyword argument 'proxies'
2025-09-28 17:09:25,727 - models.database - INFO - database.py:102 - Database initialized successfully
2025-09-28 17:09:25,729 - services.ai_service - ERROR - ai_service.py:26 - Failed to initialize OpenAI client: AsyncClient.__init__() got an unexpected keyword argument 'proxies'
2025-09-28 17:09:25,782 - models.database - INFO - database.py:102 - Database initialized successfully
2025-09-28 17:09:25,783 - services.ai_service - ERROR - ai_service.py:26 - Failed to initialize OpenAI client: AsyncClient.__init__() got an unexpected keyword argument 'proxies'
2025-09-28 17:09:25,850 - models.database - INFO - database.py:102 - Database initialized successfully
2025-09-28 17:09:25,851 - services.ai_service - ERROR - ai_service.py:26 - Failed to initialize OpenAI client: AsyncClient.__init__() got an unexpected keyword argument 'proxies'
2025-09-28 17:09:25,900 - models.database - INFO - database.py:102 - Database initialized successfully
2025-09-28 17:09:25,902 - services.ai_service - ERROR - ai_service.py:26 - Failed to initialize OpenAI client: AsyncClient.__init__() got an unexpected keyword argument 'proxies'
2025-09-28 17:09:26,004 - models.database - INFO - database.py:102 - Database initialized successfully
2025-09-28 17:09:26,036 - services.ai_service - ERROR - ai_service.py:26 - Failed to initialize OpenAI client: AsyncClient.__init__() got an unexpected keyword argument 'proxies'
2025-09-28 17:09:26,135 - models.database - INFO - database.py:102 - Database initialized successfully
2025-09-28 17:09:26,152 - services.ai_service - ERROR - ai_service.py:26 - Failed to initialize OpenAI client: AsyncClient.__init__() got an unexpected keyword argument 'proxies'
2025-09-28 17:09:26,248 - models.database - INFO - database.py:102 - Database initialized successfully
2025-09-28 17:09:26,257 - services.ai_service - ERROR - ai_service.py:26 - Failed to initialize OpenAI client: AsyncClient.__init__() got an unexpected keyword argument 'proxies'
2025-09-28 17:09:26,348 - models.database - INFO - database.py:102 - Database initialized successfully
2025-09-28 17:09:26,371 - services.ai_service - ERROR - ai_service.py:26 - Failed to initialize OpenAI client: AsyncClient.__init__() got an unexpected keyword argument 'proxies'
2025-09-28 17:09:26,561 - models.database - INFO - database.py:102 - Database initialized successfully
2025-09-28 17:09:26,562 - services.ai_service - ERROR - ai_service.py:26 - Failed to initialize OpenAI client: AsyncClient.__init__() got an unexpected keyword argument 'proxies'
2025-09-28 17:09:26,618 - models.database - INFO - database.py:102 - Database initialized successfully
2025-09-28 17:09:26,619 - services.ai_service - ERROR - ai_service.py:26 - Failed to initialize OpenAI client: AsyncClient.__init__() got an unexpected keyword argument 'proxies'
2025-09-28 17:09:26,674 - models.database - INFO - database.py:102 - Database initialized successfully
2025-09-28 17:09:26,675 - services.ai_service - ERROR - ai_service.py:26 - Failed to initialize OpenAI client: AsyncClient.__init__() got an unexpected keyword argument 'proxies'
2025-09-28 17:09:26,733 - models.database - INFO - database.py:102 - Database initialized successfully
2025-09-28 17:09:26,735 - services.ai_service - ERROR - ai_service.py:26 - Failed to initialize OpenAI client: AsyncClient.__init__() got an unexpected keyword argument 'proxies'
2025-09-28 17:09:26,786 - models.database - INFO - database.py:102 - Database initialized successfully
2025-09-28 17:09:26,787 - services.ai_service - ERROR - ai_service.py:26 - Failed to initialize OpenAI client: AsyncClient.__init__() got an unexpected keyword argument 'proxies'
2025-09-28 17:09:26,846 - models.database - INFO - database.py:102 - Database initialized successfully
2025-09-28 17:09:26,847 - services.ai_service - ERROR - ai_service.py:26 - Failed to initialize OpenAI client: AsyncClient.__init__() got an unexpected keyword argument 'proxies'
2025-09-28 17:09:26,902 - models.database - INFO - database.py:102 - Database initialized successfully
2025-09-28 17:09:26,905 - services.ai_service - ERROR - ai_service.py:26 - Failed to initialize OpenAI client: AsyncClient.__init__() got an unexpected keyword argument 'proxies'
2025-09-28 17:09:26,954 - models.database - INFO - database.py:102 - Database initialized successfully
2025-09-28 17:09:26,958 - services.ai_service - ERROR - ai_service.py:26 - Failed to initialize OpenAI client: AsyncClient.__init__() got an unexpected keyword argument 'proxies'
2025-09-28 17:09:27,021 - models.database - INFO - database.py:102 - Database initialized successfully
2025-09-28 17:09:27,023 - services.ai_service - ERROR - ai_service.py:26 - Failed to initialize OpenAI client: AsyncClient.__init__() got an unexpected keyword argument 'proxies'
2025-09-28 17:09:27,120 - models.database - INFO - database.py:102 - Database initialized successfully
2025-09-28 17:09:27,121 - services.ai_service - ERROR - ai_service.py:26 - Failed to initialize OpenAI client: AsyncClient.__init__() got an unexpected keyword argument 'proxies'
2025-09-28 17:09:27,177 - models.database - INFO - database.py:102 - Database initialized successfully
2025-09-28 17:09:27,179 - services.ai_service - ERROR - ai_service.py:26 - Failed to initialize OpenAI client: AsyncClient.__init__() got an unexpected keyword argument 'proxies'
2025-09-28 17:09:27,263 - models.database - INFO - database.py:102 - Database initialized successfully
2025-09-28 17:09:27,264 - services.ai_service - ERROR - ai_service.py:26 - Failed to initialize OpenAI client: AsyncClient.__init__() got an unexpected keyword argument 'proxies'
2025-09-28 17:09:27,322 - models.database - INFO - database.py:102 - Database initialized successfully
2025-09-28 17:09:27,323 - services.ai_service - ERROR - ai_service.py:26 - Failed to initialize OpenAI client: AsyncClient.__init__() got an unexpected keyword argument 'proxies'
2025-09-28 17:09:27,382 - models.database - INFO - database.py:102 - Database initialized successfully
2025-09-28 17:09:27,383 - services.ai_service - ERROR - ai_service.py:26 - Failed to initialize OpenAI client: AsyncClient.__init__() got an unexpected keyword argument 'proxies'
2025-09-28 17:09:27,434 - models.database - INFO - database.py:102 - Database initialized successfully
2025-09-28 17:09:27,436 - services.ai_service - ERROR - ai_service.py:26 - Failed to initialize OpenAI client: AsyncClient.__init__() got an unexpected keyword argument 'proxies'
2025-09-28 17:09:27,486 - models.database - INFO - database.py:102 - Database initialized successfully
2025-09-28 17:09:27,488 - services.ai_service - ERROR - ai_service.py:26 - Failed to initialize OpenAI client: AsyncClient.__init__() got an unexpected keyword argument 'proxies'
2025-09-28 17:09:27,546 - models.database - INFO - database.py:102 - Database initialized successfully
2025-09-28 17:09:27,547 - services.ai_service - ERROR - ai_service.py:26 - Failed to initialize OpenAI client: AsyncClient.__init__() got an unexpected keyword argument 'proxies'
2025-09-28 17:09:27,606 - models.database - INFO - database.py:102 - Database initialized successfully
2025-09-28 17:09:27,608 - services.ai_service - ERROR - ai_service.py:26 - Failed to initialize OpenAI client: AsyncClient.__init__() got an unexpected keyword argument 'proxies'
2025-09-28 17:09:27,684 - models.database - INFO - database.py:102 - Database initialized successfully
2025-09-28 17:09:27,686 - services.ai_service - ERROR - ai_service.py:26 - Failed to initialize OpenAI client: AsyncClient.__init__() got an unexpected keyword argument 'proxies'
2025-09-28 17:09:27,758 - models.database - INFO - database.py:102 - Database initialized successfully
2025-09-28 17:09:27,760 - services.ai_service - ERROR - ai_service.py:26 - Failed to initialize OpenAI client: AsyncClient.__init__() got an unexpected keyword argument 'proxies'
2025-09-28 17:09:27,824 - models.database - INFO - database.py:102 - Database initialized successfully
2025-09-28 17:09:27,825 - services.ai_service - ERROR - ai_service.py:26 - Failed to initialize OpenAI client: AsyncClient.__init__() got an unexpected keyword argument 'proxies'
2025-09-28 17:09:27,870 - models.database - INFO - database.py:102 - Database initialized successfully
2025-09-28 17:09:27,872 - services.ai_service - ERROR - ai_service.py:26 - Failed to initialize OpenAI client: AsyncClient.__init__() got an unexpected keyword argument 'proxies'
2025-09-28 17:09:27,930 - models.database - INFO - database.py:102 - Database initialized successfully
2025-09-28 17:09:27,931 - services.ai_service - ERROR - ai_service.py:26 - Failed to initialize OpenAI client: AsyncClient.__init__() got an unexpected keyword argument 'proxies'
2025-09-28 17:09:27,986 - models.database - INFO - database.py:102 - Database initialized successfully
2025-09-28 17:09:27,989 - services.ai_service - ERROR - ai_service.py:26 - Failed to initialize OpenAI client: AsyncClient.__init__() got an unexpected keyword argument 'proxies'
2025-09-28 17:09:28,061 - models.database - INFO - database.py:102 - Database initialized successfully
2025-09-28 17:09:28,062 - services.ai_service - ERROR - ai_service.py:26 - Failed to initialize OpenAI client: AsyncClient.__init__() got an unexpected keyword argument 'proxies'
2025-09-28 17:09:28,127 - models.database - INFO - database.py:102 - Database initialized successfully
2025-09-28 17:09:28,128 - services.ai_service - ERROR - ai_service.py:26 - Failed to initialize OpenAI client: AsyncClient.__init__() got an unexpected keyword argument 'proxies'
2025-09-28 17:09:28,208 - models.database - INFO - database.py:102 - Database initialized successfully
2025-09-28 17:09:28,210 - services.ai_service - ERROR - ai_service.py:26 - Failed to initialize OpenAI client: AsyncClient.__init__() got an unexpected keyword argument 'proxies'
2025-09-28 17:09:28,267 - models.database - INFO - database.py:102 - Database initialized successfully
2025-09-28 17:09:28,269 - services.ai_service - ERROR - ai_service.py:26 - Failed to initialize OpenAI client: AsyncClient.__init__() got an unexpected keyword argument 'proxies'
2025-09-28 17:09:28,319 - models.database - INFO - database.py:102 - Database initialized successfully
2025-09-28 17:09:28,320 - services.ai_service - ERROR - ai_service.py:26 - Failed to initialize OpenAI client: AsyncClient.__init__() got an unexpected keyword argument 'proxies'
2025-09-28 17:09:28,377 - models.database - INFO - database.py:102 - Database initialized successfully
2025-09-28 17:09:28,378 - services.ai_service - ERROR - ai_service.py:26 - Failed to initialize OpenAI client: AsyncClient.__init__() got an unexpected keyword argument 'proxies'
2025-09-28 17:09:28,425 - models.database - INFO - database.py:102 - Database initialized successfully
2025-09-28 17:09:28,426 - services.ai_service - ERROR - ai_service.py:26 - Failed to initialize OpenAI client: AsyncClient.__init__() got an unexpected keyword argument 'proxies'
2025-09-28 17:09:28,476 - models.database - INFO - database.py:102 - Database initialized successfully
2025-09-28 17:09:28,477 - services.ai_service - ERROR - ai_service.py:26 - Failed to initialize OpenAI client: AsyncClient.__init__() got an unexpected keyword argument 'proxies'
2025-09-28 17:09:28,530 - models.database - INFO - database.py:102 - Database initialized successfully
2025-09-28 17:09:28,531 - services.ai_service - ERROR - ai_service.py:26 - Failed to initialize OpenAI client: AsyncClient.__init__() got an unexpected keyword argument 'proxies'
2025-09-28 17:09:28,581 - models.database - INFO - database.py:102 - Database initialized successfully
2025-09-28 17:09:28,582 - services.ai_service - ERROR - ai_service.py:26 - Failed to initialize OpenAI client: AsyncClient.__init__() got an unexpected keyword argument 'proxies'
2025-09-28 17:09:28,626 - models.database - INFO - database.py:102 - Database initialized successfully
2025-09-28 17:09:28,627 - services.ai_service - ERROR - ai_service.py:26 - Failed to initialize OpenAI client: AsyncClient.__init__() got an unexpected keyword argument 'proxies'
2025-09-28 17:09:28,674 - models.database - INFO - database.py:102 - Database initialized successfully
2025-09-28 17:09:28,676 - services.ai_service - ERROR - ai_service.py:26 - Failed to initialize OpenAI client: AsyncClient.__init__() got an unexpected keyword argument 'proxies'
2025-09-28 17:09:28,735 - models.database - INFO - database.py:102 - Database initialized successfully
2025-09-28 17:09:28,736 - services.ai_service - ERROR - ai_service.py:26 - Failed to initialize OpenAI client: AsyncClient.__init__() got an unexpected keyword argument 'proxies'
2025-09-28 17:09:28,828 - models.database - INFO - database.py:102 - Database initialized successfully
2025-09-28 17:09:28,829 - services.ai_service - ERROR - ai_service.py:26 - Failed to initialize OpenAI client: AsyncClient.__init__() got an unexpected keyword argument 'proxies'
2025-09-28 17:09:28,876 - models.database - INFO - database.py:102 - Database initialized successfully
2025-09-28 17:09:28,880 - services.ai_service - ERROR - ai_service.py:26 - Failed to initialize OpenAI client: AsyncClient.__init__() got an unexpected keyword argument 'proxies'
2025-09-28 17:09:28,934 - models.database - INFO - database.py:102 - Database initialized successfully
2025-09-28 17:09:28,936 - services.ai_service - ERROR - ai_service.py:26 - Failed to initialize OpenAI client: AsyncClient.__init__() got an unexpected keyword argument 'proxies'
2025-09-28 17:09:29,060 - models.database - INFO - database.py:102 - Database initialized successfully
2025-09-28 17:09:29,061 - services.ai_service - ERROR - ai_service.py:26 - Failed to initialize OpenAI client: AsyncClient.__init__() got an unexpected keyword argument 'proxies'
2025-09-28 17:09:29,110 - models.database - INFO - database.py:102 - Database initialized successfully
2025-09-28 17:09:29,111 - services.ai_service - ERROR - ai_service.py:26 - Failed to initialize OpenAI client: AsyncClient.__init__() got an unexpected keyword argument 'proxies'
2025-09-28 17:09:29,166 - models.database - INFO - database.py:102 - Database initialized successfully
2025-09-28 17:09:29,168 - services.ai_service - ERROR - ai_service.py:26 - Failed to initialize OpenAI client: AsyncClient.__init__() got an unexpected keyword argument 'proxies'
2025-09-28 17:09:29,218 - models.database - INFO - database.py:102 - Database initialized successfully
2025-09-28 17:09:29,219 - services.ai_service - ERROR - ai_service.py:26 - Failed to initialize OpenAI client: AsyncClient.__init__() got an unexpected keyword argument 'proxies'
2025-09-28 17:09:29,268 - models.database - INFO - database.py:102 - Database initialized successfully
2025-09-28 17:09:29,270 - services.ai_service - ERROR - ai_service.py:26 - Failed to initialize OpenAI client: AsyncClient.__init__() got an unexpected keyword argument 'proxies'
2025-09-28 17:09:29,324 - models.database - INFO - database.py:102 - Database initialized successfully
2025-09-28 17:09:29,326 - services.ai_service - ERROR - ai_service.py:26 - Failed to initialize OpenAI client: AsyncClient.__init__() got an unexpected keyword argument 'proxies'
2025-09-28 17:09:29,372 - models.database - INFO - database.py:102 - Database initialized successfully
2025-09-28 17:09:29,376 - services.ai_service - ERROR - ai_service.py:26 - Failed to initialize OpenAI client: AsyncClient.__init__() got an unexpected keyword argument 'proxies'
2025-09-28 17:09:29,449 - models.database - INFO - database.py:102 - Database initialized successfully
2025-09-28 17:09:29,450 - services.ai_service - ERROR - ai_service.py:26 - Failed to initialize OpenAI client: AsyncClient.__init__() got an unexpected keyword argument 'proxies'
2025-09-28 17:09:29,520 - models.database - INFO - database.py:102 - Database initialized successfully
2025-09-28 17:09:29,523 - services.ai_service - ERROR - ai_service.py:26 - Failed to initialize OpenAI client: AsyncClient.__init__() got an unexpected keyword argument 'proxies'
2025-09-28 17:09:29,629 - models.database - INFO - database.py:102 - Database initialized successfully
2025-09-28 17:09:29,630 - services.ai_service - ERROR - ai_service.py:26 - Failed to initialize OpenAI client: AsyncClient.__init__() got an unexpected keyword argument 'proxies'
2025-09-28 17:09:29,708 - models.database - INFO - database.py:102 - Database initialized successfully
2025-09-28 17:09:29,710 - services.ai_service - ERROR - ai_service.py:26 - Failed to initialize OpenAI client: AsyncClient.__init__() got an unexpected keyword argument 'proxies'
2025-09-28 17:09:29,755 - models.database - INFO - database.py:102 - Database initialized successfully
2025-09-28 17:09:29,756 - services.ai_service - ERROR - ai_service.py:26 - Failed to initialize OpenAI client: AsyncClient.__init__() got an unexpected keyword argument 'proxies'
2025-09-28 17:09:29,806 - models.database - INFO - database.py:102 - Database initialized successfully
2025-09-28 17:09:29,808 - services.ai_service - ERROR - ai_service.py:26 - Failed to initialize OpenAI client: AsyncClient.__init__() got an unexpected keyword argument 'proxies'
2025-09-28 17:09:29,866 - models.database - INFO - database.py:102 - Database initialized successfully
2025-09-28 17:09:29,867 - services.ai_service - ERROR - ai_service.py:26 - Failed to initialize OpenAI client: AsyncClient.__init__() got an unexpected keyword argument 'proxies'
2025-09-28 17:09:29,930 - models.database - INFO - database.py:102 - Database initialized successfully
2025-09-28 17:09:29,931 - services.ai_service - ERROR - ai_service.py:26 - Failed to initialize OpenAI client: AsyncClient.__init__() got an unexpected keyword argument 'proxies'
2025-09-28 17:09:29,984 - models.database - INFO - database.py:102 - Database initialized successfully
2025-09-28 17:09:29,985 - services.ai_service - ERROR - ai_service.py:26 - Failed to initialize OpenAI client: AsyncClient.__init__() got an unexpected keyword argument 'proxies'
2025-09-28 17:09:30,042 - models.database - INFO - database.py:102 - Database initialized successfully
2025-09-28 17:09:30,043 - services.ai_service - ERROR - ai_service.py:26 - Failed to initialize OpenAI client: AsyncClient.__init__() got an unexpected keyword argument 'proxies'
2025-09-28 17:09:30,094 - models.database - INFO - database.py:102 - Database initialized successfully
2025-09-28 17:09:30,095 - services.ai_service - ERROR - ai_service.py:26 - Failed to initialize OpenAI client: AsyncClient.__init__() got an unexpected keyword argument 'proxies'
2025-09-28 17:09:30,139 - models.database - INFO - database.py:102 - Database initialized successfully
2025-09-28 17:09:30,141 - services.ai_service - ERROR - ai_service.py:26 - Failed to initialize OpenAI client: AsyncClient.__init__() got an unexpected keyword argument 'proxies'
2025-09-28 17:09:30,187 - models.database - INFO - database.py:102 - Database initialized successfully
2025-09-28 17:09:30,188 - services.ai_service - ERROR - ai_service.py:26 - Failed to initialize OpenAI client: AsyncClient.__init__() got an unexpected keyword argument 'proxies'
2025-09-28 17:09:30,243 - models.database - INFO - database.py:102 - Database initialized successfully
2025-09-28 17:09:30,244 - services.ai_service - ERROR - ai_service.py:26 - Failed to initialize OpenAI client: AsyncClient.__init__() got an unexpected keyword argument 'proxies'
2025-09-28 17:09:30,358 - models.database - INFO - database.py:102 - Database initialized successfully
2025-09-28 17:09:30,411 - services.ai_service - ERROR - ai_service.py:26 - Failed to initialize OpenAI client: AsyncClient.__init__() got an unexpected keyword argument 'proxies'
2025-09-28 17:09:30,503 - models.database - INFO - database.py:102 - Database initialized successfully
2025-09-28 17:09:30,504 - services.ai_service - ERROR - ai_service.py:26 - Failed to initialize OpenAI client: AsyncClient.__init__() got an unexpected keyword argument 'proxies'
2025-09-28 17:09:30,573 - models.database - INFO - database.py:102 - Database initialized successfully
2025-09-28 17:09:30,574 - services.ai_service - ERROR - ai_service.py:26 - Failed to initialize OpenAI client: AsyncClient.__init__() got an unexpected keyword argument 'proxies'
2025-09-28 17:09:30,620 - models.database - INFO - database.py:102 - Database initialized successfully
2025-09-28 17:09:30,621 - services.ai_service - ERROR - ai_service.py:26 - Failed to initialize OpenAI client: AsyncClient.__init__() got an unexpected keyword argument 'proxies'
2025-09-28 17:09:30,676 - models.database - INFO - database.py:102 - Database initialized successfully
2025-09-28 17:09:30,678 - services.ai_service - ERROR - ai_service.py:26 - Failed to initialize OpenAI client: AsyncClient.__init__() got an unexpected keyword argument 'proxies'
2025-09-28 17:09:30,719 - models.database - INFO - database.py:102 - Database initialized successfully
2025-09-28 17:09:30,720 - services.ai_service - ERROR - ai_service.py:26 - Failed to initialize OpenAI client: AsyncClient.__init__() got an unexpected keyword argument 'proxies'
2025-09-28 17:09:30,763 - models.database - INFO - database.py:102 - Database initialized successfully
2025-09-28 17:09:30,764 - services.ai_service - ERROR - ai_service.py:26 - Failed to initialize OpenAI client: AsyncClient.__init__() got an unexpected keyword argument 'proxies'
2025-09-28 17:09:30,814 - models.database - INFO - database.py:102 - Database initialized successfully
2025-09-28 17:09:30,816 - services.ai_service - ERROR - ai_service.py:26 - Failed to initialize OpenAI client: AsyncClient.__init__() got an unexpected keyword argument 'proxies'
2025-09-28 17:09:30,861 - models.database - INFO - database.py:102 - Database initialized successfully
2025-09-28 17:09:30,862 - services.ai_service - ERROR - ai_service.py:26 - Failed to initialize OpenAI client: AsyncClient.__init__() got an unexpected keyword argument 'proxies'
2025-09-28 17:09:30,911 - models.database - INFO - database.py:102 - Database initialized successfully
2025-09-28 17:09:30,913 - services.ai_service - ERROR - ai_service.py:26 - Failed to initialize OpenAI client: AsyncClient.__init__() got an unexpected keyword argument 'proxies'
2025-09-28 17:09:30,961 - models.database - INFO - database.py:102 - Database initialized successfully
2025-09-28 17:09:30,962 - services.ai_service - ERROR - ai_service.py:26 - Failed to initialize OpenAI client: AsyncClient.__init__() got an unexpected keyword argument 'proxies'
2025-09-28 17:09:31,013 - models.database - INFO - database.py:102 - Database initialized successfully
2025-09-28 17:09:31,015 - services.ai_service - ERROR - ai_service.py:26 - Failed to initialize OpenAI client: AsyncClient.__init__() got an unexpected keyword argument 'proxies'
2025-09-28 17:09:31,061 - models.database - INFO - database.py:102 - Database initialized successfully
2025-09-28 17:09:31,063 - services.ai_service - ERROR - ai_service.py:26 - Failed to initialize OpenAI client: AsyncClient.__init__() got an unexpected keyword argument 'proxies'
2025-09-28 17:09:31,116 - models.database - INFO - database.py:102 - Database initialized successfully
2025-09-28 17:09:31,117 - services.ai_service - ERROR - ai_service.py:26 - Failed to initialize OpenAI client: AsyncClient.__init__() got an unexpected keyword argument 'proxies'
2025-09-28 17:09:31,167 - models.database - INFO - database.py:102 - Database initialized successfully
2025-09-28 17:09:31,168 - services.ai_service - ERROR - ai_service.py:26 - Failed to initialize OpenAI client: AsyncClient.__init__() got an unexpected keyword argument 'proxies'
2025-09-28 17:09:31,268 - models.database - INFO - database.py:102 - Database initialized successfully
2025-09-28 17:09:31,270 - services.ai_service - ERROR - ai_service.py:26 - Failed to initialize OpenAI client: AsyncClient.__init__() got an unexpected keyword argument 'proxies'
2025-09-28 17:09:31,356 - models.database - INFO - database.py:102 - Database initialized successfully
2025-09-28 17:09:31,358 - services.ai_service - ERROR - ai_service.py:26 - Failed to initialize OpenAI client: AsyncClient.__init__() got an unexpected keyword argument 'proxies'
2025-09-28 17:09:31,417 - models.database - INFO - database.py:102 - Database initialized successfully
2025-09-28 17:09:31,418 - services.ai_service - ERROR - ai_service.py:26 - Failed to initialize OpenAI client: AsyncClient.__init__() got an unexpected keyword argument 'proxies'
2025-09-28 17:09:31,465 - models.database - INFO - database.py:102 - Database initialized successfully
2025-09-28 17:09:31,466 - services.ai_service - ERROR - ai_service.py:26 - Failed to initialize OpenAI client: AsyncClient.__init__() got an unexpected keyword argument 'proxies'
2025-09-28 17:09:31,519 - models.database - INFO - database.py:102 - Database initialized successfully
2025-09-28 17:09:31,520 - services.ai_service - ERROR - ai_service.py:26 - Failed to initialize OpenAI client: AsyncClient.__init__() got an unexpected keyword argument 'proxies'
2025-09-28 17:09:31,569 - models.database - INFO - database.py:102 - Database initialized successfully
2025-09-28 17:09:31,570 - services.ai_service - ERROR - ai_service.py:26 - Failed to initialize OpenAI client: AsyncClient.__init__() got an unexpected keyword argument 'proxies'
2025-09-28 17:09:31,622 - models.database - INFO - database.py:102 - Database initialized successfully
2025-09-28 17:09:31,628 - services.ai_service - ERROR - ai_service.py:26 - Failed to initialize OpenAI client: AsyncClient.__init__() got an unexpected keyword argument 'proxies'
2025-09-28 17:09:31,673 - models.database - INFO - database.py:102 - Database initialized successfully
2025-09-28 17:09:31,674 - services.ai_service - ERROR - ai_service.py:26 - Failed to initialize OpenAI client: AsyncClient.__init__() got an unexpected keyword argument 'proxies'
2025-09-28 17:09:31,716 - models.database - INFO - database.py:102 - Database initialized successfully
2025-09-28 17:09:31,718 - services.ai_service - ERROR - ai_service.py:26 - Failed to initialize OpenAI client: AsyncClient.__init__() got an unexpected keyword argument 'proxies'
2025-09-28 17:09:31,761 - models.database - INFO - database.py:102 - Database initialized successfully
2025-09-28 17:09:31,763 - services.ai_service - ERROR - ai_service.py:26 - Failed to initialize OpenAI client: AsyncClient.__init__() got an unexpected keyword argument 'proxies'
2025-09-28 17:09:31,812 - models.database - INFO - database.py:102 - Database initialized successfully
2025-09-28 17:09:31,813 - services.ai_service - ERROR - ai_service.py:26 - Failed to initialize OpenAI client: AsyncClient.__init__() got an unexpected keyword argument 'proxies'
2025-09-28 17:09:31,857 - models.database - INFO - database.py:102 - Database initialized successfully
2025-09-28 17:09:31,860 - services.ai_service - ERROR - ai_service.py:26 - Failed to initialize OpenAI client: AsyncClient.__init__() got an unexpected keyword argument 'proxies'
2025-09-28 17:09:31,909 - models.database - INFO - database.py:102 - Database initialized successfully
2025-09-28 17:09:31,911 - services.ai_service - ERROR - ai_service.py:26 - Failed to initialize OpenAI client: AsyncClient.__init__() got an unexpected keyword argument 'proxies'
2025-09-28 17:09:31,955 - models.database - INFO - database.py:102 - Database initialized successfully
2025-09-28 17:09:31,957 - services.ai_service - ERROR - ai_service.py:26 - Failed to initialize OpenAI client: AsyncClient.__init__() got an unexpected keyword argument 'proxies'
2025-09-28 17:09:32,003 - models.database - INFO - database.py:102 - Database initialized successfully
2025-09-28 17:09:32,004 - services.ai_service - ERROR - ai_service.py:26 - Failed to initialize OpenAI client: AsyncClient.__init__() got an unexpected keyword argument 'proxies'
2025-09-28 17:09:32,048 - models.database - INFO - database.py:102 - Database initialized successfully
2025-09-28 17:09:32,049 - services.ai_service - ERROR - ai_service.py:26 - Failed to initialize OpenAI client: AsyncClient.__init__() got an unexpected keyword argument 'proxies'
2025-09-28 17:09:32,108 - models.database - INFO - database.py:102 - Database initialized successfully
2025-09-28 17:09:32,110 - services.ai_service - ERROR - ai_service.py:26 - Failed to initialize OpenAI client: AsyncClient.__init__() got an unexpected keyword argument 'proxies'
2025-09-28 17:09:32,170 - models.database - INFO - database.py:102 - Database initialized successfully
2025-09-28 17:09:32,171 - services.ai_service - ERROR - ai_service.py:26 - Failed to initialize OpenAI client: AsyncClient.__init__() got an unexpected keyword argument 'proxies'
2025-09-28 17:09:32,217 - models.database - INFO - database.py:102 - Database initialized successfully
2025-09-28 17:09:32,219 - services.ai_service - ERROR - ai_service.py:26 - Failed to initialize OpenAI client: AsyncClient.__init__() got an unexpected keyword argument 'proxies'
2025-09-28 17:09:32,267 - models.database - INFO - database.py:102 - Database initialized successfully
2025-09-28 17:09:32,268 - services.ai_service - ERROR - ai_service.py:26 - Failed to initialize OpenAI client: AsyncClient.__init__() got an unexpected keyword argument 'proxies'
2025-09-28 17:09:32,312 - models.database - INFO - database.py:102 - Database initialized successfully
2025-09-28 17:09:32,313 - services.ai_service - ERROR - ai_service.py:26 - Failed to initialize OpenAI client: AsyncClient.__init__() got an unexpected keyword argument 'proxies'
2025-09-28 17:09:32,355 - models.database - INFO - database.py:102 - Database initialized successfully
2025-09-28 17:09:32,358 - services.ai_service - ERROR - ai_service.py:26 - Failed to initialize OpenAI client: AsyncClient.__init__() got an unexpected keyword argument 'proxies'
2025-09-28 17:09:32,435 - models.database - INFO - database.py:102 - Database initialized successfully
2025-09-28 17:09:32,437 - services.ai_service - ERROR - ai_service.py:26 - Failed to initialize OpenAI client: AsyncClient.__init__() got an unexpected keyword argument 'proxies'
2025-09-28 17:09:32,512 - models.database - INFO - database.py:102 - Database initialized successfully
2025-09-28 17:09:32,514 - services.ai_service - ERROR - ai_service.py:26 - Failed to initialize OpenAI client: AsyncClient.__init__() got an unexpected keyword argument 'proxies'
2025-09-28 17:09:32,599 - models.database - INFO - database.py:102 - Database initialized successfully
2025-09-28 17:09:32,601 - services.ai_service - ERROR - ai_service.py:26 - Failed to initialize OpenAI client: AsyncClient.__init__() got an unexpected keyword argument 'proxies'
2025-09-28 17:09:32,655 - models.database - INFO - database.py:102 - Database initialized successfully
2025-09-28 17:09:32,656 - services.ai_service - ERROR - ai_service.py:26 - Failed to initialize OpenAI client: AsyncClient.__init__() got an unexpected keyword argument 'proxies'
2025-09-28 17:09:32,706 - models.database - INFO - database.py:102 - Database initialized successfully
2025-09-28 17:09:32,708 - services.ai_service - ERROR - ai_service.py:26 - Failed to initialize OpenAI client: AsyncClient.__init__() got an unexpected keyword argument 'proxies'
2025-09-28 17:09:32,751 - models.database - INFO - database.py:102 - Database initialized successfully
2025-09-28 17:09:32,752 - services.ai_service - ERROR - ai_service.py:26 - Failed to initialize OpenAI client: AsyncClient.__init__() got an unexpected keyword argument 'proxies'
2025-09-28 17:09:32,810 - models.database - INFO - database.py:102 - Database initialized successfully
2025-09-28 17:09:32,812 - services.ai_service - ERROR - ai_service.py:26 - Failed to initialize OpenAI client: AsyncClient.__init__() got an unexpected keyword argument 'proxies'
2025-09-28 17:09:32,904 - models.database - INFO - database.py:102 - Database initialized successfully
2025-09-28 17:09:32,905 - services.ai_service - ERROR - ai_service.py:26 - Failed to initialize OpenAI client: AsyncClient.__init__() got an unexpected keyword argument 'proxies'
2025-09-28 17:09:32,985 - models.database - INFO - database.py:102 - Database initialized successfully
2025-09-28 17:09:32,986 - services.ai_service - ERROR - ai_service.py:26 - Failed to initialize OpenAI client: AsyncClient.__init__() got an unexpected keyword argument 'proxies'
2025-09-28 17:09:33,041 - models.database - INFO - database.py:102 - Database initialized successfully
2025-09-28 17:09:33,043 - services.ai_service - ERROR - ai_service.py:26 - Failed to initialize OpenAI client: AsyncClient.__init__() got an unexpected keyword argument 'proxies'
2025-09-28 17:09:33,128 - models.database - INFO - database.py:102 - Database initialized successfully
2025-09-28 17:09:33,129 - services.ai_service - ERROR - ai_service.py:26 - Failed to initialize OpenAI client: AsyncClient.__init__() got an unexpected keyword argument 'proxies'
2025-09-28 17:09:33,188 - models.database - INFO - database.py:102 - Database initialized successfully
2025-09-28 17:09:33,189 - services.ai_service - ERROR - ai_service.py:26 - Failed to initialize OpenAI client: AsyncClient.__init__() got an unexpected keyword argument 'proxies'
2025-09-28 17:09:33,246 - models.database - INFO - database.py:102 - Database initialized successfully
2025-09-28 17:09:33,247 - services.ai_service - ERROR - ai_service.py:26 - Failed to initialize OpenAI client: AsyncClient.__init__() got an unexpected keyword argument 'proxies'
2025-09-28 17:09:33,300 - models.database - INFO - database.py:102 - Database initialized successfully
2025-09-28 17:09:33,301 - services.ai_service - ERROR - ai_service.py:26 - Failed to initialize OpenAI client: AsyncClient.__init__() got an unexpected keyword argument 'proxies'
2025-09-28 17:09:33,353 - models.database - INFO - database.py:102 - Database initialized successfully
2025-09-28 17:09:33,354 - services.ai_service - ERROR - ai_service.py:26 - Failed to initialize OpenAI client: AsyncClient.__init__() got an unexpected keyword argument 'proxies'
2025-09-28 17:09:33,402 - models.database - INFO - database.py:102 - Database initialized successfully
2025-09-28 17:09:33,403 - services.ai_service - ERROR - ai_service.py:26 - Failed to initialize OpenAI client: AsyncClient.__init__() got an unexpected keyword argument 'proxies'
2025-09-28 17:09:33,458 - models.database - INFO - database.py:102 - Database initialized successfully
2025-09-28 17:09:33,460 - services.ai_service - ERROR - ai_service.py:26 - Failed to initialize OpenAI client: AsyncClient.__init__() got an unexpected keyword argument 'proxies'
2025-09-28 17:09:33,546 - models.database - INFO - database.py:102 - Database initialized successfully
2025-09-28 17:09:33,548 - services.ai_service - ERROR - ai_service.py:26 - Failed to initialize OpenAI client: AsyncClient.__init__() got an unexpected keyword argument 'proxies'
2025-09-28 17:09:33,600 - models.database - INFO - database.py:102 - Database initialized successfully
2025-09-28 17:09:33,601 - services.ai_service - ERROR - ai_service.py:26 - Failed to initialize OpenAI client: AsyncClient.__init__() got an unexpected keyword argument 'proxies'
2025-09-28 17:09:33,654 - models.database - INFO - database.py:102 - Database initialized successfully
2025-09-28 17:09:33,656 - services.ai_service - ERROR - ai_service.py:26 - Failed to initialize OpenAI client: AsyncClient.__init__() got an unexpected keyword argument 'proxies'
2025-09-28 17:09:33,717 - models.database - INFO - database.py:102 - Database initialized successfully
2025-09-28 17:09:33,719 - services.ai_service - ERROR - ai_service.py:26 - Failed to initialize OpenAI client: AsyncClient.__init__() got an unexpected keyword argument 'proxies'
2025-09-28 17:09:33,770 - models.database - INFO - database.py:102 - Database initialized successfully
2025-09-28 17:09:33,771 - services.ai_service - ERROR - ai_service.py:26 - Failed to initialize OpenAI client: AsyncClient.__init__() got an unexpected keyword argument 'proxies'
2025-09-28 17:09:33,836 - models.database - INFO - database.py:102 - Database initialized successfully
2025-09-28 17:09:33,837 - services.ai_service - ERROR - ai_service.py:26 - Failed to initialize OpenAI client: AsyncClient.__init__() got an unexpected keyword argument 'proxies'
2025-09-28 17:09:33,891 - models.database - INFO - database.py:102 - Database initialized successfully
2025-09-28 17:09:33,892 - services.ai_service - ERROR - ai_service.py:26 - Failed to initialize OpenAI client: AsyncClient.__init__() got an unexpected keyword argument 'proxies'
2025-09-28 17:09:33,944 - models.database - INFO - database.py:102 - Database initialized successfully
2025-09-28 17:09:33,945 - services.ai_service - ERROR - ai_service.py:26 - Failed to initialize OpenAI client: AsyncClient.__init__() got an unexpected keyword argument 'proxies'
2025-09-28 17:09:34,000 - models.database - INFO - database.py:102 - Database initialized successfully
2025-09-28 17:09:34,002 - services.ai_service - ERROR - ai_service.py:26 - Failed to initialize OpenAI client: AsyncClient.__init__() got an unexpected keyword argument 'proxies'
2025-09-28 17:09:34,064 - models.database - INFO - database.py:102 - Database initialized successfully
2025-09-28 17:09:34,066 - services.ai_service - ERROR - ai_service.py:26 - Failed to initialize OpenAI client: AsyncClient.__init__() got an unexpected keyword argument 'proxies'
2025-09-28 17:09:34,126 - models.database - INFO - database.py:102 - Database initialized successfully
2025-09-28 17:09:34,128 - services.ai_service - ERROR - ai_service.py:26 - Failed to initialize OpenAI client: AsyncClient.__init__() got an unexpected keyword argument 'proxies'
2025-09-28 17:09:34,184 - models.database - INFO - database.py:102 - Database initialized successfully
2025-09-28 17:09:34,185 - services.ai_service - ERROR - ai_service.py:26 - Failed to initialize OpenAI client: AsyncClient.__init__() got an unexpected keyword argument 'proxies'
2025-09-28 17:09:34,241 - models.database - INFO - database.py:102 - Database initialized successfully
2025-09-28 17:09:34,242 - services.ai_service - ERROR - ai_service.py:26 - Failed to initialize OpenAI client: AsyncClient.__init__() got an unexpected keyword argument 'proxies'
2025-09-28 17:09:34,295 - models.database - INFO - database.py:102 - Database initialized successfully
2025-09-28 17:09:34,297 - services.ai_service - ERROR - ai_service.py:26 - Failed to initialize OpenAI client: AsyncClient.__init__() got an unexpected keyword argument 'proxies'
2025-09-28 17:09:34,351 - models.database - INFO - database.py:102 - Database initialized successfully
2025-09-28 17:09:34,352 - services.ai_service - ERROR - ai_service.py:26 - Failed to initialize OpenAI client: AsyncClient.__init__() got an unexpected keyword argument 'proxies'
2025-09-28 17:09:34,397 - models.database - INFO - database.py:102 - Database initialized successfully
2025-09-28 17:09:34,398 - services.ai_service - ERROR - ai_service.py:26 - Failed to initialize OpenAI client: AsyncClient.__init__() got an unexpected keyword argument 'proxies'
2025-09-28 17:09:34,451 - models.database - INFO - database.py:102 - Database initialized successfully
2025-09-28 17:09:34,452 - services.ai_service - ERROR - ai_service.py:26 - Failed to initialize OpenAI client: AsyncClient.__init__() got an unexpected keyword argument 'proxies'
2025-09-28 17:09:34,527 - models.database - INFO - database.py:102 - Database initialized successfully
2025-09-28 17:09:34,529 - services.ai_service - ERROR - ai_service.py:26 - Failed to initialize OpenAI client: AsyncClient.__init__() got an unexpected keyword argument 'proxies'
2025-09-28 17:09:34,579 - models.database - INFO - database.py:102 - Database initialized successfully
2025-09-28 17:09:34,581 - services.ai_service - ERROR - ai_service.py:26 - Failed to initialize OpenAI client: AsyncClient.__init__() got an unexpected keyword argument 'proxies'
2025-09-28 17:09:34,674 - models.database - INFO - database.py:102 - Database initialized successfully
2025-09-28 17:09:34,675 - services.ai_service - ERROR - ai_service.py:26 - Failed to initialize OpenAI client: AsyncClient.__init__() got an unexpected keyword argument 'proxies'
2025-09-28 17:09:34,747 - models.database - INFO - database.py:102 - Database initialized successfully
2025-09-28 17:09:34,748 - services.ai_service - ERROR - ai_service.py:26 - Failed to initialize OpenAI client: AsyncClient.__init__() got an unexpected keyword argument 'proxies'
2025-09-28 17:09:34,804 - models.database - INFO - database.py:102 - Database initialized successfully
2025-09-28 17:09:34,805 - services.ai_service - ERROR - ai_service.py:26 - Failed to initialize OpenAI client: AsyncClient.__init__() got an unexpected keyword argument 'proxies'
2025-09-28 17:09:34,856 - models.database - INFO - database.py:102 - Database initialized successfully
2025-09-28 17:09:34,857 - services.ai_service - ERROR - ai_service.py:26 - Failed to initialize OpenAI client: AsyncClient.__init__() got an unexpected keyword argument 'proxies'
2025-09-28 17:09:34,910 - models.database - INFO - database.py:102 - Database initialized successfully
2025-09-28 17:09:34,914 - services.ai_service - ERROR - ai_service.py:26 - Failed to initialize OpenAI client: AsyncClient.__init__() got an unexpected keyword argument 'proxies'
2025-09-28 17:09:34,964 - models.database - INFO - database.py:102 - Database initialized successfully
2025-09-28 17:09:34,965 - services.ai_service - ERROR - ai_service.py:26 - Failed to initialize OpenAI client: AsyncClient.__init__() got an unexpected keyword argument 'proxies'
2025-09-28 17:09:35,022 - models.database - INFO - database.py:102 - Database initialized successfully
2025-09-28 17:09:35,024 - services.ai_service - ERROR - ai_service.py:26 - Failed to initialize OpenAI client: AsyncClient.__init__() got an unexpected keyword argument 'proxies'
2025-09-28 17:09:35,068 - models.database - INFO - database.py:102 - Database initialized successfully
2025-09-28 17:09:35,069 - services.ai_service - ERROR - ai_service.py:26 - Failed to initialize OpenAI client: AsyncClient.__init__() got an unexpected keyword argument 'proxies'
2025-09-28 17:09:35,119 - models.database - INFO - database.py:102 - Database initialized successfully
2025-09-28 17:09:35,120 - services.ai_service - ERROR - ai_service.py:26 - Failed to initialize OpenAI client: AsyncClient.__init__() got an unexpected keyword argument 'proxies'
2025-09-28 17:09:35,185 - models.database - INFO - database.py:102 - Database initialized successfully
2025-09-28 17:09:35,187 - services.ai_service - ERROR - ai_service.py:26 - Failed to initialize OpenAI client: AsyncClient.__init__() got an unexpected keyword argument 'proxies'
2025-09-28 17:09:35,302 - models.database - INFO - database.py:102 - Database initialized successfully
2025-09-28 17:09:35,364 - services.ai_service - ERROR - ai_service.py:26 - Failed to initialize OpenAI client: AsyncClient.__init__() got an unexpected keyword argument 'proxies'
2025-09-28 17:09:35,455 - models.database - INFO - database.py:102 - Database initialized successfully
2025-09-28 17:09:35,456 - services.ai_service - ERROR - ai_service.py:26 - Failed to initialize OpenAI client: AsyncClient.__init__() got an unexpected keyword argument 'proxies'
2025-09-28 17:09:35,502 - models.database - INFO - database.py:102 - Database initialized successfully
2025-09-28 17:09:35,503 - services.ai_service - ERROR - ai_service.py:26 - Failed to initialize OpenAI client: AsyncClient.__init__() got an unexpected keyword argument 'proxies'
2025-09-28 17:09:35,557 - models.database - INFO - database.py:102 - Database initialized successfully
2025-09-28 17:09:35,558 - services.ai_service - ERROR - ai_service.py:26 - Failed to initialize OpenAI client: AsyncClient.__init__() got an unexpected keyword argument 'proxies'
2025-09-28 17:09:35,611 - models.database - INFO - database.py:102 - Database initialized successfully
2025-09-28 17:09:35,614 - services.ai_service - ERROR - ai_service.py:26 - Failed to initialize OpenAI client: AsyncClient.__init__() got an unexpected keyword argument 'proxies'
2025-09-28 17:09:35,689 - models.database - INFO - database.py:102 - Database initialized successfully
2025-09-28 17:09:35,690 - services.ai_service - ERROR - ai_service.py:26 - Failed to initialize OpenAI client: AsyncClient.__init__() got an unexpected keyword argument 'proxies'
2025-09-28 17:09:35,738 - models.database - INFO - database.py:102 - Database initialized successfully
2025-09-28 17:09:35,739 - services.ai_service - ERROR - ai_service.py:26 - Failed to initialize OpenAI client: AsyncClient.__init__() got an unexpected keyword argument 'proxies'
2025-09-28 17:09:35,788 - __main__ - ERROR - app.py:817 - Application startup failed: maximum recursion depth exceeded
2025-09-28 17:11:02,334 - root - INFO - logger.py:49 - Social Media Automation System logging initialized
2025-09-28 17:11:02,336 - __main__ - WARNING - run.py:47 - Configuration warnings:
2025-09-28 17:11:02,337 - __main__ - WARNING - run.py:49 -   - Missing API keys for: YouTube
2025-09-28 17:11:02,337 - __main__ - WARNING - run.py:49 -   - Please change the default JWT_SECRET_KEY in production
2025-09-28 17:11:02,343 - models.database - INFO - database.py:102 - Database initialized successfully
2025-09-28 17:11:02,344 - services.ai_service - ERROR - ai_service.py:26 - Failed to initialize OpenAI client: AsyncClient.__init__() got an unexpected keyword argument 'proxies'
2025-09-28 17:11:02,394 - app - INFO - app.py:59 - Social Media Automation System initialized successfully
2025-09-28 17:11:02,394 - __main__ - INFO - run.py:59 - Starting Social Media Automation System
2025-09-28 17:11:02,395 - __main__ - INFO - run.py:60 - Host: 0.0.0.0, Port: 5000, Debug: True
2025-09-28 17:11:02,395 - __main__ - INFO - run.py:61 - Upload folder: uploads
2025-09-28 17:11:02,396 - __main__ - INFO - run.py:65 - Enabled platforms: instagram, tiktok, kawai
2025-09-28 17:11:02,400 - models.database - INFO - database.py:102 - Database initialized successfully
2025-09-28 17:11:02,400 - services.scheduler - INFO - scheduler.py:13 - PostScheduler iniciado
2025-09-28 17:11:02,401 - app - INFO - app.py:763 - Application context initialized successfully
2025-09-28 17:11:02,402 - app - INFO - app.py:775 - Starting Social Media Automation System on 0.0.0.0:5000
2025-09-28 17:11:02,403 - app - INFO - app.py:776 - Debug mode: True
2025-09-28 17:11:02,405 - app - INFO - app.py:777 - Upload folder: uploads
2025-09-28 17:11:02,500 - werkzeug - INFO - _internal.py:187 - [31m[1mWARNING: This is a development server. Do not use it in a production deployment. Use a production WSGI server instead.[0m
 * Running on all addresses (0.0.0.0)
 * Running on http://127.0.0.1:5000
 * Running on http://192.168.0.7:5000
2025-09-28 17:11:02,501 - werkzeug - INFO - _internal.py:187 - [33mPress CTRL+C to quit[0m
2025-09-28 17:11:02,507 - werkzeug - INFO - _internal.py:187 -  * Restarting with stat
2025-09-28 17:11:07,092 - root - INFO - logger.py:49 - Social Media Automation System logging initialized
2025-09-28 17:11:07,096 - __main__ - WARNING - run.py:47 - Configuration warnings:
2025-09-28 17:11:07,097 - __main__ - WARNING - run.py:49 -   - Missing API keys for: YouTube
2025-09-28 17:11:07,098 - __main__ - WARNING - run.py:49 -   - Please change the default JWT_SECRET_KEY in production
2025-09-28 17:11:07,104 - models.database - INFO - database.py:102 - Database initialized successfully
2025-09-28 17:11:07,106 - services.ai_service - ERROR - ai_service.py:26 - Failed to initialize OpenAI client: AsyncClient.__init__() got an unexpected keyword argument 'proxies'
2025-09-28 17:11:07,219 - app - INFO - app.py:59 - Social Media Automation System initialized successfully
2025-09-28 17:11:07,221 - __main__ - INFO - run.py:59 - Starting Social Media Automation System
2025-09-28 17:11:07,223 - __main__ - INFO - run.py:60 - Host: 0.0.0.0, Port: 5000, Debug: True
2025-09-28 17:11:07,226 - __main__ - INFO - run.py:61 - Upload folder: uploads
2025-09-28 17:11:07,230 - __main__ - INFO - run.py:65 - Enabled platforms: instagram, tiktok, kawai
2025-09-28 17:11:07,254 - models.database - INFO - database.py:102 - Database initialized successfully
2025-09-28 17:11:07,256 - services.scheduler - INFO - scheduler.py:13 - PostScheduler iniciado
2025-09-28 17:11:07,257 - app - INFO - app.py:763 - Application context initialized successfully
2025-09-28 17:11:07,258 - app - INFO - app.py:775 - Starting Social Media Automation System on 0.0.0.0:5000
2025-09-28 17:11:07,263 - app - INFO - app.py:776 - Debug mode: True
2025-09-28 17:11:07,263 - app - INFO - app.py:777 - Upload folder: uploads
2025-09-28 17:11:07,305 - werkzeug - WARNING - _internal.py:187 -  * Debugger is active!
2025-09-28 17:11:07,314 - werkzeug - INFO - _internal.py:187 -  * Debugger PIN: 876-337-494
2025-09-28 17:11:13,942 - werkzeug - INFO - _internal.py:187 - 127.0.0.1 - - [28/Sep/2025 17:11:13] "GET / HTTP/1.1" 200 -
2025-09-28 17:11:14,158 - werkzeug - INFO - _internal.py:187 - 127.0.0.1 - - [28/Sep/2025 17:11:14] "GET /static/css/style.css HTTP/1.1" 200 -
2025-09-28 17:11:14,261 - werkzeug - INFO - _internal.py:187 - 127.0.0.1 - - [28/Sep/2025 17:11:14] "GET /static/js/app.js HTTP/1.1" 200 -
2025-09-28 17:11:14,474 - werkzeug - INFO - _internal.py:187 - 127.0.0.1 - - [28/Sep/2025 17:11:14] "GET /api/accounts/status HTTP/1.1" 200 -
2025-09-28 17:11:45,329 - werkzeug - INFO - _internal.py:187 - 127.0.0.1 - - [28/Sep/2025 17:11:45] "GET /api/accounts/status HTTP/1.1" 200 -
2025-09-28 17:11:50,408 - werkzeug - INFO - _internal.py:187 - 127.0.0.1 - - [28/Sep/2025 17:11:50] "GET /oauth/youtube/start HTTP/1.1" 200 -
2025-09-28 17:11:51,644 - werkzeug - INFO - _internal.py:187 - 127.0.0.1 - - [28/Sep/2025 17:11:51] "GET /api/accounts/status HTTP/1.1" 200 -
2025-09-28 17:12:14,219 - werkzeug - INFO - _internal.py:187 - 127.0.0.1 - - [28/Sep/2025 17:12:14] "GET /api/schedule HTTP/1.1" 200 -
2025-09-28 17:12:24,313 - werkzeug - INFO - _internal.py:187 - 127.0.0.1 - - [28/Sep/2025 17:12:24] "GET /api/analytics?range=30d HTTP/1.1" 200 -
2025-09-28 17:16:27,464 - werkzeug - INFO - _internal.py:187 - 127.0.0.1 - - [28/Sep/2025 17:16:27] "GET / HTTP/1.1" 200 -
2025-09-28 17:16:27,535 - werkzeug - INFO - _internal.py:187 - 127.0.0.1 - - [28/Sep/2025 17:16:27] "[36mGET /static/css/style.css HTTP/1.1[0m" 304 -
2025-09-28 17:16:27,545 - werkzeug - INFO - _internal.py:187 - 127.0.0.1 - - [28/Sep/2025 17:16:27] "[36mGET /static/js/app.js HTTP/1.1[0m" 304 -
2025-09-28 17:16:27,950 - werkzeug - INFO - _internal.py:187 - 127.0.0.1 - - [28/Sep/2025 17:16:27] "GET /api/accounts/status HTTP/1.1" 200 -
2025-09-28 17:16:52,163 - werkzeug - INFO - _internal.py:187 - 127.0.0.1 - - [28/Sep/2025 17:16:52] "GET / HTTP/1.1" 200 -
2025-09-28 17:16:52,205 - werkzeug - INFO - _internal.py:187 - 127.0.0.1 - - [28/Sep/2025 17:16:52] "[36mGET /static/css/style.css HTTP/1.1[0m" 304 -
2025-09-28 17:16:52,223 - werkzeug - INFO - _internal.py:187 - 127.0.0.1 - - [28/Sep/2025 17:16:52] "[36mGET /static/js/app.js HTTP/1.1[0m" 304 -
2025-09-28 17:16:52,325 - werkzeug - INFO - _internal.py:187 - 127.0.0.1 - - [28/Sep/2025 17:16:52] "GET /api/accounts/status HTTP/1.1" 200 -
2025-09-29 09:18:32,254 - werkzeug - INFO - _internal.py:187 - 127.0.0.1 - - [29/Sep/2025 09:18:32] "[33mGET /consultoria/ HTTP/1.1[0m" 404 -
2025-09-29 09:18:32,391 - werkzeug - INFO - _internal.py:187 - 127.0.0.1 - - [29/Sep/2025 09:18:32] "[33mGET /favicon.ico HTTP/1.1[0m" 404 -
2025-09-29 09:18:35,409 - werkzeug - INFO - _internal.py:187 - 127.0.0.1 - - [29/Sep/2025 09:18:35] "GET / HTTP/1.1" 200 -
2025-09-29 09:18:36,657 - werkzeug - INFO - _internal.py:187 - 127.0.0.1 - - [29/Sep/2025 09:18:36] "GET /static/css/style.css HTTP/1.1" 200 -
2025-09-29 09:18:36,668 - werkzeug - INFO - _internal.py:187 - 127.0.0.1 - - [29/Sep/2025 09:18:36] "GET /static/js/app.js HTTP/1.1" 200 -
2025-09-29 09:18:36,721 - werkzeug - INFO - _internal.py:187 - 127.0.0.1 - - [29/Sep/2025 09:18:36] "GET /api/accounts/status HTTP/1.1" 200 -
2025-10-01 11:51:24,917 - root - INFO - logger.py:49 - Social Media Automation System logging initialized
2025-10-01 11:51:24,920 - __main__ - WARNING - run.py:47 - Configuration warnings:
2025-10-01 11:51:24,920 - __main__ - WARNING - run.py:49 -   - Missing API keys for: YouTube
2025-10-01 11:51:24,921 - __main__ - WARNING - run.py:49 -   - Please change the default JWT_SECRET_KEY in production
2025-10-01 11:51:24,950 - models.database - INFO - database.py:102 - Database initialized successfully
2025-10-01 11:51:24,956 - services.ai_service - ERROR - ai_service.py:26 - Failed to initialize OpenAI client: AsyncClient.__init__() got an unexpected keyword argument 'proxies'
2025-10-01 11:51:24,993 - app - INFO - app.py:59 - Social Media Automation System initialized successfully
2025-10-01 11:51:24,993 - __main__ - INFO - run.py:59 - Starting Social Media Automation System
2025-10-01 11:51:24,993 - __main__ - INFO - run.py:60 - Host: 0.0.0.0, Port: 5000, Debug: True
2025-10-01 11:51:24,994 - __main__ - INFO - run.py:61 - Upload folder: uploads
2025-10-01 11:51:24,997 - __main__ - INFO - run.py:65 - Enabled platforms: instagram, tiktok, kawai
2025-10-01 11:51:25,001 - models.database - INFO - database.py:102 - Database initialized successfully
2025-10-01 11:51:25,003 - services.scheduler - INFO - scheduler.py:13 - PostScheduler iniciado
2025-10-01 11:51:25,004 - app - INFO - app.py:763 - Application context initialized successfully
2025-10-01 11:51:25,014 - app - INFO - app.py:775 - Starting Social Media Automation System on 0.0.0.0:5000
2025-10-01 11:51:25,016 - app - INFO - app.py:776 - Debug mode: True
2025-10-01 11:51:25,017 - app - INFO - app.py:777 - Upload folder: uploads
2025-10-01 11:51:25,096 - werkzeug - INFO - _internal.py:187 - [31m[1mWARNING: This is a development server. Do not use it in a production deployment. Use a production WSGI server instead.[0m
 * Running on all addresses (0.0.0.0)
 * Running on http://127.0.0.1:5000
 * Running on http://192.168.0.7:5000
2025-10-01 11:51:25,097 - werkzeug - INFO - _internal.py:187 - [33mPress CTRL+C to quit[0m
2025-10-01 11:51:25,103 - werkzeug - INFO - _internal.py:187 -  * Restarting with stat
2025-10-01 11:51:27,074 - root - INFO - logger.py:49 - Social Media Automation System logging initialized
2025-10-01 11:51:27,075 - __main__ - WARNING - run.py:47 - Configuration warnings:
2025-10-01 11:51:27,075 - __main__ - WARNING - run.py:49 -   - Missing API keys for: YouTube
2025-10-01 11:51:27,076 - __main__ - WARNING - run.py:49 -   - Please change the default JWT_SECRET_KEY in production
2025-10-01 11:51:27,079 - models.database - INFO - database.py:102 - Database initialized successfully
2025-10-01 11:51:27,080 - services.ai_service - ERROR - ai_service.py:26 - Failed to initialize OpenAI client: AsyncClient.__init__() got an unexpected keyword argument 'proxies'
2025-10-01 11:51:27,103 - app - INFO - app.py:59 - Social Media Automation System initialized successfully
2025-10-01 11:51:27,103 - __main__ - INFO - run.py:59 - Starting Social Media Automation System
2025-10-01 11:51:27,103 - __main__ - INFO - run.py:60 - Host: 0.0.0.0, Port: 5000, Debug: True
2025-10-01 11:51:27,104 - __main__ - INFO - run.py:61 - Upload folder: uploads
2025-10-01 11:51:27,105 - __main__ - INFO - run.py:65 - Enabled platforms: instagram, tiktok, kawai
2025-10-01 11:51:27,106 - models.database - INFO - database.py:102 - Database initialized successfully
2025-10-01 11:51:27,107 - services.scheduler - INFO - scheduler.py:13 - PostScheduler iniciado
2025-10-01 11:51:27,107 - app - INFO - app.py:763 - Application context initialized successfully
2025-10-01 11:51:27,107 - app - INFO - app.py:775 - Starting Social Media Automation System on 0.0.0.0:5000
2025-10-01 11:51:27,108 - app - INFO - app.py:776 - Debug mode: True
2025-10-01 11:51:27,108 - app - INFO - app.py:777 - Upload folder: uploads
2025-10-01 11:51:27,123 - werkzeug - WARNING - _internal.py:187 -  * Debugger is active!
2025-10-01 11:51:27,129 - werkzeug - INFO - _internal.py:187 -  * Debugger PIN: 876-337-494
2025-10-01 11:53:39,143 - services.scheduler - INFO - scheduler.py:18 - PostScheduler parado
2025-10-01 11:53:39,144 - app - INFO - app.py:790 - Application shutdown complete
2025-10-01 11:53:39,368 - services.scheduler - INFO - scheduler.py:18 - PostScheduler parado
2025-10-01 11:53:39,368 - app - INFO - app.py:790 - Application shutdown complete
2025-10-01 11:53:54,328 - root - INFO - logger.py:49 - Social Media Automation System logging initialized
2025-10-01 11:53:54,329 - __main__ - WARNING - run.py:47 - Configuration warnings:
2025-10-01 11:53:54,329 - __main__ - WARNING - run.py:49 -   - Missing API keys for: YouTube
2025-10-01 11:53:54,329 - __main__ - WARNING - run.py:49 -   - Please change the default JWT_SECRET_KEY in production
2025-10-01 11:53:54,333 - models.database - INFO - database.py:102 - Database initialized successfully
2025-10-01 11:53:54,334 - services.ai_service - ERROR - ai_service.py:26 - Failed to initialize OpenAI client: AsyncClient.__init__() got an unexpected keyword argument 'proxies'
2025-10-01 11:53:54,355 - app - INFO - app.py:59 - Social Media Automation System initialized successfully
2025-10-01 11:53:54,356 - __main__ - INFO - run.py:59 - Starting Social Media Automation System
2025-10-01 11:53:54,356 - __main__ - INFO - run.py:60 - Host: 0.0.0.0, Port: 5000, Debug: True
2025-10-01 11:53:54,356 - __main__ - INFO - run.py:61 - Upload folder: uploads
2025-10-01 11:53:54,357 - __main__ - INFO - run.py:65 - Enabled platforms: instagram, tiktok, kawai
2025-10-01 11:53:54,360 - models.database - INFO - database.py:102 - Database initialized successfully
2025-10-01 11:53:54,361 - services.scheduler - INFO - scheduler.py:13 - PostScheduler iniciado
2025-10-01 11:53:54,361 - app - INFO - app.py:763 - Application context initialized successfully
2025-10-01 11:53:54,362 - app - INFO - app.py:775 - Starting Social Media Automation System on 0.0.0.0:5000
2025-10-01 11:53:54,363 - app - INFO - app.py:776 - Debug mode: True
2025-10-01 11:53:54,364 - app - INFO - app.py:777 - Upload folder: uploads
2025-10-01 11:53:54,405 - werkzeug - INFO - _internal.py:187 - [31m[1mWARNING: This is a development server. Do not use it in a production deployment. Use a production WSGI server instead.[0m
 * Running on all addresses (0.0.0.0)
 * Running on http://127.0.0.1:5000
 * Running on http://192.168.0.7:5000
2025-10-01 11:53:54,406 - werkzeug - INFO - _internal.py:187 - [33mPress CTRL+C to quit[0m
2025-10-01 11:53:54,408 - werkzeug - INFO - _internal.py:187 -  * Restarting with stat
2025-10-01 11:53:57,517 - root - INFO - logger.py:49 - Social Media Automation System logging initialized
2025-10-01 11:53:57,518 - __main__ - WARNING - run.py:47 - Configuration warnings:
2025-10-01 11:53:57,519 - __main__ - WARNING - run.py:49 -   - Missing API keys for: YouTube
2025-10-01 11:53:57,519 - __main__ - WARNING - run.py:49 -   - Please change the default JWT_SECRET_KEY in production
2025-10-01 11:53:57,524 - models.database - INFO - database.py:102 - Database initialized successfully
2025-10-01 11:53:57,525 - services.ai_service - ERROR - ai_service.py:26 - Failed to initialize OpenAI client: AsyncClient.__init__() got an unexpected keyword argument 'proxies'
2025-10-01 11:53:57,553 - app - INFO - app.py:59 - Social Media Automation System initialized successfully
2025-10-01 11:53:57,553 - __main__ - INFO - run.py:59 - Starting Social Media Automation System
2025-10-01 11:53:57,554 - __main__ - INFO - run.py:60 - Host: 0.0.0.0, Port: 5000, Debug: True
2025-10-01 11:53:57,555 - __main__ - INFO - run.py:61 - Upload folder: uploads
2025-10-01 11:53:57,556 - __main__ - INFO - run.py:65 - Enabled platforms: instagram, tiktok, kawai
2025-10-01 11:53:57,558 - models.database - INFO - database.py:102 - Database initialized successfully
2025-10-01 11:53:57,559 - services.scheduler - INFO - scheduler.py:13 - PostScheduler iniciado
2025-10-01 11:53:57,560 - app - INFO - app.py:763 - Application context initialized successfully
2025-10-01 11:53:57,561 - app - INFO - app.py:775 - Starting Social Media Automation System on 0.0.0.0:5000
2025-10-01 11:53:57,561 - app - INFO - app.py:776 - Debug mode: True
2025-10-01 11:53:57,562 - app - INFO - app.py:777 - Upload folder: uploads
2025-10-01 11:53:57,589 - werkzeug - WARNING - _internal.py:187 -  * Debugger is active!
2025-10-01 11:53:57,594 - werkzeug - INFO - _internal.py:187 -  * Debugger PIN: 876-337-494
2025-10-01 11:54:01,292 - werkzeug - INFO - _internal.py:187 - 127.0.0.1 - - [01/Oct/2025 11:54:01] "GET / HTTP/1.1" 200 -
2025-10-01 11:54:01,501 - werkzeug - INFO - _internal.py:187 - 127.0.0.1 - - [01/Oct/2025 11:54:01] "GET /static/css/style.css HTTP/1.1" 200 -
2025-10-01 11:54:01,534 - werkzeug - INFO - _internal.py:187 - 127.0.0.1 - - [01/Oct/2025 11:54:01] "GET /static/js/app.js HTTP/1.1" 200 -
2025-10-01 11:54:01,731 - werkzeug - INFO - _internal.py:187 - 127.0.0.1 - - [01/Oct/2025 11:54:01] "GET /api/accounts/status HTTP/1.1" 200 -
2025-10-01 11:54:01,744 - werkzeug - INFO - _internal.py:187 - 127.0.0.1 - - [01/Oct/2025 11:54:01] "[33mGET /favicon.ico HTTP/1.1[0m" 404 -
2025-10-01 12:08:06,996 - werkzeug - INFO - _internal.py:187 - 127.0.0.1 - - [01/Oct/2025 12:08:06] "GET /api/accounts/status HTTP/1.1" 200 -
2025-10-01 12:08:09,002 - werkzeug - INFO - _internal.py:187 - 127.0.0.1 - - [01/Oct/2025 12:08:09] "GET /oauth/youtube/start HTTP/1.1" 200 -
2025-10-01 12:08:12,127 - werkzeug - INFO - _internal.py:187 - 127.0.0.1 - - [01/Oct/2025 12:08:12] "GET /api/accounts/status HTTP/1.1" 200 -
2025-10-01 12:09:15,157 - werkzeug - INFO - _internal.py:187 - 127.0.0.1 - - [01/Oct/2025 12:09:15] "GET /oauth/youtube/start HTTP/1.1" 200 -
2025-10-01 12:09:16,288 - werkzeug - INFO - _internal.py:187 - 127.0.0.1 - - [01/Oct/2025 12:09:16] "GET /api/accounts/status HTTP/1.1" 200 -
2025-10-01 12:12:35,616 - services.scheduler - INFO - scheduler.py:18 - PostScheduler parado
2025-10-01 12:12:35,618 - app - INFO - app.py:790 - Application shutdown complete
2025-10-01 12:12:35,944 - services.scheduler - INFO - scheduler.py:18 - PostScheduler parado
2025-10-01 12:12:35,944 - app - INFO - app.py:790 - Application shutdown complete
2025-10-01 12:12:44,592 - root - INFO - logger.py:49 - Social Media Automation System logging initialized
2025-10-01 12:12:44,593 - __main__ - WARNING - run.py:47 - Configuration warnings:
2025-10-01 12:12:44,593 - __main__ - WARNING - run.py:49 -   - Missing API keys for: YouTube
2025-10-01 12:12:44,593 - __main__ - WARNING - run.py:49 -   - Please change the default JWT_SECRET_KEY in production
2025-10-01 12:12:44,596 - models.database - INFO - database.py:102 - Database initialized successfully
2025-10-01 12:12:44,597 - services.ai_service - ERROR - ai_service.py:26 - Failed to initialize OpenAI client: AsyncClient.__init__() got an unexpected keyword argument 'proxies'
2025-10-01 12:12:44,611 - app - INFO - app.py:59 - Social Media Automation System initialized successfully
2025-10-01 12:12:44,611 - __main__ - INFO - run.py:59 - Starting Social Media Automation System
2025-10-01 12:12:44,611 - __main__ - INFO - run.py:60 - Host: 0.0.0.0, Port: 5000, Debug: True
2025-10-01 12:12:44,612 - __main__ - INFO - run.py:61 - Upload folder: uploads
2025-10-01 12:12:44,612 - __main__ - INFO - run.py:65 - Enabled platforms: instagram, tiktok, kawai
2025-10-01 12:12:44,614 - models.database - INFO - database.py:102 - Database initialized successfully
2025-10-01 12:12:44,615 - services.scheduler - INFO - scheduler.py:13 - PostScheduler iniciado
2025-10-01 12:12:44,615 - app - INFO - app.py:763 - Application context initialized successfully
2025-10-01 12:12:44,615 - app - INFO - app.py:775 - Starting Social Media Automation System on 0.0.0.0:5000
2025-10-01 12:12:44,616 - app - INFO - app.py:776 - Debug mode: True
2025-10-01 12:12:44,616 - app - INFO - app.py:777 - Upload folder: uploads
2025-10-01 12:12:44,658 - werkzeug - INFO - _internal.py:187 - [31m[1mWARNING: This is a development server. Do not use it in a production deployment. Use a production WSGI server instead.[0m
 * Running on all addresses (0.0.0.0)
 * Running on http://127.0.0.1:5000
 * Running on http://192.168.0.7:5000
2025-10-01 12:12:44,658 - werkzeug - INFO - _internal.py:187 - [33mPress CTRL+C to quit[0m
2025-10-01 12:12:44,663 - werkzeug - INFO - _internal.py:187 -  * Restarting with stat
2025-10-01 12:12:46,858 - root - INFO - logger.py:49 - Social Media Automation System logging initialized
2025-10-01 12:12:46,859 - __main__ - WARNING - run.py:47 - Configuration warnings:
2025-10-01 12:12:46,859 - __main__ - WARNING - run.py:49 -   - Missing API keys for: YouTube
2025-10-01 12:12:46,860 - __main__ - WARNING - run.py:49 -   - Please change the default JWT_SECRET_KEY in production
2025-10-01 12:12:46,863 - models.database - INFO - database.py:102 - Database initialized successfully
2025-10-01 12:12:46,864 - services.ai_service - ERROR - ai_service.py:26 - Failed to initialize OpenAI client: AsyncClient.__init__() got an unexpected keyword argument 'proxies'
2025-10-01 12:12:46,885 - app - INFO - app.py:59 - Social Media Automation System initialized successfully
2025-10-01 12:12:46,885 - __main__ - INFO - run.py:59 - Starting Social Media Automation System
2025-10-01 12:12:46,886 - __main__ - INFO - run.py:60 - Host: 0.0.0.0, Port: 5000, Debug: True
2025-10-01 12:12:46,886 - __main__ - INFO - run.py:61 - Upload folder: uploads
2025-10-01 12:12:46,886 - __main__ - INFO - run.py:65 - Enabled platforms: instagram, tiktok, kawai
2025-10-01 12:12:46,891 - models.database - INFO - database.py:102 - Database initialized successfully
2025-10-01 12:12:46,893 - services.scheduler - INFO - scheduler.py:13 - PostScheduler iniciado
2025-10-01 12:12:46,893 - app - INFO - app.py:763 - Application context initialized successfully
2025-10-01 12:12:46,894 - app - INFO - app.py:775 - Starting Social Media Automation System on 0.0.0.0:5000
2025-10-01 12:12:46,894 - app - INFO - app.py:776 - Debug mode: True
2025-10-01 12:12:46,895 - app - INFO - app.py:777 - Upload folder: uploads
2025-10-01 12:12:46,913 - werkzeug - WARNING - _internal.py:187 -  * Debugger is active!
2025-10-01 12:12:46,917 - werkzeug - INFO - _internal.py:187 -  * Debugger PIN: 876-337-494
2025-10-01 12:12:50,941 - werkzeug - INFO - _internal.py:187 - 127.0.0.1 - - [01/Oct/2025 12:12:50] "GET / HTTP/1.1" 200 -
2025-10-01 12:12:51,086 - werkzeug - INFO - _internal.py:187 - 127.0.0.1 - - [01/Oct/2025 12:12:51] "[36mGET /static/css/style.css HTTP/1.1[0m" 304 -
2025-10-01 12:12:51,120 - werkzeug - INFO - _internal.py:187 - 127.0.0.1 - - [01/Oct/2025 12:12:51] "[36mGET /static/js/app.js HTTP/1.1[0m" 304 -
2025-10-01 12:12:51,291 - werkzeug - INFO - _internal.py:187 - 127.0.0.1 - - [01/Oct/2025 12:12:51] "GET /api/accounts/status HTTP/1.1" 200 -
2025-10-01 12:13:04,213 - werkzeug - INFO - _internal.py:187 - 127.0.0.1 - - [01/Oct/2025 12:13:04] "GET /api/accounts/status HTTP/1.1" 200 -
2025-10-01 12:13:05,761 - werkzeug - INFO - _internal.py:187 - 127.0.0.1 - - [01/Oct/2025 12:13:05] "GET /oauth/youtube/start HTTP/1.1" 200 -
2025-10-01 12:13:07,887 - werkzeug - INFO - _internal.py:187 - 127.0.0.1 - - [01/Oct/2025 12:13:07] "GET /api/accounts/status HTTP/1.1" 200 -
2025-10-01 21:56:44,804 - werkzeug - INFO - _internal.py:187 - 127.0.0.1 - - [01/Oct/2025 21:56:44] "GET / HTTP/1.1" 200 -
2025-10-01 21:56:44,897 - werkzeug - INFO - _internal.py:187 - 127.0.0.1 - - [01/Oct/2025 21:56:44] "[36mGET /static/css/style.css HTTP/1.1[0m" 304 -
2025-10-01 21:56:44,965 - werkzeug - INFO - _internal.py:187 - 127.0.0.1 - - [01/Oct/2025 21:56:44] "[36mGET /static/js/app.js HTTP/1.1[0m" 304 -
2025-10-01 21:56:45,384 - werkzeug - INFO - _internal.py:187 - 127.0.0.1 - - [01/Oct/2025 21:56:45] "GET /api/accounts/status HTTP/1.1" 200 -
2025-10-01 22:19:46,909 - werkzeug - INFO - _internal.py:187 - 127.0.0.1 - - [01/Oct/2025 22:19:46] "GET / HTTP/1.1" 200 -
2025-10-01 22:19:46,939 - werkzeug - INFO - _internal.py:187 - 127.0.0.1 - - [01/Oct/2025 22:19:46] "[36mGET /static/css/style.css HTTP/1.1[0m" 304 -
2025-10-01 22:19:46,944 - werkzeug - INFO - _internal.py:187 - 127.0.0.1 - - [01/Oct/2025 22:19:46] "[36mGET /static/js/app.js HTTP/1.1[0m" 304 -
2025-10-01 22:19:47,212 - werkzeug - INFO - _internal.py:187 - 127.0.0.1 - - [01/Oct/2025 22:19:47] "GET /api/accounts/status HTTP/1.1" 200 -
2025-10-01 22:20:02,273 - services.scheduler - INFO - scheduler.py:18 - PostScheduler parado
2025-10-01 22:20:02,276 - app - INFO - app.py:790 - Application shutdown complete
2025-10-01 22:20:02,679 - services.scheduler - INFO - scheduler.py:18 - PostScheduler parado
2025-10-01 22:20:02,685 - app - INFO - app.py:790 - Application shutdown complete
2025-10-03 10:41:51,719 - root - INFO - logger.py:49 - Social Media Automation System logging initialized
2025-10-03 10:41:51,722 - __main__ - WARNING - run.py:47 - Configuration warnings:
2025-10-03 10:41:51,722 - __main__ - WARNING - run.py:49 -   - Missing API keys for: YouTube
2025-10-03 10:41:51,722 - __main__ - WARNING - run.py:49 -   - Please change the default JWT_SECRET_KEY in production
2025-10-03 10:41:51,746 - models.database - INFO - database.py:102 - Database initialized successfully
2025-10-03 10:41:51,746 - services.ai_service - ERROR - ai_service.py:26 - Failed to initialize OpenAI client: AsyncClient.__init__() got an unexpected keyword argument 'proxies'
2025-10-03 10:41:51,763 - app - INFO - app.py:59 - Social Media Automation System initialized successfully
2025-10-03 10:41:51,764 - __main__ - INFO - run.py:59 - Starting Social Media Automation System
2025-10-03 10:41:51,764 - __main__ - INFO - run.py:60 - Host: 0.0.0.0, Port: 5000, Debug: True
2025-10-03 10:41:51,764 - __main__ - INFO - run.py:61 - Upload folder: uploads
2025-10-03 10:41:51,768 - __main__ - INFO - run.py:65 - Enabled platforms: instagram, tiktok, kawai
2025-10-03 10:41:51,771 - models.database - INFO - database.py:102 - Database initialized successfully
2025-10-03 10:41:51,772 - services.scheduler - INFO - scheduler.py:13 - PostScheduler iniciado
2025-10-03 10:41:51,772 - app - INFO - app.py:763 - Application context initialized successfully
2025-10-03 10:41:51,773 - app - INFO - app.py:775 - Starting Social Media Automation System on 0.0.0.0:5000
2025-10-03 10:41:51,773 - app - INFO - app.py:776 - Debug mode: True
2025-10-03 10:41:51,774 - app - INFO - app.py:777 - Upload folder: uploads
2025-10-03 10:41:51,819 - werkzeug - INFO - _internal.py:187 - [31m[1mWARNING: This is a development server. Do not use it in a production deployment. Use a production WSGI server instead.[0m
 * Running on all addresses (0.0.0.0)
 * Running on http://127.0.0.1:5000
 * Running on http://192.168.0.7:5000
2025-10-03 10:41:51,819 - werkzeug - INFO - _internal.py:187 - [33mPress CTRL+C to quit[0m
2025-10-03 10:41:51,823 - werkzeug - INFO - _internal.py:187 -  * Restarting with stat
2025-10-03 10:41:53,486 - root - INFO - logger.py:49 - Social Media Automation System logging initialized
2025-10-03 10:41:53,487 - __main__ - WARNING - run.py:47 - Configuration warnings:
2025-10-03 10:41:53,487 - __main__ - WARNING - run.py:49 -   - Missing API keys for: YouTube
2025-10-03 10:41:53,487 - __main__ - WARNING - run.py:49 -   - Please change the default JWT_SECRET_KEY in production
2025-10-03 10:41:53,491 - models.database - INFO - database.py:102 - Database initialized successfully
2025-10-03 10:41:53,491 - services.ai_service - ERROR - ai_service.py:26 - Failed to initialize OpenAI client: AsyncClient.__init__() got an unexpected keyword argument 'proxies'
2025-10-03 10:41:53,516 - app - INFO - app.py:59 - Social Media Automation System initialized successfully
2025-10-03 10:41:53,516 - __main__ - INFO - run.py:59 - Starting Social Media Automation System
2025-10-03 10:41:53,517 - __main__ - INFO - run.py:60 - Host: 0.0.0.0, Port: 5000, Debug: True
2025-10-03 10:41:53,517 - __main__ - INFO - run.py:61 - Upload folder: uploads
2025-10-03 10:41:53,518 - __main__ - INFO - run.py:65 - Enabled platforms: instagram, tiktok, kawai
2025-10-03 10:41:53,520 - models.database - INFO - database.py:102 - Database initialized successfully
2025-10-03 10:41:53,520 - services.scheduler - INFO - scheduler.py:13 - PostScheduler iniciado
2025-10-03 10:41:53,521 - app - INFO - app.py:763 - Application context initialized successfully
2025-10-03 10:41:53,521 - app - INFO - app.py:775 - Starting Social Media Automation System on 0.0.0.0:5000
2025-10-03 10:41:53,521 - app - INFO - app.py:776 - Debug mode: True
2025-10-03 10:41:53,522 - app - INFO - app.py:777 - Upload folder: uploads
2025-10-03 10:41:53,542 - werkzeug - WARNING - _internal.py:187 -  * Debugger is active!
2025-10-03 10:41:53,545 - werkzeug - INFO - _internal.py:187 -  * Debugger PIN: 876-337-494
2025-10-03 10:42:23,545 - werkzeug - INFO - _internal.py:187 - 127.0.0.1 - - [03/Oct/2025 10:42:23] "GET / HTTP/1.1" 200 -
2025-10-03 10:42:23,792 - werkzeug - INFO - _internal.py:187 - 127.0.0.1 - - [03/Oct/2025 10:42:23] "GET /static/css/style.css HTTP/1.1" 200 -
2025-10-03 10:42:23,853 - werkzeug - INFO - _internal.py:187 - 127.0.0.1 - - [03/Oct/2025 10:42:23] "GET /static/js/app.js HTTP/1.1" 200 -
2025-10-03 10:42:25,395 - werkzeug - INFO - _internal.py:187 - 127.0.0.1 - - [03/Oct/2025 10:42:25] "GET /api/accounts/status HTTP/1.1" 200 -
2025-10-03 10:42:44,554 - werkzeug - INFO - _internal.py:187 - 127.0.0.1 - - [03/Oct/2025 10:42:44] "GET /api/accounts/status HTTP/1.1" 200 -
2025-10-03 10:42:47,148 - werkzeug - INFO - _internal.py:187 - 127.0.0.1 - - [03/Oct/2025 10:42:47] "GET /oauth/youtube/start HTTP/1.1" 200 -
2025-10-03 10:42:49,320 - werkzeug - INFO - _internal.py:187 - 127.0.0.1 - - [03/Oct/2025 10:42:49] "GET /api/accounts/status HTTP/1.1" 200 -
2025-10-03 10:43:11,598 - werkzeug - INFO - _internal.py:187 - 127.0.0.1 - - [03/Oct/2025 10:43:11] "GET /oauth/youtube/start HTTP/1.1" 200 -
2025-10-03 10:43:12,727 - werkzeug - INFO - _internal.py:187 - 127.0.0.1 - - [03/Oct/2025 10:43:12] "GET /api/accounts/status HTTP/1.1" 200 -
2025-10-03 11:20:56,651 - services.scheduler - INFO - scheduler.py:18 - PostScheduler parado
2025-10-03 11:20:56,653 - app - INFO - app.py:790 - Application shutdown complete
2025-10-03 11:20:56,861 - services.scheduler - INFO - scheduler.py:18 - PostScheduler parado
2025-10-03 11:20:56,862 - app - INFO - app.py:790 - Application shutdown complete
2025-10-03 12:40:28,767 - root - INFO - logger.py:49 - Social Media Automation System logging initialized
2025-10-03 12:40:28,784 - __main__ - WARNING - run.py:47 - Configuration warnings:
2025-10-03 12:40:28,785 - __main__ - WARNING - run.py:49 -   - Missing API keys for: YouTube
2025-10-03 12:40:28,786 - __main__ - WARNING - run.py:49 -   - Please change the default JWT_SECRET_KEY in production
2025-10-03 12:40:28,792 - models.database - INFO - database.py:102 - Database initialized successfully
2025-10-03 12:40:28,793 - services.ai_service - ERROR - ai_service.py:26 - Failed to initialize OpenAI client: AsyncClient.__init__() got an unexpected keyword argument 'proxies'
2025-10-03 12:40:28,819 - app - INFO - app.py:59 - Social Media Automation System initialized successfully
2025-10-03 12:40:28,820 - __main__ - INFO - run.py:59 - Starting Social Media Automation System
2025-10-03 12:40:28,821 - __main__ - INFO - run.py:60 - Host: 0.0.0.0, Port: 5000, Debug: True
2025-10-03 12:40:28,821 - __main__ - INFO - run.py:61 - Upload folder: uploads
2025-10-03 12:40:28,822 - __main__ - INFO - run.py:65 - Enabled platforms: instagram, tiktok, kawai
2025-10-03 12:40:28,825 - models.database - INFO - database.py:102 - Database initialized successfully
2025-10-03 12:40:28,829 - services.scheduler - INFO - scheduler.py:13 - PostScheduler iniciado
2025-10-03 12:40:28,830 - app - INFO - app.py:763 - Application context initialized successfully
2025-10-03 12:40:28,830 - app - INFO - app.py:775 - Starting Social Media Automation System on 0.0.0.0:5000
2025-10-03 12:40:28,830 - app - INFO - app.py:776 - Debug mode: True
2025-10-03 12:40:28,831 - app - INFO - app.py:777 - Upload folder: uploads
2025-10-03 12:40:28,877 - werkzeug - INFO - _internal.py:187 - [31m[1mWARNING: This is a development server. Do not use it in a production deployment. Use a production WSGI server instead.[0m
 * Running on all addresses (0.0.0.0)
 * Running on http://127.0.0.1:5000
 * Running on http://192.168.0.7:5000
2025-10-03 12:40:28,878 - werkzeug - INFO - _internal.py:187 - [33mPress CTRL+C to quit[0m
2025-10-03 12:40:28,883 - werkzeug - INFO - _internal.py:187 -  * Restarting with stat
2025-10-03 12:40:30,987 - root - INFO - logger.py:49 - Social Media Automation System logging initialized
2025-10-03 12:40:30,989 - __main__ - WARNING - run.py:47 - Configuration warnings:
2025-10-03 12:40:30,989 - __main__ - WARNING - run.py:49 -   - Missing API keys for: YouTube
2025-10-03 12:40:30,989 - __main__ - WARNING - run.py:49 -   - Please change the default JWT_SECRET_KEY in production
2025-10-03 12:40:30,993 - models.database - INFO - database.py:102 - Database initialized successfully
2025-10-03 12:40:30,994 - services.ai_service - ERROR - ai_service.py:26 - Failed to initialize OpenAI client: AsyncClient.__init__() got an unexpected keyword argument 'proxies'
2025-10-03 12:40:31,023 - app - INFO - app.py:59 - Social Media Automation System initialized successfully
2025-10-03 12:40:31,024 - __main__ - INFO - run.py:59 - Starting Social Media Automation System
2025-10-03 12:40:31,024 - __main__ - INFO - run.py:60 - Host: 0.0.0.0, Port: 5000, Debug: True
2025-10-03 12:40:31,025 - __main__ - INFO - run.py:61 - Upload folder: uploads
2025-10-03 12:40:31,026 - __main__ - INFO - run.py:65 - Enabled platforms: instagram, tiktok, kawai
2025-10-03 12:40:31,029 - models.database - INFO - database.py:102 - Database initialized successfully
2025-10-03 12:40:31,032 - services.scheduler - INFO - scheduler.py:13 - PostScheduler iniciado
2025-10-03 12:40:31,034 - app - INFO - app.py:763 - Application context initialized successfully
2025-10-03 12:40:31,046 - app - INFO - app.py:775 - Starting Social Media Automation System on 0.0.0.0:5000
2025-10-03 12:40:31,050 - app - INFO - app.py:776 - Debug mode: True
2025-10-03 12:40:31,060 - app - INFO - app.py:777 - Upload folder: uploads
2025-10-03 12:40:31,084 - werkzeug - WARNING - _internal.py:187 -  * Debugger is active!
2025-10-03 12:40:31,093 - werkzeug - INFO - _internal.py:187 -  * Debugger PIN: 876-337-494
2025-10-03 12:40:38,399 - werkzeug - INFO - _internal.py:187 - 127.0.0.1 - - [03/Oct/2025 12:40:38] "GET / HTTP/1.1" 200 -
2025-10-03 12:40:38,558 - werkzeug - INFO - _internal.py:187 - 127.0.0.1 - - [03/Oct/2025 12:40:38] "GET /static/css/style.css HTTP/1.1" 200 -
2025-10-03 12:40:38,620 - werkzeug - INFO - _internal.py:187 - 127.0.0.1 - - [03/Oct/2025 12:40:38] "GET /static/js/app.js HTTP/1.1" 200 -
2025-10-03 12:40:38,782 - werkzeug - INFO - _internal.py:187 - 127.0.0.1 - - [03/Oct/2025 12:40:38] "GET /api/accounts/status HTTP/1.1" 200 -
2025-10-03 12:40:51,855 - werkzeug - INFO - _internal.py:187 - 127.0.0.1 - - [03/Oct/2025 12:40:51] "GET /api/accounts/status HTTP/1.1" 200 -
2025-10-03 12:40:53,378 - werkzeug - INFO - _internal.py:187 - 127.0.0.1 - - [03/Oct/2025 12:40:53] "GET /oauth/youtube/start HTTP/1.1" 200 -
2025-10-03 12:40:55,518 - werkzeug - INFO - _internal.py:187 - 127.0.0.1 - - [03/Oct/2025 12:40:55] "GET /api/accounts/status HTTP/1.1" 200 -
2025-10-03 12:45:18,421 - services.scheduler - INFO - scheduler.py:18 - PostScheduler parado
2025-10-03 12:45:18,422 - app - INFO - app.py:790 - Application shutdown complete
2025-10-03 12:45:18,620 - services.scheduler - INFO - scheduler.py:18 - PostScheduler parado
2025-10-03 12:45:18,621 - app - INFO - app.py:790 - Application shutdown complete
2025-10-04 13:15:00,014 - root - INFO - logger.py:49 - Social Media Automation System logging initialized
2025-10-04 13:15:00,017 - __main__ - WARNING - run.py:47 - Configuration warnings:
2025-10-04 13:15:00,018 - __main__ - WARNING - run.py:49 -   - Missing API keys for: YouTube, Instagram, TikTok, Kawai
2025-10-04 13:15:00,019 - __main__ - WARNING - run.py:49 -   - Please change the default JWT_SECRET_KEY in production
2025-10-04 13:15:00,049 - models.database - INFO - database.py:102 - Database initialized successfully
2025-10-04 13:15:00,051 - services.ai_service - ERROR - ai_service.py:26 - Failed to initialize OpenAI client: AsyncClient.__init__() got an unexpected keyword argument 'proxies'
2025-10-04 13:15:00,072 - app - INFO - app.py:59 - Social Media Automation System initialized successfully
2025-10-04 13:15:00,072 - __main__ - INFO - run.py:59 - Starting Social Media Automation System
2025-10-04 13:15:00,073 - __main__ - INFO - run.py:60 - Host: 0.0.0.0, Port: 5000, Debug: True
2025-10-04 13:15:00,074 - __main__ - INFO - run.py:61 - Upload folder: uploads
2025-10-04 13:15:00,074 - __main__ - INFO - run.py:65 - Enabled platforms: None
2025-10-04 13:15:00,075 - __main__ - WARNING - run.py:68 - No platforms are properly configured. Please check your API keys.
2025-10-04 13:15:00,077 - models.database - INFO - database.py:102 - Database initialized successfully
2025-10-04 13:15:00,080 - services.scheduler - INFO - scheduler.py:13 - PostScheduler iniciado
2025-10-04 13:15:00,081 - app - INFO - app.py:763 - Application context initialized successfully
2025-10-04 13:15:00,081 - app - INFO - app.py:775 - Starting Social Media Automation System on 0.0.0.0:5000
2025-10-04 13:15:00,082 - app - INFO - app.py:776 - Debug mode: True
2025-10-04 13:15:00,082 - app - INFO - app.py:777 - Upload folder: uploads
2025-10-04 13:15:00,130 - werkzeug - INFO - _internal.py:187 - [31m[1mWARNING: This is a development server. Do not use it in a production deployment. Use a production WSGI server instead.[0m
 * Running on all addresses (0.0.0.0)
 * Running on http://127.0.0.1:5000
 * Running on http://192.168.0.7:5000
2025-10-04 13:15:00,131 - werkzeug - INFO - _internal.py:187 - [33mPress CTRL+C to quit[0m
2025-10-04 13:15:00,135 - werkzeug - INFO - _internal.py:187 -  * Restarting with stat
2025-10-04 13:15:02,119 - root - INFO - logger.py:49 - Social Media Automation System logging initialized
2025-10-04 13:15:02,121 - __main__ - WARNING - run.py:47 - Configuration warnings:
2025-10-04 13:15:02,121 - __main__ - WARNING - run.py:49 -   - Missing API keys for: YouTube, Instagram, TikTok, Kawai
2025-10-04 13:15:02,121 - __main__ - WARNING - run.py:49 -   - Please change the default JWT_SECRET_KEY in production
2025-10-04 13:15:02,125 - models.database - INFO - database.py:102 - Database initialized successfully
2025-10-04 13:15:02,126 - services.ai_service - ERROR - ai_service.py:26 - Failed to initialize OpenAI client: AsyncClient.__init__() got an unexpected keyword argument 'proxies'
2025-10-04 13:15:02,154 - app - INFO - app.py:59 - Social Media Automation System initialized successfully
2025-10-04 13:15:02,155 - __main__ - INFO - run.py:59 - Starting Social Media Automation System
2025-10-04 13:15:02,155 - __main__ - INFO - run.py:60 - Host: 0.0.0.0, Port: 5000, Debug: True
2025-10-04 13:15:02,156 - __main__ - INFO - run.py:61 - Upload folder: uploads
2025-10-04 13:15:02,156 - __main__ - INFO - run.py:65 - Enabled platforms: None
2025-10-04 13:15:02,156 - __main__ - WARNING - run.py:68 - No platforms are properly configured. Please check your API keys.
2025-10-04 13:15:02,158 - models.database - INFO - database.py:102 - Database initialized successfully
2025-10-04 13:15:02,159 - services.scheduler - INFO - scheduler.py:13 - PostScheduler iniciado
2025-10-04 13:15:02,159 - app - INFO - app.py:763 - Application context initialized successfully
2025-10-04 13:15:02,159 - app - INFO - app.py:775 - Starting Social Media Automation System on 0.0.0.0:5000
2025-10-04 13:15:02,160 - app - INFO - app.py:776 - Debug mode: True
2025-10-04 13:15:02,160 - app - INFO - app.py:777 - Upload folder: uploads
2025-10-04 13:15:02,187 - werkzeug - WARNING - _internal.py:187 -  * Debugger is active!
2025-10-04 13:15:02,196 - werkzeug - INFO - _internal.py:187 -  * Debugger PIN: 876-337-494
2025-10-04 13:15:11,018 - werkzeug - INFO - _internal.py:187 - 127.0.0.1 - - [04/Oct/2025 13:15:11] "GET / HTTP/1.1" 200 -
2025-10-04 13:15:11,222 - werkzeug - INFO - _internal.py:187 - 127.0.0.1 - - [04/Oct/2025 13:15:11] "[36mGET /static/css/style.css HTTP/1.1[0m" 304 -
2025-10-04 13:15:11,239 - werkzeug - INFO - _internal.py:187 - 127.0.0.1 - - [04/Oct/2025 13:15:11] "[36mGET /static/js/app.js HTTP/1.1[0m" 304 -
2025-10-04 13:15:11,469 - werkzeug - INFO - _internal.py:187 - 127.0.0.1 - - [04/Oct/2025 13:15:11] "GET /api/accounts/status HTTP/1.1" 200 -
2025-10-04 13:15:14,173 - werkzeug - INFO - _internal.py:187 - 127.0.0.1 - - [04/Oct/2025 13:15:14] "GET /api/accounts/status HTTP/1.1" 200 -
2025-10-04 13:15:16,594 - werkzeug - INFO - _internal.py:187 - 127.0.0.1 - - [04/Oct/2025 13:15:16] "GET /oauth/youtube/start HTTP/1.1" 200 -
2025-10-04 13:15:23,730 - werkzeug - INFO - _internal.py:187 - 127.0.0.1 - - [04/Oct/2025 13:15:23] "GET /api/accounts/status HTTP/1.1" 200 -
2025-10-04 13:15:51,977 - werkzeug - INFO - _internal.py:187 - 127.0.0.1 - - [04/Oct/2025 13:15:51] "GET / HTTP/1.1" 200 -
2025-10-04 13:15:52,068 - werkzeug - INFO - _internal.py:187 - 127.0.0.1 - - [04/Oct/2025 13:15:52] "GET /static/css/style.css HTTP/1.1" 200 -
2025-10-04 13:15:52,122 - werkzeug - INFO - _internal.py:187 - 127.0.0.1 - - [04/Oct/2025 13:15:52] "GET /static/js/app.js HTTP/1.1" 200 -
2025-10-04 13:15:52,376 - werkzeug - INFO - _internal.py:187 - 127.0.0.1 - - [04/Oct/2025 13:15:52] "GET /api/accounts/status HTTP/1.1" 200 -
2025-10-04 13:15:52,512 - werkzeug - INFO - _internal.py:187 - 127.0.0.1 - - [04/Oct/2025 13:15:52] "[33mGET /favicon.ico HTTP/1.1[0m" 404 -
2025-10-04 13:15:54,955 - werkzeug - INFO - _internal.py:187 - 127.0.0.1 - - [04/Oct/2025 13:15:54] "GET /api/accounts/status HTTP/1.1" 200 -
2025-10-04 13:15:56,652 - werkzeug - INFO - _internal.py:187 - 127.0.0.1 - - [04/Oct/2025 13:15:56] "GET /oauth/youtube/start HTTP/1.1" 200 -
2025-10-04 13:16:02,774 - werkzeug - INFO - _internal.py:187 - 127.0.0.1 - - [04/Oct/2025 13:16:02] "GET /api/accounts/status HTTP/1.1" 200 -
2025-10-04 13:36:46,389 - werkzeug - INFO - _internal.py:187 - 127.0.0.1 - - [04/Oct/2025 13:36:46] "GET /oauth/youtube/start HTTP/1.1" 200 -
2025-10-04 13:36:53,544 - werkzeug - INFO - _internal.py:187 - 127.0.0.1 - - [04/Oct/2025 13:36:53] "GET /api/accounts/status HTTP/1.1" 200 -
2025-10-04 13:39:17,797 - services.scheduler - INFO - scheduler.py:18 - PostScheduler parado
2025-10-04 13:39:17,797 - app - INFO - app.py:790 - Application shutdown complete
2025-10-04 13:39:18,026 - services.scheduler - INFO - scheduler.py:18 - PostScheduler parado
2025-10-04 13:39:18,027 - app - INFO - app.py:790 - Application shutdown complete
2025-10-04 13:39:31,733 - root - INFO - logger.py:49 - Social Media Automation System logging initialized
2025-10-04 13:39:31,734 - __main__ - WARNING - run.py:47 - Configuration warnings:
2025-10-04 13:39:31,734 - __main__ - WARNING - run.py:49 -   - Missing API keys for: YouTube, Instagram, TikTok, Kawai
2025-10-04 13:39:31,735 - __main__ - WARNING - run.py:49 -   - Please change the default JWT_SECRET_KEY in production
2025-10-04 13:39:31,738 - models.database - INFO - database.py:102 - Database initialized successfully
2025-10-04 13:39:31,739 - services.ai_service - ERROR - ai_service.py:26 - Failed to initialize OpenAI client: AsyncClient.__init__() got an unexpected keyword argument 'proxies'
2025-10-04 13:39:31,753 - app - INFO - app.py:59 - Social Media Automation System initialized successfully
2025-10-04 13:39:31,753 - __main__ - INFO - run.py:59 - Starting Social Media Automation System
2025-10-04 13:39:31,754 - __main__ - INFO - run.py:60 - Host: 0.0.0.0, Port: 5000, Debug: True
2025-10-04 13:39:31,754 - __main__ - INFO - run.py:61 - Upload folder: uploads
2025-10-04 13:39:31,754 - __main__ - INFO - run.py:65 - Enabled platforms: None
2025-10-04 13:39:31,754 - __main__ - WARNING - run.py:68 - No platforms are properly configured. Please check your API keys.
2025-10-04 13:39:31,756 - models.database - INFO - database.py:102 - Database initialized successfully
2025-10-04 13:39:31,757 - services.scheduler - INFO - scheduler.py:13 - PostScheduler iniciado
2025-10-04 13:39:31,757 - app - INFO - app.py:763 - Application context initialized successfully
2025-10-04 13:39:31,757 - app - INFO - app.py:775 - Starting Social Media Automation System on 0.0.0.0:5000
2025-10-04 13:39:31,758 - app - INFO - app.py:776 - Debug mode: True
2025-10-04 13:39:31,758 - app - INFO - app.py:777 - Upload folder: uploads
2025-10-04 13:39:31,789 - werkzeug - INFO - _internal.py:187 - [31m[1mWARNING: This is a development server. Do not use it in a production deployment. Use a production WSGI server instead.[0m
 * Running on all addresses (0.0.0.0)
 * Running on http://127.0.0.1:5000
 * Running on http://192.168.0.7:5000
2025-10-04 13:39:31,795 - werkzeug - INFO - _internal.py:187 - [33mPress CTRL+C to quit[0m
2025-10-04 13:39:31,798 - werkzeug - INFO - _internal.py:187 -  * Restarting with stat
2025-10-04 13:39:33,616 - root - INFO - logger.py:49 - Social Media Automation System logging initialized
2025-10-04 13:39:33,617 - __main__ - WARNING - run.py:47 - Configuration warnings:
2025-10-04 13:39:33,617 - __main__ - WARNING - run.py:49 -   - Missing API keys for: YouTube, Instagram, TikTok, Kawai
2025-10-04 13:39:33,618 - __main__ - WARNING - run.py:49 -   - Please change the default JWT_SECRET_KEY in production
2025-10-04 13:39:33,621 - models.database - INFO - database.py:102 - Database initialized successfully
2025-10-04 13:39:33,622 - services.ai_service - ERROR - ai_service.py:26 - Failed to initialize OpenAI client: AsyncClient.__init__() got an unexpected keyword argument 'proxies'
2025-10-04 13:39:33,644 - app - INFO - app.py:59 - Social Media Automation System initialized successfully
2025-10-04 13:39:33,644 - __main__ - INFO - run.py:59 - Starting Social Media Automation System
2025-10-04 13:39:33,645 - __main__ - INFO - run.py:60 - Host: 0.0.0.0, Port: 5000, Debug: True
2025-10-04 13:39:33,645 - __main__ - INFO - run.py:61 - Upload folder: uploads
2025-10-04 13:39:33,646 - __main__ - INFO - run.py:65 - Enabled platforms: None
2025-10-04 13:39:33,646 - __main__ - WARNING - run.py:68 - No platforms are properly configured. Please check your API keys.
2025-10-04 13:39:33,684 - models.database - INFO - database.py:102 - Database initialized successfully
2025-10-04 13:39:33,692 - services.scheduler - INFO - scheduler.py:13 - PostScheduler iniciado
2025-10-04 13:39:33,730 - app - INFO - app.py:763 - Application context initialized successfully
2025-10-04 13:39:33,772 - app - INFO - app.py:775 - Starting Social Media Automation System on 0.0.0.0:5000
2025-10-04 13:39:33,777 - app - INFO - app.py:776 - Debug mode: True
2025-10-04 13:39:33,778 - app - INFO - app.py:777 - Upload folder: uploads
2025-10-04 13:39:33,821 - werkzeug - WARNING - _internal.py:187 -  * Debugger is active!
2025-10-04 13:39:33,831 - werkzeug - INFO - _internal.py:187 -  * Debugger PIN: 876-337-494
2025-10-04 13:39:38,635 - werkzeug - INFO - _internal.py:187 - 127.0.0.1 - - [04/Oct/2025 13:39:38] "GET / HTTP/1.1" 200 -
2025-10-04 13:39:38,800 - werkzeug - INFO - _internal.py:187 - 127.0.0.1 - - [04/Oct/2025 13:39:38] "[36mGET /static/css/style.css HTTP/1.1[0m" 304 -
2025-10-04 13:39:38,824 - werkzeug - INFO - _internal.py:187 - 127.0.0.1 - - [04/Oct/2025 13:39:38] "[36mGET /static/js/app.js HTTP/1.1[0m" 304 -
2025-10-04 13:39:39,060 - werkzeug - INFO - _internal.py:187 - 127.0.0.1 - - [04/Oct/2025 13:39:39] "GET /api/accounts/status HTTP/1.1" 200 -
2025-10-04 13:39:41,631 - werkzeug - INFO - _internal.py:187 - 127.0.0.1 - - [04/Oct/2025 13:39:41] "GET /api/accounts/status HTTP/1.1" 200 -
2025-10-04 13:39:44,456 - werkzeug - INFO - _internal.py:187 - 127.0.0.1 - - [04/Oct/2025 13:39:44] "GET /oauth/youtube/start HTTP/1.1" 200 -
2025-10-04 13:39:51,585 - werkzeug - INFO - _internal.py:187 - 127.0.0.1 - - [04/Oct/2025 13:39:51] "GET /api/accounts/status HTTP/1.1" 200 -
2025-10-04 15:45:19,661 - werkzeug - INFO - _internal.py:187 - 127.0.0.1 - - [04/Oct/2025 15:45:19] "GET / HTTP/1.1" 200 -
2025-10-04 15:45:19,726 - werkzeug - INFO - _internal.py:187 - 127.0.0.1 - - [04/Oct/2025 15:45:19] "[36mGET /static/css/style.css HTTP/1.1[0m" 304 -
2025-10-04 15:45:19,848 - werkzeug - INFO - _internal.py:187 - 127.0.0.1 - - [04/Oct/2025 15:45:19] "[36mGET /static/js/app.js HTTP/1.1[0m" 304 -
2025-10-04 15:45:19,898 - werkzeug - INFO - _internal.py:187 - 127.0.0.1 - - [04/Oct/2025 15:45:19] "GET /api/accounts/status HTTP/1.1" 200 -
2025-10-04 15:45:21,695 - werkzeug - INFO - _internal.py:187 - 127.0.0.1 - - [04/Oct/2025 15:45:21] "GET /api/accounts/status HTTP/1.1" 200 -
2025-10-04 15:45:24,495 - werkzeug - INFO - _internal.py:187 - 127.0.0.1 - - [04/Oct/2025 15:45:24] "GET /oauth/youtube/start HTTP/1.1" 200 -
2025-10-04 15:45:30,640 - werkzeug - INFO - _internal.py:187 - 127.0.0.1 - - [04/Oct/2025 15:45:30] "GET /api/accounts/status HTTP/1.1" 200 -
2025-10-04 18:16:14,726 - root - INFO - logger.py:49 - Social Media Automation System logging initialized
2025-10-04 18:16:14,727 - __main__ - WARNING - run.py:47 - Configuration warnings:
2025-10-04 18:16:14,728 - __main__ - WARNING - run.py:49 -   - Missing API keys for: YouTube, Instagram, TikTok, Kawai
2025-10-04 18:16:14,728 - __main__ - WARNING - run.py:49 -   - Please change the default JWT_SECRET_KEY in production
2025-10-04 18:16:14,733 - models.database - INFO - database.py:102 - Database initialized successfully
2025-10-04 18:16:14,734 - services.ai_service - ERROR - ai_service.py:26 - Failed to initialize OpenAI client: AsyncClient.__init__() got an unexpected keyword argument 'proxies'
2025-10-04 18:16:14,748 - app - INFO - app.py:59 - Social Media Automation System initialized successfully
2025-10-04 18:16:14,748 - __main__ - INFO - run.py:59 - Starting Social Media Automation System
2025-10-04 18:16:14,748 - __main__ - INFO - run.py:60 - Host: 0.0.0.0, Port: 5000, Debug: True
2025-10-04 18:16:14,749 - __main__ - INFO - run.py:61 - Upload folder: uploads
2025-10-04 18:16:14,749 - __main__ - INFO - run.py:65 - Enabled platforms: None
2025-10-04 18:16:14,749 - __main__ - WARNING - run.py:68 - No platforms are properly configured. Please check your API keys.
2025-10-04 18:16:14,751 - models.database - INFO - database.py:102 - Database initialized successfully
2025-10-04 18:16:14,752 - services.scheduler - INFO - scheduler.py:13 - PostScheduler iniciado
2025-10-04 18:16:14,752 - app - INFO - app.py:763 - Application context initialized successfully
2025-10-04 18:16:14,753 - app - INFO - app.py:775 - Starting Social Media Automation System on 0.0.0.0:5000
2025-10-04 18:16:14,754 - app - INFO - app.py:776 - Debug mode: True
2025-10-04 18:16:14,755 - app - INFO - app.py:777 - Upload folder: uploads
2025-10-04 18:16:14,797 - werkzeug - INFO - _internal.py:187 - [31m[1mWARNING: This is a development server. Do not use it in a production deployment. Use a production WSGI server instead.[0m
 * Running on all addresses (0.0.0.0)
 * Running on http://127.0.0.1:5000
 * Running on http://192.168.0.7:5000
2025-10-04 18:16:14,797 - werkzeug - INFO - _internal.py:187 - [33mPress CTRL+C to quit[0m
2025-10-04 18:16:14,803 - werkzeug - INFO - _internal.py:187 -  * Restarting with stat
2025-10-04 18:16:16,557 - root - INFO - logger.py:49 - Social Media Automation System logging initialized
2025-10-04 18:16:16,558 - __main__ - WARNING - run.py:47 - Configuration warnings:
2025-10-04 18:16:16,558 - __main__ - WARNING - run.py:49 -   - Missing API keys for: YouTube, Instagram, TikTok, Kawai
2025-10-04 18:16:16,558 - __main__ - WARNING - run.py:49 -   - Please change the default JWT_SECRET_KEY in production
2025-10-04 18:16:16,562 - models.database - INFO - database.py:102 - Database initialized successfully
2025-10-04 18:16:16,562 - services.ai_service - ERROR - ai_service.py:26 - Failed to initialize OpenAI client: AsyncClient.__init__() got an unexpected keyword argument 'proxies'
2025-10-04 18:16:16,582 - app - INFO - app.py:59 - Social Media Automation System initialized successfully
2025-10-04 18:16:16,583 - __main__ - INFO - run.py:59 - Starting Social Media Automation System
2025-10-04 18:16:16,584 - __main__ - INFO - run.py:60 - Host: 0.0.0.0, Port: 5000, Debug: True
2025-10-04 18:16:16,584 - __main__ - INFO - run.py:61 - Upload folder: uploads
2025-10-04 18:16:16,586 - __main__ - INFO - run.py:65 - Enabled platforms: None
2025-10-04 18:16:16,586 - __main__ - WARNING - run.py:68 - No platforms are properly configured. Please check your API keys.
2025-10-04 18:16:16,591 - models.database - INFO - database.py:102 - Database initialized successfully
2025-10-04 18:16:16,591 - services.scheduler - INFO - scheduler.py:13 - PostScheduler iniciado
2025-10-04 18:16:16,592 - app - INFO - app.py:763 - Application context initialized successfully
2025-10-04 18:16:16,592 - app - INFO - app.py:775 - Starting Social Media Automation System on 0.0.0.0:5000
2025-10-04 18:16:16,592 - app - INFO - app.py:776 - Debug mode: True
2025-10-04 18:16:16,593 - app - INFO - app.py:777 - Upload folder: uploads
2025-10-04 18:16:16,610 - werkzeug - WARNING - _internal.py:187 -  * Debugger is active!
2025-10-04 18:16:16,615 - werkzeug - INFO - _internal.py:187 -  * Debugger PIN: 876-337-494
2025-10-04 18:16:27,841 - werkzeug - INFO - _internal.py:187 - 127.0.0.1 - - [04/Oct/2025 18:16:27] "GET / HTTP/1.1" 200 -
2025-10-04 18:16:28,031 - werkzeug - INFO - _internal.py:187 - 127.0.0.1 - - [04/Oct/2025 18:16:28] "[36mGET /static/css/style.css HTTP/1.1[0m" 304 -
2025-10-04 18:16:28,058 - werkzeug - INFO - _internal.py:187 - 127.0.0.1 - - [04/Oct/2025 18:16:28] "[36mGET /static/js/app.js HTTP/1.1[0m" 304 -
2025-10-04 18:16:28,241 - werkzeug - INFO - _internal.py:187 - 127.0.0.1 - - [04/Oct/2025 18:16:28] "GET /api/accounts/status HTTP/1.1" 200 -
2025-10-04 18:16:35,032 - werkzeug - INFO - _internal.py:187 - 127.0.0.1 - - [04/Oct/2025 18:16:35] "GET /api/accounts/status HTTP/1.1" 200 -
2025-10-04 18:16:37,315 - werkzeug - INFO - _internal.py:187 - 127.0.0.1 - - [04/Oct/2025 18:16:37] "GET /oauth/youtube/start HTTP/1.1" 200 -
2025-10-04 18:16:43,450 - werkzeug - INFO - _internal.py:187 - 127.0.0.1 - - [04/Oct/2025 18:16:43] "GET /api/accounts/status HTTP/1.1" 200 -
2025-10-04 18:17:10,981 - werkzeug - INFO - _internal.py:187 - 127.0.0.1 - - [04/Oct/2025 18:17:10] "GET / HTTP/1.1" 200 -
2025-10-04 18:17:11,022 - werkzeug - INFO - _internal.py:187 - 127.0.0.1 - - [04/Oct/2025 18:17:11] "[36mGET /static/css/style.css HTTP/1.1[0m" 304 -
2025-10-04 18:17:11,033 - werkzeug - INFO - _internal.py:187 - 127.0.0.1 - - [04/Oct/2025 18:17:11] "[36mGET /static/js/app.js HTTP/1.1[0m" 304 -
2025-10-04 18:17:11,215 - werkzeug - INFO - _internal.py:187 - 127.0.0.1 - - [04/Oct/2025 18:17:11] "GET /api/accounts/status HTTP/1.1" 200 -
2025-10-04 18:17:16,019 - werkzeug - INFO - _internal.py:187 - 127.0.0.1 - - [04/Oct/2025 18:17:16] "GET /api/accounts/status HTTP/1.1" 200 -
2025-10-04 18:17:17,637 - werkzeug - INFO - _internal.py:187 - 127.0.0.1 - - [04/Oct/2025 18:17:17] "GET /oauth/youtube/start HTTP/1.1" 200 -
2025-10-04 18:17:24,766 - werkzeug - INFO - _internal.py:187 - 127.0.0.1 - - [04/Oct/2025 18:17:24] "GET /api/accounts/status HTTP/1.1" 200 -
2025-10-04 18:19:23,327 - werkzeug - INFO - _internal.py:187 - 127.0.0.1 - - [04/Oct/2025 18:19:23] "GET /oauth/youtube/start HTTP/1.1" 200 -
2025-10-04 18:19:30,466 - werkzeug - INFO - _internal.py:187 - 127.0.0.1 - - [04/Oct/2025 18:19:30] "GET /api/accounts/status HTTP/1.1" 200 -
2025-10-04 18:20:43,098 - werkzeug - INFO - _internal.py:187 - 127.0.0.1 - - [04/Oct/2025 18:20:43] "GET /oauth/youtube/start HTTP/1.1" 200 -
2025-10-04 18:20:49,220 - werkzeug - INFO - _internal.py:187 - 127.0.0.1 - - [04/Oct/2025 18:20:49] "GET /api/accounts/status HTTP/1.1" 200 -
2025-10-04 18:22:51,567 - services.scheduler - INFO - scheduler.py:18 - PostScheduler parado
2025-10-04 18:22:51,568 - app - INFO - app.py:790 - Application shutdown complete
2025-10-04 18:22:51,773 - services.scheduler - INFO - scheduler.py:18 - PostScheduler parado
2025-10-04 18:22:51,773 - app - INFO - app.py:790 - Application shutdown complete
2025-10-04 18:23:00,209 - root - INFO - logger.py:49 - Social Media Automation System logging initialized
2025-10-04 18:23:00,210 - __main__ - WARNING - run.py:47 - Configuration warnings:
2025-10-04 18:23:00,210 - __main__ - WARNING - run.py:49 -   - Missing API keys for: YouTube, Instagram, TikTok, Kawai
2025-10-04 18:23:00,210 - __main__ - WARNING - run.py:49 -   - Please change the default JWT_SECRET_KEY in production
2025-10-04 18:23:00,214 - models.database - INFO - database.py:102 - Database initialized successfully
2025-10-04 18:23:00,215 - services.ai_service - ERROR - ai_service.py:26 - Failed to initialize OpenAI client: AsyncClient.__init__() got an unexpected keyword argument 'proxies'
2025-10-04 18:23:00,227 - app - INFO - app.py:59 - Social Media Automation System initialized successfully
2025-10-04 18:23:00,228 - __main__ - INFO - run.py:59 - Starting Social Media Automation System
2025-10-04 18:23:00,228 - __main__ - INFO - run.py:60 - Host: 0.0.0.0, Port: 5000, Debug: True
2025-10-04 18:23:00,228 - __main__ - INFO - run.py:61 - Upload folder: uploads
2025-10-04 18:23:00,228 - __main__ - INFO - run.py:65 - Enabled platforms: None
2025-10-04 18:23:00,229 - __main__ - WARNING - run.py:68 - No platforms are properly configured. Please check your API keys.
2025-10-04 18:23:00,231 - models.database - INFO - database.py:102 - Database initialized successfully
2025-10-04 18:23:00,232 - services.scheduler - INFO - scheduler.py:13 - PostScheduler iniciado
2025-10-04 18:23:00,232 - app - INFO - app.py:763 - Application context initialized successfully
2025-10-04 18:23:00,232 - app - INFO - app.py:775 - Starting Social Media Automation System on 0.0.0.0:5000
2025-10-04 18:23:00,233 - app - INFO - app.py:776 - Debug mode: True
2025-10-04 18:23:00,233 - app - INFO - app.py:777 - Upload folder: uploads
2025-10-04 18:23:00,291 - werkzeug - INFO - _internal.py:187 - [31m[1mWARNING: This is a development server. Do not use it in a production deployment. Use a production WSGI server instead.[0m
 * Running on all addresses (0.0.0.0)
 * Running on http://127.0.0.1:5000
 * Running on http://192.168.0.7:5000
2025-10-04 18:23:00,292 - werkzeug - INFO - _internal.py:187 - [33mPress CTRL+C to quit[0m
2025-10-04 18:23:00,294 - werkzeug - INFO - _internal.py:187 -  * Restarting with stat
2025-10-04 18:23:02,525 - root - INFO - logger.py:49 - Social Media Automation System logging initialized
2025-10-04 18:23:02,527 - __main__ - WARNING - run.py:47 - Configuration warnings:
2025-10-04 18:23:02,527 - __main__ - WARNING - run.py:49 -   - Missing API keys for: YouTube, Instagram, TikTok, Kawai
2025-10-04 18:23:02,528 - __main__ - WARNING - run.py:49 -   - Please change the default JWT_SECRET_KEY in production
2025-10-04 18:23:02,536 - models.database - INFO - database.py:102 - Database initialized successfully
2025-10-04 18:23:02,537 - services.ai_service - ERROR - ai_service.py:26 - Failed to initialize OpenAI client: AsyncClient.__init__() got an unexpected keyword argument 'proxies'
2025-10-04 18:23:02,580 - app - INFO - app.py:59 - Social Media Automation System initialized successfully
2025-10-04 18:23:02,585 - __main__ - INFO - run.py:59 - Starting Social Media Automation System
2025-10-04 18:23:02,586 - __main__ - INFO - run.py:60 - Host: 0.0.0.0, Port: 5000, Debug: True
2025-10-04 18:23:02,586 - __main__ - INFO - run.py:61 - Upload folder: uploads
2025-10-04 18:23:02,587 - __main__ - INFO - run.py:65 - Enabled platforms: None
2025-10-04 18:23:02,587 - __main__ - WARNING - run.py:68 - No platforms are properly configured. Please check your API keys.
2025-10-04 18:23:02,591 - models.database - INFO - database.py:102 - Database initialized successfully
2025-10-04 18:23:02,592 - services.scheduler - INFO - scheduler.py:13 - PostScheduler iniciado
2025-10-04 18:23:02,594 - app - INFO - app.py:763 - Application context initialized successfully
2025-10-04 18:23:02,595 - app - INFO - app.py:775 - Starting Social Media Automation System on 0.0.0.0:5000
2025-10-04 18:23:02,595 - app - INFO - app.py:776 - Debug mode: True
2025-10-04 18:23:02,596 - app - INFO - app.py:777 - Upload folder: uploads
2025-10-04 18:23:02,658 - werkzeug - WARNING - _internal.py:187 -  * Debugger is active!
2025-10-04 18:23:02,664 - werkzeug - INFO - _internal.py:187 -  * Debugger PIN: 876-337-494
2025-10-04 18:23:02,729 - werkzeug - INFO - _internal.py:187 - 127.0.0.1 - - [04/Oct/2025 18:23:02] "GET / HTTP/1.1" 200 -
2025-10-04 18:23:02,875 - werkzeug - INFO - _internal.py:187 - 127.0.0.1 - - [04/Oct/2025 18:23:02] "[36mGET /static/css/style.css HTTP/1.1[0m" 304 -
2025-10-04 18:23:02,923 - werkzeug - INFO - _internal.py:187 - 127.0.0.1 - - [04/Oct/2025 18:23:02] "[36mGET /static/js/app.js HTTP/1.1[0m" 304 -
2025-10-04 18:23:03,129 - werkzeug - INFO - _internal.py:187 - 127.0.0.1 - - [04/Oct/2025 18:23:03] "GET /api/accounts/status HTTP/1.1" 200 -
2025-10-04 18:23:18,033 - werkzeug - INFO - _internal.py:187 - 127.0.0.1 - - [04/Oct/2025 18:23:18] "GET /api/accounts/status HTTP/1.1" 200 -
2025-10-04 18:23:19,689 - werkzeug - INFO - _internal.py:187 - 127.0.0.1 - - [04/Oct/2025 18:23:19] "GET /oauth/youtube/start HTTP/1.1" 200 -
2025-10-04 18:23:21,823 - werkzeug - INFO - _internal.py:187 - 127.0.0.1 - - [04/Oct/2025 18:23:21] "GET /api/accounts/status HTTP/1.1" 200 -
2025-10-04 19:14:50,682 - werkzeug - INFO - _internal.py:187 -  * Detected change in 'C:\\Users\\Wilker Gandra\\Documents\\GitHub\\videos_automacoes\\run.py', reloading
2025-10-04 19:14:50,683 - services.scheduler - INFO - scheduler.py:18 - PostScheduler parado
2025-10-04 19:14:50,683 - app - INFO - app.py:790 - Application shutdown complete
2025-10-04 19:14:50,950 - werkzeug - INFO - _internal.py:187 -  * Restarting with stat
2025-10-04 19:14:52,916 - root - INFO - logger.py:49 - Social Media Automation System logging initialized
2025-10-04 19:14:52,918 - __main__ - WARNING - run.py:50 - Configuration warnings:
2025-10-04 19:14:52,918 - __main__ - WARNING - run.py:52 -   - Missing API keys for: YouTube, Instagram, TikTok, Kawai
2025-10-04 19:14:52,919 - __main__ - WARNING - run.py:52 -   - Please change the default JWT_SECRET_KEY in production
2025-10-04 19:14:52,922 - models.database - INFO - database.py:102 - Database initialized successfully
2025-10-04 19:14:52,923 - services.ai_service - ERROR - ai_service.py:26 - Failed to initialize OpenAI client: AsyncClient.__init__() got an unexpected keyword argument 'proxies'
2025-10-04 19:14:52,944 - app - INFO - app.py:59 - Social Media Automation System initialized successfully
2025-10-04 19:14:52,945 - __main__ - INFO - run.py:62 - Starting Social Media Automation System
2025-10-04 19:14:52,945 - __main__ - INFO - run.py:63 - Host: 0.0.0.0, Port: 5000, Debug: True
2025-10-04 19:14:52,946 - __main__ - INFO - run.py:64 - Upload folder: uploads
2025-10-04 19:14:52,949 - __main__ - INFO - run.py:68 - Enabled platforms: None
2025-10-04 19:14:52,956 - __main__ - WARNING - run.py:71 - No platforms are properly configured. Please check your API keys.
2025-10-04 19:14:52,959 - models.database - INFO - database.py:102 - Database initialized successfully
2025-10-04 19:14:52,960 - services.scheduler - INFO - scheduler.py:13 - PostScheduler iniciado
2025-10-04 19:14:52,961 - app - INFO - app.py:763 - Application context initialized successfully
2025-10-04 19:14:52,970 - app - INFO - app.py:775 - Starting Social Media Automation System on 0.0.0.0:5000
2025-10-04 19:14:52,972 - app - INFO - app.py:776 - Debug mode: True
2025-10-04 19:14:52,973 - app - INFO - app.py:777 - Upload folder: uploads
2025-10-04 19:14:52,994 - werkzeug - WARNING - _internal.py:187 -  * Debugger is active!
2025-10-04 19:14:53,002 - werkzeug - INFO - _internal.py:187 -  * Debugger PIN: 876-337-494
